Workbook

Sheet AHL
A1: =COUNTIF(A4:A50,"<>") -> 38 | B1: =COUNTIF(B4:B50,"<>") -> 35 | C1: =COUNTIF(C4:C50,"<>") -> 33 | D1: =COUNTIF(D4:D50,"<>") -> 33 | E1: =COUNTIF(E4:E50,"<>") -> 32 | F1: =COUNTIF(F4:F50,"<>") -> 31 | G1: =COUNTIF(G4:G50,"<>") -> 31 | H1: =COUNTIF(H4:H50,"<>") -> 30 | ... CD1: =COUNTIF(CD4:CD50,"<>") -> 1
A2: it | B2: au | C2: au | D2: it | E2: au | F2: it | G2: au | H2: sl | I2: it | J2: au | K2: au | L2: au | M2: au | N2: it | O2: au | P2: au | Q2: sl | R2: it | S2: it | T2: au | U2: sl | V2: au | W2: sl | X2: it | Y2: it | Z2: it | AA2: it | AB2: it | AC2: au | AD2: au | AE2: it | AF2: it | AG2: it | AH2: it | AI2: au | AJ2: it | AK2: au | AL2: au | AM2: au | AN2: it | AO2: sl | AP2: sl | AQ2: au | AR2: au | AS2: it | AT2: it | AU2: au | AV2: it | AW2: sl | AX2: au | AY2: au | AZ2: it | BA2: au | BB2: it | BC2: au | BD2: au | BE2: it | BF2: sl | BG2: sl | BH2: sl | BI2: au | BJ2: au | BK2: sl | BL2: sl | BM2: au | BN2: it | BO2: au | BP2: au | BQ2: au | BR2: au | BS2: au | BT2: au | BU2: au | BV2: au | BW2: au | BX2: it | BY2: it | BZ2: au | CA2: it | CB2: sl | CC2: au | CD2: au
A3: De zordoMa | B3: HolzerTo | C3: OrelSt | D3: LazzeriAl | E3: RuetzMa | F3: CristeliMa | G3: SchauerJa | H3: BulovecMi | I3: PinieOm | J3: SeewaldJe | K3: HlavatyAl | L3: JägerRi | M3: RinkerDa | N3: BrondiPa | O3: KainbergerJu | P3: MoidlMa | Q3: BajtMi | R3: MoschenAn | S3: FleischmannLu | T3: PuffWo | U3: JeramFi | V3: WeissAl | W3: BergantAn | X3: CusinFe | Y3: StefenelliFe | Z3: VirtaTu | AA3: PaceJa | AB3: GiacomozziFe | AC3: BrockAd | AD3: EislCh | AE3: BenvegnuAn | AF3: AbeltinoSi | AG3: PirasAn | AH3: FecchioFe | AI3: TelesklavFa | AJ3: GrisentiLu | AK3: WidmannFl | AL3: VoicanCh | AM3: MattheyPh | AN3: LegaSi | AO3: LesniakBo | AP3: ArlicMa | AQ3: HesinaCh | AR3: LehnerMo | AS3: FormaioniTh | AT3: SoraperraSi | AU3: WuchererGe | AV3: RivisAn | AW3: RezekGr | AX3: LegatKo | AY3: SpiegelSe | AZ3: VignoloSi | BA3: WendnerMa | BB3: RiccoSt | BC3: KummerSt | BD3: KanyoTa | BE3: EggerTh | BF3: FajdigaAl | BG3: MarkizetiGr | BH3: JavornikBl | BI3: MeixnerSe | BJ3: MoidlDa | BK3: MilovanovicJa | BL3: MurnikPe | BM3: WuntschekDo | BN3: RivisFe | BO3: PötscherMi | BP3: SchonaklenerPa | BQ3: PreiserJu | BR3: SchweighoferMa | BS3: DieberDo | BT3: WenuschHe | BU3: WiestAl | BV3: ZacherlPa | BW3: KlemmAn | BX3: AngyalBo | BY3: BassoNi | BZ3: MartinFl | CA3: MantovaniDa | CB3: MiklicGr | CC3: HuberRe | CD3: HolzerDa
A4: 2023-09-16 | B4: 2023-09-16 | C4: 2023-09-16 | D4: 2023-09-19 | E4: 2023-09-19 | F4: 2023-09-23 | G4: 2023-09-30 | H4: 2023-09-22 | I4: 2023-09-23 | J4: 2023-10-05 | K4: 2023-09-30 | L4: 2023-09-30 | M4: 2023-10-07 | N4: 2023-09-21 | O4: 2023-09-16 | P4: 2023-09-16 | Q4: 2023-09-23 | R4: 2023-09-21 | S4: 2023-10-07 | T4: 2023-10-26 | U4: 2023-09-22 | V4: 2023-09-21 | W4: 2023-09-16 | X4: 2023-09-16 | Y4: 2023-09-24 | Z4: 2023-09-23 | AA4: 2023-09-16 | AB4: 2023-09-16 | AC4: 2023-09-16 | AD4: 2023-09-21 | AE4: 2023-09-16 | AF4: 2023-09-16 | AG4: 2023-09-16 | AH4: 2023-09-23 | AI4: 2023-09-30 | AJ4: 2023-09-21 | AK4: 2023-09-28 | AL4: 2023-09-23 | AM4: 2023-09-23 | AN4: 2023-09-24 | AO4: 2023-09-16 | AP4: 2023-10-01 | AQ4: 2023-09-23 | AR4: 2023-09-29 | AS4: 2023-10-21 | AT4: 2023-09-19 | AU4: 2023-09-21 | AV4: 2023-09-28 | AW4: 2023-09-21 | AX4: 2023-09-19 | AY4: 2023-09-21 | AZ4: 2023-09-16 | BA4: 2023-09-16 | BB4: 2023-09-21 | BC4: 2023-09-30 | BD4: 2023-09-30 | BE4: 2023-09-30 | BF4: 2023-10-01 | BG4: 2023-09-16 | BH4: 2023-10-05 | BI4: 2023-09-16 | BJ4: 2023-09-19 | BK4: 2023-09-16 | BL4: 2023-10-06 | BM4: 2023-10-07 | BN4: 2023-09-21 | BO4: 2023-10-17 | BP4: 2023-09-16 | BQ4: 2023-09-21 | BR4: 2023-09-30 | BS4: 2023-09-19 | BT4: 2023-09-16 | BU4: 2023-09-30 | BV4: 2023-09-16 | BW4: 2023-09-21 | BX4: 2023-10-21 | BY4: 2023-10-21 | BZ4: 2023-09-16 | CA4: 2023-11-25 | CB4: 2023-12-09 | CC4: 2024-01-03 | CD4: 2023-12-19
A5: 2023-09-19 | B5: 2023-09-23 | C5: 2023-09-21 | D5: 2023-09-23 | E5: 2023-09-23 | F5: 2023-09-21 | G5: 2023-10-14 | H5: 2023-10-07 | I5: 2023-09-21 | J5: 2023-10-19 | K5: 2023-10-05 | L5: 2023-09-27 | M5: 2023-10-15 | N5: 2023-10-05 | O5: 2023-09-22 | P5: 2023-09-21 | Q5: 2023-09-28 | R5: 2023-10-14 | S5: 2023-10-14 | T5: 2023-11-24 | U5: 2023-09-21 | V5: 2023-10-21 | W5: 2023-09-23 | X5: 2023-09-24 | Y5: 2023-09-21 | Z5: 2023-09-28 | AA5: 2023-09-23 | AB5: 2023-09-23 | AC5: 2023-09-26 | AD5: 2023-10-05 | AE5: 2023-09-28 | AF5: 2023-09-23 | AG5: 2023-09-21 | AH5: 2023-09-28 | AI5: 2023-09-29 | AJ5: 2023-09-28 | AK5: 2023-10-17 | AL5: 2023-09-21 | AM5: 2023-09-29 | AN5: 2023-09-16 | AO5: 2023-09-26 | AP5: 2023-10-07 | AQ5: 2023-10-07 | AR5: 2023-10-05 | AS5: 2023-11-01 | AT5: 2023-09-27 | AU5: 2023-09-28 | AV5: 2023-09-16 | AW5: 2023-10-21 | AX5: 2023-09-23 | AY5: 2023-09-27 | AZ5: 2023-09-21 | BA5: 2023-09-28 | BB5: 2023-09-16 | BC5: 2023-10-12 | BD5: 2023-10-07 | BE5: 2023-10-05 | BF5: 2023-10-14 | BG5: 2023-09-22 | BH5: 2023-10-19 | BI5: 2023-09-21 | BJ5: 2023-09-21 | BK5: 2023-09-21 | BL5: 2023-10-17 | BM5: 2023-10-19 | BN5: 2023-09-28 | BO5: 2023-11-04 | BP5: 2023-09-21 | BQ5: 2023-09-30 | BR5: 2023-10-21 | BS5: 2023-09-26 | BT5: 2023-10-07 | BU5: 2023-10-14 | BV5: 2023-09-21 | BW5: 2023-11-16 | BX5: 2023-11-04 | BY5: 2023-11-01 | BZ5: 2023-10-24
A6: 2023-09-24 | B6: 2023-09-30 | C6: 2023-09-28 | D6: 2023-09-28 | E6: 2023-09-28 | F6: 2023-09-28 | G6: 2023-10-05 | H6: 2023-10-12 | I6: 2023-09-28 | J6: 2023-10-14 | K6: 2023-10-21 | L6: 2023-10-14 | M6: 2023-10-21 | N6: 2023-10-19 | O6: 2023-09-28 | P6: 2023-10-01 | Q6: 2023-09-29 | R6: 2023-10-21 | S6: 2023-10-21 | T6: 2023-11-25 | U6: 2023-10-07 | V6: 2023-10-26 | W6: 2023-09-28 | X6: 2023-09-28 | Y6: 2023-10-01 | Z6: 2023-10-05 | AA6: 2023-09-30 | AB6: 2023-09-28 | AC6: 2023-09-30 | AD6: 2023-09-30 | AE6: 2023-10-07 | AF6: 2023-09-21 | AG6: 2023-09-30 | AH6: 2023-10-07 | AI6: 2023-10-06 | AJ6: 2023-09-19 | AK6: 2023-10-12 | AL6: 2023-10-05 | AM6: 2023-09-16 | AN6: 2023-10-19 | AO6: 2023-09-21 | AP6: 2023-09-30 | AQ6: 2023-10-15 | AR6: 2023-10-14 | AS6: 2023-10-28 | AT6: 2023-10-05 | AU6: 2023-10-14 | AV6: 2023-10-05 | AW6: 2023-10-26 | AX6: 2023-09-30 | AY6: 2023-10-07 | AZ6: 2023-09-28 | BA6: 2023-10-12 | BB6: 2023-10-07 | BC6: 2023-10-21 | BD6: 2023-10-19 | BE6: 2023-10-12 | BF6: 2023-10-24 | BG6: 2023-10-05 | BH6: 2023-11-01 | BI6: 2023-09-30 | BJ6: 2023-10-01 | BK6: 2023-10-19 | BL6: 2023-10-28 | BM6: 2023-09-30 | BN6: 2023-09-16 | BO6: 2023-10-24 | BP6: 2023-09-26 | BQ6: 2023-10-07 | BR6: 2023-10-07 | BS6: 2023-10-19 | BT6: 2023-10-19 | BU6: 2023-10-28 | BV6: 2023-09-28 | BW6: 2023-12-09 | BX6: 2023-11-30 | BY6: 2023-10-28
A7: 2023-09-28 | B7: 2023-10-07 | C7: 2023-10-05 | D7: 2023-10-05 | E7: 2023-10-01 | F7: 2023-10-05 | G7: 2023-11-04 | H7: 2023-10-19 | I7: 2023-10-12 | J7: 2023-11-04 | K7: 2023-11-01 | L7: 2023-10-21 | M7: 2023-10-19 | N7: 2023-10-12 | O7: 2023-10-05 | P7: 2023-10-07 | Q7: 2023-10-06 | R7: 2023-10-05 | S7: 2023-10-01 | T7: 2023-12-09 | U7: 2023-10-28 | V7: 2023-11-30 | W7: 2023-10-07 | X7: 2023-10-05 | Y7: 2023-10-12 | Z7: 2023-10-12 | AA7: 2023-10-05 | AB7: 2023-10-05 | AC7: 2023-10-14 | AD7: 2023-12-07 | AE7: 2023-10-14 | AF7: 2023-09-30 | AG7: 2023-10-05 | AH7: 2023-10-12 | AI7: 2023-10-12 | AJ7: 2023-10-07 | AK7: 2023-11-01 | AL7: 2023-10-14 | AM7: 2023-10-05 | AN7: 2023-10-28 | AO7: 2023-10-06 | AP7: 2023-11-04 | AQ7: 2023-10-12 | AR7: 2023-10-19 | AS7: 2023-11-16 | AT7: 2023-10-12 | AU7: 2023-10-19 | AV7: 2023-10-12 | AW7: 2024-01-25 | AX7: 2023-10-07 | AY7: 2023-10-14 | AZ7: 2023-10-07 | BA7: 2023-10-19 | BB7: 2023-10-12 | BC7: 2023-10-28 | BD7: 2023-10-28 | BE7: 2023-10-21 | BF7: 2023-11-01 | BG7: 2023-10-14 | BH7: 2023-11-23 | BI7: 2023-10-07 | BJ7: 2023-10-12 | BK7: 2023-10-07 | BL7: 2023-11-18 | BM7: 2023-11-01 | BN7: 2023-10-12 | BO7: 2023-10-28 | BP7: 2023-10-05 | BQ7: 2023-10-21 | BR7: 2023-10-05 | BS7: 2023-11-04 | BT7: 2023-11-04 | BU7: 2023-11-18 | BV7: 2023-10-12 | BW7: 2023-12-26
A8: 2023-09-27 | B8: 2023-10-19 | C8: 2023-10-17 | D8: 2023-10-08 | E8: 2023-10-15 | F8: 2023-10-12 | G8: 2023-10-26 | H8: 2023-09-30 | I8: 2023-10-21 | J8: 2023-10-26 | K8: 2023-11-04 | L8: 2023-10-19 | M8: 2023-10-05 | N8: 2023-09-23 | O8: 2023-10-12 | P8: 2023-10-19 | Q8: 2023-10-19 | R8: 2023-09-23 | S8: 2023-11-01 | T8: 2023-12-19 | U8: 2023-10-21 | V8: 2023-11-18 | W8: 2023-09-30 | X8: 2023-10-12 | Y8: 2023-10-19 | Z8: 2023-10-19 | AA8: 2023-10-12 | AB8: 2023-10-12 | AC8: 2023-10-19 | AD8: 2023-11-15 | AE8: 2023-09-23 | AF8: 2023-10-05 | AG8: 2023-10-07 | AH8: 2023-10-21 | AI8: 2023-10-21 | AJ8: 2023-10-14 | AK8: 2023-10-24 | AL8: 2023-11-04 | AM8: 2023-10-14 | AN8: 2023-10-14 | AO8: 2023-10-14 | AP8: 2023-10-26 | AQ8: 2023-11-01 | AR8: 2023-11-04 | AS8: 2023-11-18 | AT8: 2023-11-01 | AU8: 2023-10-07 | AV8: 2023-10-21 | AW8: 2024-02-01 | AX8: 2023-10-14 | AY8: 2023-11-03 | AZ8: 2023-10-14 | BA8: 2023-11-04 | BB8: 2023-10-19 | BC8: 2023-11-24 | BD8: 2023-10-12 | BE8: 2023-11-01 | BF8: 2023-11-16 | BG8: 2023-10-26 | BH8: 2023-12-07 | BI8: 2023-10-21 | BJ8: 2023-10-19 | BK8: 2023-10-28 | BL8: 2023-11-28 | BM8: 2023-10-26 | BN8: 2023-10-28 | BO8: 2023-11-23 | BP8: 2023-10-14 | BQ8: 2023-11-03 | BR8: 2023-10-28 | BS8: 2023-11-18 | BT8: 2023-11-28 | BU8: 2023-12-02 | BV8: 2023-09-30
A9: 2023-10-05 | B9: 2023-11-01 | C9: 2023-11-01 | D9: 2023-10-15 | E9: 2023-10-12 | F9: 2023-10-19 | G9: 2023-10-24 | H9: 2023-10-26 | I9: 2023-10-08 | J9: 2023-10-28 | K9: 2023-10-26 | L9: 2023-10-01 | M9: 2023-11-01 | N9: 2023-11-01 | O9: 2023-10-19 | P9: 2023-11-04 | Q9: 2023-10-07 | R9: 2023-11-04 | S9: 2023-11-29 | T9: 2023-12-26 | U9: 2023-11-23 | V9: 2023-12-19 | W9: 2023-11-04 | X9: 2023-10-19 | Y9: 2023-09-30 | Z9: 2023-11-05 | AA9: 2023-09-28 | AB9: 2023-11-05 | AC9: 2023-11-04 | AD9: 2023-11-21 | AE9: 2023-11-01 | AF9: 2023-10-12 | AG9: 2023-10-14 | AH9: 2023-11-05 | AI9: 2023-11-01 | AJ9: 2023-10-21 | AK9: 2023-10-21 | AL9: 2023-11-18 | AM9: 2023-10-12 | AN9: 2023-11-16 | AO9: 2023-10-21 | AP9: 2023-11-23 | AQ9: 2023-10-26 | AR9: 2023-10-28 | AS9: 2023-11-19 | AT9: 2023-10-26 | AU9: 2023-11-01 | AV9: 2023-10-28 | AW9: 2024-02-22 | AX9: 2023-10-21 | AY9: 2023-10-26 | AZ9: 2023-10-12 | BA9: 2023-10-26 | BB9: 2023-10-14 | BC9: 2023-11-25 | BD9: 2023-11-23 | BE9: 2023-11-23 | BF9: 2023-12-09 | BG9: 2023-11-18 | BH9: 2024-01-03 | BI9: 2023-10-28 | BJ9: 2023-11-01 | BK9: 2023-11-23 | BL9: 2023-12-09 | BM9: 2023-11-23 | BN9: 2023-11-18 | BO9: 2023-12-07 | BP9: 2023-10-19 | BQ9: 2023-11-04 | BR9: 2023-11-30 | BS9: 2023-12-19 | BT9: 2023-11-21 | BU9: 2023-12-28
A10: 2023-10-08 | B10: 2023-11-04 | C10: 2023-10-26 | D10: 2023-10-21 | E10: 2023-10-07 | F10: 2023-10-26 | G10: 2023-11-15 | H10: 2023-11-04 | I10: 2023-11-01 | J10: 2023-10-21 | K10: 2023-11-18 | L10: 2023-11-03 | M10: 2023-10-26 | N10: 2023-10-26 | O10: 2023-11-04 | P10: 2023-10-28 | Q10: 2023-10-26 | R10: 2023-10-28 | S10: 2023-12-02 | T10: 2023-12-30 | U10: 2023-12-02 | V10: 2024-01-05 | W10: 2023-10-24 | X10: 2023-09-23 | Y10: 2023-10-28 | Z10: 2023-10-21 | AA10: 2023-11-05 | AB10: 2023-10-28 | AC10: 2023-10-26 | AD10: 2023-12-09 | AE10: 2023-10-26 | AF10: 2023-10-19 | AG10: 2023-10-21 | AH10: 2023-10-28 | AI10: 2023-10-19 | AJ10: 2023-10-28 | AK10: 2023-11-16 | AL10: 2023-12-09 | AM10: 2023-11-04 | AN10: 2023-11-25 | AO10: 2023-11-04 | AP10: 2023-12-02 | AQ10: 2023-11-23 | AR10: 2023-11-30 | AS10: 2023-12-07 | AT10: 2023-11-16 | AU10: 2023-10-26 | AV10: 2023-11-14 | AW10: 2024-02-24 | AX10: 2023-11-01 | AY10: 2023-11-25 | AZ10: 2023-10-28 | BA10: 2023-10-28 | BB10: 2023-10-28 | BC10: 2023-11-16 | BD10: 2023-11-30 | BE10: 2023-12-02 | BF10: 2023-11-30 | BG10: 2023-12-01 | BH10: 2023-12-21 | BI10: 2023-11-18 | BJ10: 2023-11-18 | BK10: 2023-12-02 | BL10: 2023-12-30 | BM10: 2023-11-04 | BN10: 2023-12-09 | BO10: 2023-12-21 | BP10: 2023-11-01 | BQ10: 2023-11-21 | BR10: 2023-12-26 | BS10: 2024-01-03 | BT10: 2024-01-27 | BU10: 2024-02-15
A11: 2023-10-14 | B11: 2023-10-26 | C11: 2023-10-28 | D11: 2023-10-07 | E11: 2023-10-19 | F11: 2023-10-08 | G11: 2023-11-23 | H11: 2023-11-23 | I11: 2023-10-19 | J11: 2023-11-01 | K11: 2023-11-30 | L11: 2023-11-04 | M11: 2023-11-25 | N11: 2023-11-16 | O11: 2023-10-26 | P11: 2023-11-23 | Q11: 2023-11-04 | R11: 2023-11-17 | S11: 2023-12-26 | T11: 2023-12-07 | U11: 2023-12-09 | V11: 2024-01-13 | W11: 2023-10-21 | X11: 2023-10-26 | Y11: 2023-11-01 | Z11: 2023-11-25 | AA11: 2023-10-26 | AB11: 2023-11-18 | AC11: 2023-10-21 | AD11: 2023-12-21 | AE11: 2023-11-16 | AF11: 2023-10-28 | AG11: 2023-09-28 | AH11: 2023-11-16 | AI11: 2023-11-16 | AJ11: 2023-11-16 | AK11: 2023-11-23 | AL11: 2023-12-02 | AM11: 2023-10-19 | AN11: 2023-11-26 | AO11: 2023-10-28 | AP11: 2023-12-30 | AQ11: 2023-11-25 | AR11: 2023-12-02 | AS11: 2023-11-25 | AT11: 2023-11-25 | AU11: 2023-11-24 | AV11: 2023-11-18 | AW11: 2024-02-29 | AX11: 2023-12-02 | AY11: 2023-12-02 | AZ11: 2023-11-16 | BA11: 2023-11-18 | BB11: 2023-10-21 | BC11: 2023-12-09 | BD11: 2023-12-28 | BE11: 2023-12-05 | BF11: 2023-12-26 | BG11: 2023-12-19 | BH11: 2024-01-18 | BI11: 2023-11-30 | BJ11: 2023-12-09 | BK11: 2023-12-19 | BL11: 2023-12-26 | BM11: 2023-12-19 | BN11: 2023-11-25 | BO11: 2024-01-25 | BP11: 2023-11-04 | BQ11: 2023-12-02 | BR11: 2024-01-03 | BS11: 2024-02-17
A12: 2023-10-21 | B12: 2023-10-24 | C12: 2023-11-18 | D12: 2023-11-04 | E12: 2023-11-01 | F12: 2023-11-04 | G12: 2023-11-29 | H12: 2023-12-01 | I12: 2023-11-14 | J12: 2023-11-18 | K12: 2023-12-30 | L12: 2023-10-24 | M12: 2023-12-03 | N12: 2023-11-23 | O12: 2023-11-23 | P12: 2023-11-30 | Q12: 2023-11-23 | R12: 2023-11-23 | S12: 2023-12-23 | T12: 2024-01-05 | U12: 2023-12-21 | V12: 2024-01-20 | W12: 2023-11-30 | X12: 2023-11-04 | Y12: 2023-11-18 | Z12: 2023-12-02 | AA12: 2023-10-28 | AB12: 2023-11-29 | AC12: 2023-11-21 | AD12: 2023-12-28 | AE12: 2023-11-25 | AF12: 2023-11-01 | AG12: 2023-10-28 | AH12: 2023-11-25 | AI12: 2023-11-30 | AJ12: 2023-11-23 | AK12: 2023-12-01 | AL12: 2023-12-19 | AM12: 2023-11-23 | AN12: 2023-12-06 | AO12: 2023-11-16 | AP12: 2024-01-05 | AQ12: 2023-12-03 | AR12: 2023-12-09 | AS12: 2023-12-21 | AT12: 2023-12-02 | AU12: 2023-11-25 | AV12: 2023-11-25 | AW12: 2024-03-05 | AX12: 2023-11-28 | AY12: 2023-12-07 | AZ12: 2023-11-25 | BA12: 2023-12-01 | BB12: 2023-12-02 | BC12: 2023-12-26 | BD12: 2024-01-03 | BE12: 2023-12-21 | BF12: 2024-01-03 | BG12: 2023-12-26 | BH12: 2024-01-27 | BI12: 2023-12-07 | BJ12: 2023-12-07 | BK12: 2023-12-21 | BL12: 2024-01-20 | BM12: 2023-12-26 | BN12: 2023-12-19 | BO12: 2024-02-13
A13: 2023-11-01 | B13: 2023-11-25 | C13: 2023-11-24 | D13: 2023-10-28 | E13: 2023-10-26 | F13: 2023-10-28 | G13: 2023-12-02 | H13: 2023-12-09 | I13: 2023-11-23 | J13: 2023-12-02 | K13: 2024-01-05 | L13: 2023-11-17 | M13: 2023-12-09 | N13: 2023-11-25 | O13: 2023-11-30 | P13: 2023-12-02 | Q13: 2023-12-02 | R13: 2023-12-03 | S13: 2024-01-05 | T13: 2024-01-20 | U13: 2023-12-28 | V13: 2024-01-25 | W13: 2023-12-07 | X13: 2023-11-16 | Y13: 2023-11-19 | Z13: 2023-12-09 | AA13: 2023-11-16 | AB13: 2023-12-07 | AC13: 2023-11-30 | AD13: 2023-12-30 | AE13: 2023-12-02 | AF13: 2023-11-17 | AG13: 2023-11-16 | AH13: 2023-11-30 | AI13: 2023-11-23 | AJ13: 2023-11-25 | AK13: 2023-12-09 | AL13: 2024-01-03 | AM13: 2023-12-02 | AN13: 2023-11-18 | AO13: 2023-11-28 | AP13: 2024-01-18 | AQ13: 2023-11-30 | AR13: 2023-11-23 | AS13: 2023-12-28 | AT13: 2023-12-09 | AU13: 2023-12-26 | AV13: 2023-12-02 | AW13: 2024-03-07 | AX13: 2023-12-09 | AY13: 2023-12-26 | AZ13: 2023-11-26 | BA13: 2023-12-26 | BB13: 2023-12-09 | BC13: 2023-12-30 | BD13: 2024-01-18 | BE13: 2023-12-28 | BF13: 2024-01-20 | BG13: 2023-12-30 | BH13: 2024-02-01 | BI13: 2023-12-26 | BJ13: 2023-12-30 | BK13: 2024-01-03 | BL13: 2024-02-03 | BM13: 2023-12-28 | BN13: 2024-02-12
A14: 2023-10-26 | B14: 2023-12-02 | C14: 2023-11-25 | D14: 2023-11-18 | E14: 2023-11-03 | F14: 2023-11-01 | G14: 2023-12-07 | H14: 2023-11-18 | I14: 2023-11-25 | J14: 2023-12-23 | K14: 2024-01-13 | L14: 2023-11-29 | M14: 2023-12-07 | N14: 2023-12-02 | O14: 2023-12-07 | P14: 2023-12-09 | Q14: 2023-12-28 | R14: 2023-11-14 | S14: 2024-01-20 | T14: 2024-02-03 | U14: 2023-12-19 | V14: 2024-02-01 | W14: 2023-12-19 | X14: 2023-11-23 | Y14: 2023-11-25 | Z14: 2023-11-16 | AA14: 2023-12-09 | AB14: 2023-12-02 | AC14: 2023-12-28 | AD14: 2024-01-27 | AE14: 2023-12-09 | AF14: 2023-11-23 | AG14: 2023-11-23 | AH14: 2023-12-21 | AI14: 2023-12-26 | AJ14: 2023-11-30 | AK14: 2023-12-19 | AL14: 2024-01-05 | AM14: 2023-12-09 | AN14: 2023-12-26 | AO14: 2023-12-07 | AP14: 2024-01-25 | AQ14: 2023-12-26 | AR14: 2023-12-26 | AS14: 2023-12-19 | AT14: 2023-12-21 | AU14: 2023-12-30 | AV14: 2023-12-28 | AW14: 2024-03-14 | AX14: 2023-12-19 | AY14: 2023-12-28 | AZ14: 2023-12-06 | BA14: 2024-01-03 | BB14: 2023-12-21 | BC14: 2024-01-05 | BD14: 2024-01-27 | BE14: 2024-01-03 | BF14: 2024-02-01 | BG14: 2024-01-03 | BH14: 2024-02-15 | BI14: 2024-01-27 | BJ14: 2024-02-17 | BK14: 2024-02-03 | BL14: 2024-02-22 | BM14: 2023-12-30
A15: 2023-11-18 | B15: 2023-12-06 | C15: 2023-12-09 | D15: 2023-11-19 | E15: 2023-11-17 | F15: 2023-11-16 | G15: 2023-12-19 | H15: 2023-12-19 | I15: 2023-11-30 | J15: 2023-12-30 | K15: 2024-01-20 | L15: 2023-12-06 | M15: 2023-12-28 | N15: 2023-12-09 | O15: 2023-11-18 | P15: 2023-11-18 | Q15: 2023-12-30 | R15: 2023-11-25 | S15: 2024-02-17 | T15: 2024-02-17 | U15: 2024-01-20 | V15: 2024-02-08 | W15: 2023-12-28 | X15: 2023-11-25 | Y15: 2023-12-02 | Z15: 2023-11-23 | AA15: 2023-11-30 | AB15: 2023-12-21 | AC15: 2023-12-19 | AD15: 2024-02-03 | AE15: 2023-12-21 | AF15: 2023-12-05 | AG15: 2023-12-09 | AH15: 2023-12-28 | AI15: 2023-12-28 | AJ15: 2023-12-21 | AK15: 2023-12-26 | AL15: 2024-01-18 | AM15: 2023-11-30 | AN15: 2023-12-19 | AO15: 2023-12-21 | AP15: 2024-02-01 | AQ15: 2023-12-28 | AR15: 2023-12-28 | AS15: 2023-12-26 | AT15: 2023-12-28 | AU15: 2024-01-05 | AV15: 2023-12-19 | AW15: 2024-03-21 | AX15: 2023-12-30 | AY15: 2023-12-21 | AZ15: 2023-12-21 | BA15: 2024-01-20 | BB15: 2023-12-28 | BC15: 2024-02-03 | BD15: 2024-02-03 | BE15: 2024-01-27 | BF15: 2024-02-15 | BG15: 2024-01-25 | BH15: 2024-02-22 | BI15: 2024-02-13
A16: 2023-11-14 | B16: 2023-11-15 | C16: 2023-11-30 | D16: 2023-12-05 | E16: 2023-11-23 | F16: 2023-11-18 | G16: 2023-12-23 | H16: 2023-12-30 | I16: 2023-12-07 | J16: 2024-01-02 | K16: 2024-01-18 | L16: 2023-12-07 | M16: 2023-12-19 | N16: 2023-11-30 | O16: 2023-12-21 | P16: 2023-12-30 | Q16: 2024-01-05 | R16: 2023-12-21 | S16: 2024-02-20 | T16: 2024-02-22 | U16: 2024-01-27 | V16: 2024-02-17 | W16: 2024-01-05 | X16: 2023-11-26 | Y16: 2023-11-30 | Z16: 2023-12-21 | AA16: 2023-12-02 | AB16: 2023-12-28 | AC16: 2024-01-03 | AD16: 2024-02-22 | AE16: 2023-12-26 | AF16: 2023-12-21 | AG16: 2023-11-30 | AH16: 2023-12-07 | AI16: 2024-01-02 | AJ16: 2023-12-26 | AK16: 2023-12-30 | AL16: 2024-01-25 | AM16: 2023-12-28 | AN16: 2023-12-30 | AO16: 2023-12-28 | AP16: 2024-02-24 | AQ16: 2024-01-03 | AR16: 2023-12-30 | AS16: 2024-01-03 | AT16: 2023-12-26 | AU16: 2024-01-13 | AV16: 2024-01-03 | AW16: 2024-03-26 | AX16: 2024-01-05 | AY16: 2024-01-17 | AZ16: 2023-12-19 | BA16: 2024-02-02 | BB16: 2024-01-03 | BC16: 2024-01-25 | BD16: 2024-02-17 | BE16: 2024-02-24
A17: 2023-11-25 | B17: 2023-12-21 | C17: 2023-12-21 | D17: 2023-11-30 | E17: 2023-11-25 | F17: 2023-11-19 | G17: 2023-12-30 | H17: 2024-01-05 | I17: 2023-12-28 | J17: 2024-01-05 | K17: 2024-01-27 | L17: 2023-11-15 | M17: 2023-12-30 | N17: 2023-12-21 | O17: 2023-12-26 | P17: 2024-01-05 | Q17: 2024-01-20 | R17: 2023-12-26 | S17: 2024-02-24 | T17: 2024-02-24 | U17: 2024-02-22 | V17: 2024-02-22 | W17: 2024-01-18 | X17: 2023-12-02 | Y17: 2023-12-21 | Z17: 2023-12-28 | AA17: 2023-12-21 | AB17: 2023-12-19 | AC17: 2024-01-20 | AD17: 2024-02-24 | AE17: 2023-12-19 | AF17: 2023-12-30 | AG17: 2023-12-21 | AH17: 2024-01-03 | AI17: 2024-01-13 | AJ17: 2023-12-30 | AK17: 2024-01-05 | AL17: 2024-02-01 | AM17: 2023-12-19 | AN17: 2024-01-05 | AO17: 2024-01-18 | AP17: 2024-02-29 | AQ17: 2024-01-11 | AR17: 2024-01-05 | AS17: 2024-01-18 | AT17: 2024-01-03 | AU17: 2024-01-25 | AV17: 2024-01-20 | AW17: 2024-03-30 | AX17: 2024-01-25 | AY17: 2024-02-03 | AZ17: 2023-12-30 | BA17: 2024-02-13 | BB17: 2024-02-15 | BC17: 2024-02-22 | BD17: 2024-02-24
A18: 2023-12-02 | B18: 2023-12-28 | C18: 2023-12-26 | D18: 2023-11-16 | E18: 2023-12-03 | F18: 2023-12-09 | G18: 2024-01-05 | H18: 2024-01-18 | I18: 2023-12-19 | J18: 2023-12-26 | K18: 2024-02-08 | L18: 2023-12-21 | M18: 2024-01-05 | N18: 2023-12-28 | O18: 2023-12-28 | P18: 2024-01-11 | Q18: 2024-01-27 | R18: 2023-12-19 | S18: 2024-03-09 | T18: 2024-02-29 | U18: 2024-02-27 | V18: 2024-02-24 | W18: 2024-01-27 | X18: 2023-12-07 | Y18: 2023-12-28 | Z18: 2024-01-05 | AA18: 2023-12-28 | AB18: 2024-01-03 | AC18: 2024-01-18 | AD18: 2024-03-05 | AE18: 2023-12-30 | AF18: 2024-01-05 | AG18: 2023-12-28 | AH18: 2024-01-05 | AI18: 2024-01-18 | AJ18: 2024-01-03 | AK18: 2024-01-18 | AL18: 2024-02-17 | AM18: 2023-12-26 | AN18: 2024-01-20 | AO18: 2024-01-27 | AP18: 2024-03-07 | AQ18: 2024-01-31 | AR18: 2024-02-03 | AS18: 2024-01-27 | AT18: 2024-01-25 | AU18: 2024-02-03 | AV18: 2024-02-01 | AW18: 2024-04-06 | AX18: 2024-02-17 | AY18: 2024-02-14 | AZ18: 2024-01-27 | BA18: 2024-02-24
A19: 2023-12-05 | B19: 2023-12-30 | C19: 2023-12-07 | D19: 2023-11-25 | E19: 2023-12-07 | F19: 2023-11-23 | G19: 2024-01-11 | H19: 2024-01-27 | I19: 2024-01-03 | J19: 2024-01-13 | K19: 2024-02-03 | L19: 2023-12-26 | M19: 2023-12-21 | N19: 2023-12-19 | O19: 2024-01-02 | P19: 2024-01-18 | Q19: 2024-01-25 | R19: 2023-12-30 | S19: 2024-03-12 | T19: 2024-03-07 | U19: 2024-03-05 | V19: 2024-03-02 | W19: 2024-02-02 | X19: 2023-12-21 | Y19: 2023-12-30 | Z19: 2024-01-18 | AA19: 2024-01-03 | AB19: 2024-01-18 | AC19: 2024-02-03 | AD19: 2024-03-07 | AE19: 2024-01-05 | AF19: 2024-01-18 | AG19: 2024-01-03 | AH19: 2024-01-25 | AI19: 2024-01-25 | AJ19: 2024-01-20 | AK19: 2024-01-25 | AL19: 2024-02-22 | AM19: 2024-01-25 | AN19: 2024-01-27 | AO19: 2024-02-02 | AP19: 2024-03-09 | AQ19: 2024-02-14 | AR19: 2024-02-17 | AS19: 2024-02-01 | AT19: 2024-02-03 | AU19: 2024-02-10 | AV19: 2024-02-03 | AW19: 2024-04-11 | AX19: 2024-02-24 | AY19: 2024-02-24
A20: 2023-12-09 | B20: 2024-01-05 | C20: 2024-01-02 | D20: 2023-11-26 | E20: 2023-12-26 | F20: 2023-11-25 | G20: 2024-01-18 | H20: 2024-02-03 | I20: 2024-01-05 | J20: 2024-01-18 | K20: 2024-02-17 | L20: 2023-12-30 | M20: 2024-01-10 | N20: 2024-01-03 | O20: 2024-01-25 | P20: 2024-01-27 | Q20: 2024-02-22 | R20: 2024-01-03 | S20: 2024-03-14 | T20: 2024-03-09 | U20: 2024-03-07 | V20: 2024-03-05 | W20: 2024-02-22 | X20: 2023-12-26 | Y20: 2024-01-05 | Z20: 2024-02-01 | AA20: 2024-01-18 | AB20: 2024-01-20 | AC20: 2024-02-17 | AD20: 2024-03-12 | AE20: 2024-01-20 | AF20: 2024-01-27 | AG20: 2024-01-20 | AH20: 2024-01-20 | AI20: 2024-02-01 | AJ20: 2024-02-03 | AK20: 2024-02-03 | AL20: 2024-02-24 | AM20: 2024-02-03 | AN20: 2024-02-03 | AO20: 2024-02-22 | AP20: 2024-03-14 | AQ20: 2024-02-17 | AR20: 2024-02-24 | AS20: 2024-02-15 | AT20: 2024-02-15 | AU20: 2024-02-24 | AV20: 2024-02-15
A21: 2023-12-21 | B21: 2024-01-10 | C21: 2023-12-19 | D21: 2023-12-21 | E21: 2023-12-19 | F21: 2023-12-21 | G21: 2024-01-31 | H21: 2024-01-25 | I21: 2024-01-20 | J21: 2024-01-25 | K21: 2024-02-22 | L21: 2024-01-03 | M21: 2024-01-17 | N21: 2024-01-18 | O21: 2024-01-20 | P21: 2024-02-03 | Q21: 2024-02-27 | R21: 2024-01-20 | S21: 2024-03-16 | T21: 2024-03-12 | U21: 2024-03-09 | V21: 2024-03-09 | W21: 2024-02-24 | X21: 2023-12-30 | Y21: 2024-01-20 | Z21: 2024-02-24 | AA21: 2024-01-25 | AB21: 2024-01-27 | AC21: 2024-02-24 | AD21: 2024-03-14 | AE21: 2024-02-01 | AF21: 2024-01-20 | AG21: 2024-02-03 | AH21: 2024-02-03 | AI21: 2024-02-08 | AJ21: 2024-02-15 | AK21: 2024-02-17 | AL21: 2024-03-02 | AM21: 2024-02-17 | AN21: 2024-02-15
A22: 2023-12-28 | B22: 2024-01-20 | C22: 2024-01-13 | D22: 2023-12-26 | E22: 2023-12-23 | F22: 2023-12-26 | G22: 2024-02-14 | H22: 2024-02-22 | I22: 2024-02-03 | J22: 2024-02-10 | K22: 2024-03-02 | L22: 2023-12-19 | M22: 2024-01-25 | N22: 2024-01-27 | O22: 2024-01-31 | P22: 2024-03-02 | Q22: 2024-03-05 | R22: 2024-01-25 | S22: 2024-03-19 | T22: 2024-03-14 | U22: 2024-03-12 | V22: 2024-03-12 | W22: 2024-02-27 | X22: 2024-01-05 | Y22: 2024-01-27 | Z22: 2024-02-29 | AA22: 2024-02-12 | AB22: 2024-02-01 | AC22: 2024-03-07 | AD22: 2024-03-21 | AE22: 2024-02-15 | AF22: 2024-02-03 | AG22: 2024-02-15 | AH22: 2024-02-15 | AI22: 2024-02-15 | AJ22: 2024-02-22 | AK22: 2024-02-15 | AL22: 2024-03-05
A23: 2023-12-19 | B23: 2024-01-17 | C23: 2024-01-11 | D23: 2023-12-30 | E23: 2023-12-30 | F23: 2023-12-28 | G23: 2024-02-17 | H23: 2024-02-24 | I23: 2024-02-12 | J23: 2024-02-03 | K23: 2024-03-05 | L23: 2024-01-05 | M23: 2024-02-01 | N23: 2024-01-20 | O23: 2024-02-13 | P23: 2024-03-05 | Q23: 2024-03-09 | R23: 2024-02-01 | S23: 2024-03-23 | T23: 2024-03-16 | U23: 2024-03-16 | V23: 2024-03-21 | W23: 2024-03-05 | X23: 2024-01-20 | Y23: 2024-02-03 | Z23: 2024-03-07 | AA23: 2024-02-15 | AB23: 2024-02-15 | AC23: 2024-03-12 | AD23: 2024-03-26 | AE23: 2024-02-22 | AF23: 2024-02-18 | AG23: 2024-02-22 | AH23: 2024-02-22 | AI23: 2024-02-17
A24: 2024-01-03 | B24: 2024-01-13 | C24: 2024-01-18 | D24: 2024-01-05 | E24: 2024-01-03 | F24: 2023-12-19 | G24: 2024-02-22 | H24: 2024-02-27 | I24: 2024-02-17 | J24: 2024-02-22 | K24: 2024-03-09 | L24: 2024-01-10 | M24: 2024-02-14 | N24: 2024-02-01 | O24: 2024-02-22 | P24: 2024-03-09 | Q24: 2024-03-14 | R24: 2024-02-15 | S24: 2024-03-28 | T24: 2024-03-19 | U24: 2024-03-19 | V24: 2024-03-26 | W24: 2024-03-09 | X24: 2024-02-03 | Y24: 2024-02-15 | Z24: 2024-03-09 | AA24: 2024-02-29 | AB24: 2024-02-18 | AC24: 2024-03-16 | AD24: 2024-03-30
A25: 2024-01-05 | B25: 2024-01-25 | C25: 2024-01-25 | D25: 2024-01-18 | E25: 2024-01-05 | F25: 2023-12-30 | G25: 2024-02-27 | H25: 2024-03-05 | I25: 2024-02-24 | J25: 2024-02-24 | K25: 2024-03-14 | L25: 2024-01-20 | M25: 2024-02-17 | N25: 2024-02-03 | O25: 2024-02-24 | P25: 2024-03-16 | Q25: 2024-03-19 | R25: 2024-02-17 | S25: 2024-04-02 | T25: 2024-03-23 | U25: 2024-03-23 | V25: 2024-03-30 | W25: 2024-03-14 | X25: 2024-02-22 | Y25: 2024-02-20 | Z25: 2024-03-14
A26: 2024-01-20 | B26: 2024-02-08 | C26: 2024-02-02 | D26: 2024-01-20 | E26: 2024-01-13 | F26: 2024-01-05 | G26: 2024-03-05 | H26: 2024-03-07 | I26: 2024-02-27 | J26: 2024-02-27 | K26: 2024-03-12 | L26: 2024-01-17 | M26: 2024-02-22 | N26: 2024-02-15 | O26: 2024-03-05 | P26: 2024-03-23 | Q26: 2024-03-23 | R26: 2024-02-20 | S26: 2024-04-06 | T26: 2024-03-28 | U26: 2024-03-28 | V26: 2024-04-04
A27: 2024-01-18 | B27: 2024-02-03 | C27: 2024-02-10 | D27: 2024-02-01 | E27: 2024-01-10 | F27: 2024-02-01 | G27: 2024-03-09 | H27: 2024-03-12 | I27: 2024-03-07 | J27: 2024-03-05 | K27: 2024-03-21 | L27: 2024-01-31 | M27: 2024-02-27 | N27: 2024-02-17 | O27: 2024-03-09 | P27: 2024-03-26 | Q27: 2024-03-28 | R27: 2024-02-24 | S27: 2024-04-11 | T27: 2024-04-06
A28: 2024-02-01 | B28: 2024-02-15 | C28: 2024-02-01 | D28: 2024-02-18 | E28: 2024-01-18 | F28: 2024-02-15 | G28: 2024-03-12 | H28: 2024-03-16 | I28: 2024-03-09 | J28: 2024-03-07 | K28: 2024-03-26 | L28: 2024-02-15 | M28: 2024-03-07 | N28: 2024-02-20 | O28: 2024-03-12 | P28: 2024-03-30
A29: 2024-02-12 | B29: 2024-02-17 | C29: 2024-02-17 | D29: 2024-03-05 | E29: 2024-01-25 | F29: 2024-02-18 | G29: 2024-03-14 | H29: 2024-03-19 | I29: 2024-03-12 | J29: 2024-03-12 | K29: 2024-03-30 | L29: 2024-02-22 | M29: 2024-03-12 | N29: 2024-02-24 | O29: 2024-03-16 | P29: 2024-04-09
A30: 2024-02-22 | B30: 2024-02-22 | C30: 2024-02-22 | D30: 2024-03-07 | E30: 2024-02-01 | F30: 2024-02-17 | G30: 2024-03-19 | H30: 2024-03-23 | I30: 2024-03-16 | J30: 2024-03-21 | K30: 2024-04-06 | L30: 2024-02-24 | M30: 2024-03-14
A31: 2024-02-24 | B31: 2024-02-24 | C31: 2024-02-24 | D31: 2024-03-09 | E31: 2024-02-10 | F31: 2024-02-29 | G31: 2024-03-23 | H31: 2024-03-28 | I31: 2024-03-21 | J31: 2024-03-26 | K31: 2024-04-13
A32: 2024-02-15 | B32: 2024-02-29 | C32: 2024-02-29 | D32: 2024-03-21 | E32: 2024-02-15 | F32: 2024-03-05 | G32: 2024-03-28 | H32: 2024-04-04 | I32: 2024-03-26 | J32: 2024-03-30
A33: 2024-03-05 | B33: 2024-03-07 | C33: 2024-03-07 | D33: 2024-03-26 | E33: 2024-02-17 | F33: 2024-03-12 | G33: 2024-04-02 | H33: 2024-04-11 | I33: 2024-03-30 | J33: 2024-04-04
A34: 2024-03-07 | B34: 2024-03-12 | C34: 2024-03-09 | D34: 2024-03-30 | E34: 2024-02-22 | F34: 2024-03-07 | G34: 2024-04-09
A35: 2024-03-09 | B35: 2024-03-19 | C35: 2024-03-12 | D35: 2024-04-02 | E35: 2024-02-24
A36: 2024-03-21 | B36: 2024-03-23 | C36: 2024-03-14 | D36: 2024-04-09
A37: 2024-03-19 | B37: 2024-03-28
A38: 2024-03-28 | B38: 2024-04-04 | O38: <
A39: 2024-04-02
A40: 2024-04-09
...

Sheet AHL_DAT
A3: 2023-09-16 | B3: 2023-09-19 | C3: 2023-09-22 | D3: 2023-09-23 | E3: 2023-09-24 | F3: 2023-09-26 | G3: 2023-09-21 | H3: 2023-09-28 | I3: 2023-09-29 | J3: 2023-09-30 | K3: 2023-09-27 | L3: 2023-10-01 | M3: 2023-10-05 | N3: 2023-10-06 | O3: 2023-10-07 | P3: 2023-10-08 | Q3: 2023-10-14 | R3: 2023-10-15 | S3: 2023-10-12 | T3: 2023-10-21 | U3: 2023-10-17 | V3: 2023-10-19 | W3: 2023-11-01 | X3: 2023-11-03 | Y3: 2023-11-04 | Z3: 2023-11-05 | AA3: 2023-10-24 | AB3: 2023-10-26 | AC3: 2023-10-28 | AD3: 2023-11-17 | AE3: 2023-11-18 | AF3: 2023-11-14 | AG3: 2023-11-15 | AH3: 2023-11-16 | AI3: 2023-11-19 | AJ3: 2023-11-24 | AK3: 2023-11-21 | AL3: 2023-11-23 | AM3: 2023-11-25 | AN3: 2023-11-26 | AO3: 2023-11-28 | AP3: 2023-11-29 | AQ3: 2023-11-30 | AR3: 2023-12-01 | AS3: 2023-12-02 | AT3: 2023-12-03 | AU3: 2023-12-05 | AV3: 2023-12-09 | AW3: 2023-12-06 | AX3: 2023-12-07 | AY3: 2023-12-19 | AZ3: 2023-12-21 | BA3: 2023-12-26 | BB3: 2023-12-28 | BC3: 2023-12-23 | BD3: 2023-12-30 | BE3: 2024-01-05 | BF3: 2024-01-03 | BG3: 2024-01-02 | BH3: 2024-01-13 | BI3: 2024-01-10 | BJ3: 2024-01-11 | BK3: 2024-01-20 | BL3: 2024-01-17 | BM3: 2024-01-18 | BN3: 2024-01-27 | BO3: 2024-01-25 | BP3: 2024-02-02 | BQ3: 2024-01-31 | BR3: 2024-02-01 | BS3: 2024-02-03 | BT3: 2024-02-08 | BU3: 2024-02-10 | BV3: 2024-02-13 | BW3: 2024-02-12 | BX3: 2024-02-14 | BY3: 2024-02-15 | BZ3: 2024-02-17 | CA3: 2024-02-18 | CB3: 2024-02-20 | CC3: 2024-02-22 | CD3: 2024-02-24 | CE3: 2024-02-27 | CF3: 2024-02-29 | CG3: 2024-03-02 | CH3: 2024-03-05 | CI3: 2024-03-07 | CJ3: 2024-03-09 | CK3: 2024-03-12 | CL3: 2024-03-14 | CM3: 2024-03-16 | CN3: 2024-03-19 | CO3: 2024-03-21 | CP3: 2024-03-23 | CQ3: 2024-03-26 | CR3: 2024-03-28 | CS3: 2024-03-30 | CT3: 2024-04-02 | CU3: 2024-04-04 | CV3: 2024-04-06 | CW3: 2024-04-09 | CX3: 2024-04-11 | CY3: 2024-04-13
A4: GiacomozziFe | B4: MoidlDa | C4: BulovecMi | D4: BajtMi | E4: LegaSi | F4: BrockAd | G4: LesniakBo | H4: PinieOm | I4: BajtMi | J4: KummerSt | K4: SoraperraSi | L4: RuetzMa | M4: KainbergerJu | N4: BajtMi | O4: BenvegnuAn | P4: LazzeriAl | Q4: BenvegnuAn | R4: LazzeriAl | S4: MoidlDa | T4: HlavatyAl | U4: OrelSt | V4: MilovanovicJa | W4: HolzerTo | X4: RuetzMa | Y4: BrockAd | Z4: GiacomozziFe | AA4: FajdigaAl | AB4: BajtMi | AC4: LesniakBo | AD4: MoschenAn | AE4: BulovecMi | AF4: MoschenAn | AG4: HolzerTo | AH4: KummerSt | AI4: LazzeriAl | AJ4: KummerSt | AK4: BrockAd | AL4: BajtMi | AM4: HolzerTo | AN4: LazzeriAl | AO4: LesniakBo | AP4: GiacomozziFe | AQ4: KainbergerJu | AR4: BulovecMi | AS4: LehnerMo | AT4: MoschenAn | AU4: EggerTh | AV4: KummerSt | AW4: HolzerTo | AX4: LesniakBo | AY4: BulovecMi | AZ4: KainbergerJu | BA4: FajdigaAl | BB4: EggerTh | BC4: RuetzMa | BD4: HolzerTo | BE4: HlavatyAl | BF4: MilovanovicJa | BG4: KainbergerJu | BH4: OrelSt | BI4: HolzerTo | BJ4: OrelSt | BK4: BenvegnuAn | BL4: HolzerTo | BM4: BrockAd | BN4: BulovecMi | BO4: KummerSt | BP4: LesniakBo | BQ4: KainbergerJu | BR4: FajdigaAl | BS4: KummerSt | BT4: HlavatyAl | BU4: OrelSt | BV4: KainbergerJu | BW4: PinieOm | BX4: SchauerJa | BY4: FajdigaAl | BZ4: HlavatyAl | CA4: GiacomozziFe | CB4: MoschenAn | CC4: PirasAn | CD4: SpiegelSe | CE4: BajtMi | CF4: HolzerTo | CG4: HlavatyAl | CH4: KainbergerJu | CI4: LazzeriAl | CJ4: KainbergerJu | CK4: BulovecMi | CL4: BajtMi | CM4: BrockAd | CN4: BajtMi | CO4: HlavatyAl | CP4: BajtMi | CQ4: LazzeriAl | CR4: BulovecMi | CS4: PinieOm | CT4: LazzeriAl | CU4: BulovecMi | CV4: HlavatyAl | CW4: LazzeriAl | CX4: BulovecMi | CY4: HlavatyAl
A5: RivisFe | B5: RuetzMa | C5: KainbergerJu | D5: VirtaTu | E5: StefenelliFe | F5: LesniakBo | G5: MilovanovicJa | H5: RuetzMa | I5: LehnerMo | J5: SchauerJa | K5: SpiegelSe | L5: StefenelliFe | M5: LazzeriAl | N5: LesniakBo | O5: RiccoSt | P5: PinieOm | Q5: LegaSi | R5: RuetzMa | S5: RuetzMa | T5: MeixnerSe | U5: WidmannFl | V5: WuntschekDo | W5: PinieOm | X5: SpiegelSe | Y5: KainbergerJu | Z5: VirtaTu | AA5: WidmannFl | AB5: OrelSt | AC5: SchweighoferMa | AD5: RuetzMa | AE5: OrelSt | AF5: PinieOm | AG5: SchauerJa | AH5: WidmannFl | AI5: StefenelliFe | AJ5: OrelSt | AK5: WenuschHe | AL5: KainbergerJu | AM5: SpiegelSe | AN5: LegaSi | AO5: WenuschHe | AP5: SchauerJa | AQ5: LehnerMo | AR5: WidmannFl | AS5: VoicanCh | AT5: RuetzMa | AU5: LazzeriAl | AV5: VoicanCh | AW5: LegaSi | AX5: MeixnerSe | AY5: WidmannFl | AZ5: OrelSt | BA5: KummerSt | BB5: HolzerTo | BC5: SchauerJa | BD5: RuetzMa | BE5: VoicanCh | BF5: PinieOm | BG5: OrelSt | BH5: RuetzMa | BI5: RuetzMa | BJ5: SchauerJa | BK5: BrockAd | BL5: SpiegelSe | BM5: HlavatyAl | BN5: LesniakBo | BO5: WidmannFl | BP5: OrelSt | BQ5: SchauerJa | BR5: VoicanCh | BS5: PinieOm | BT5: HolzerTo | BU5: RuetzMa | BV5: MeixnerSe | BW5: RivisFe | BX5: SpiegelSe | BY5: WidmannFl | BZ5: VoicanCh | CA5: LazzeriAl | CB5: StefenelliFe | CC5: SchauerJa | CD5: VirtaTu | CE5: BulovecMi | CF5: VirtaTu | CG5: VoicanCh | CH5: LazzeriAl | CI5: OrelSt | CJ5: SchauerJa | CK5: HlavatyAl | CL5: HlavatyAl | CM5: BulovecMi | CN5: BulovecMi | CO5: RezekGr | CP5: BulovecMi | CQ5: RezekGr | CR5: HolzerTo | CS5: RezekGr | CT5: SchauerJa | CU5: HolzerTo | CV5: RezekGr | CW5: SchauerJa | CX5: RezekGr | CY5: HolzerTo
A6: MattheyPh | B6: DieberDo | C6: JeramFi | D6: BergantAn | E6: CusinFe | F6: DieberDo | G6: JeramFi | H6: CristeliMa | I6: MattheyPh | J6: EislCh | K6: De zordoMa | L6: FleischmannLu | M6: BrondiPa | N6: MurnikPe | O6: FecchioFe | P6: CristeliMa | Q6: GrisentiLu | R6: HesinaCh | S6: MattheyPh | T6: AngyalBo | U6: MurnikPe | V6: JavornikBl | W6: FleischmannLu | X6: JägerRi | Y6: BergantAn | Z6: FecchioFe | AA6: BergantAn | AB6: ArlicMa | AC6: JeramFi | AD6: AbeltinoSi | AE6: MarkizetiGr | AF6: De zordoMa | AG6: EislCh | AH6: KlemmAn | AI6: CristeliMa | AJ6: PuffWo | AK6: EislCh | AL6: ArlicMa | AM6: BrondiPa | AN6: CusinFe | AO6: LegatKo | AP6: FleischmannLu | AQ6: HesinaCh | AR6: MarkizetiGr | AS6: MattheyPh | AT6: HesinaCh | AU6: AbeltinoSi | AV6: KlemmAn | AW6: JägerRi | AX6: BergantAn | AY6: BergantAn | AZ6: EislCh | BA6: MurnikPe | BB6: PaceJa | BC6: FleischmannLu | BD6: JägerRi | BE6: LegatKo | BF6: BrondiPa | BG6: SeewaldJe | BH6: SeewaldJe | BI6: JägerRi | BJ6: HesinaCh | BK6: FleischmannLu | BL6: JägerRi | BM6: KanyoTa | BN6: BergantAn | BO6: MattheyPh | BP6: BergantAn | BQ6: HesinaCh | BR6: ArlicMa | BS6: FecchioFe | BT6: TelesklavFa | BU6: SeewaldJe | BV6: PötscherMi | BW6: De zordoMa | BX6: HesinaCh | BY6: JavornikBl | BZ6: KanyoTa | CA6: AbeltinoSi | CB6: BrondiPa | CC6: GrisentiLu | CD6: De zordoMa | CE6: BergantAn | CF6: CristeliMa | CG6: MoidlMa | CH6: De zordoMa | CI6: CristeliMa | CJ6: MoidlMa | CK6: JeramFi | CL6: ArlicMa | CM6: JeramFi | CN6: JeramFi | CO6: SeewaldJe | CP6: JeramFi | CQ6: EislCh | CR6: De zordoMa | CS6: EislCh | CT6: De zordoMa | CU6: SeewaldJe | CV6: FleischmannLu | CW6: De zordoMa | CX6: De zordoMa | CY6: PuffWo
A7: VignoloSi | B7: LegatKo | C7: MarkizetiGr | D7: FecchioFe | E7: De zordoMa | F7: SchonaklenerPa | G7: KlemmAn | H7: CusinFe | I7: TelesklavFa | J7: TelesklavFa | K7: JägerRi | L7: JägerRi | M7: EislCh | N7: TelesklavFa | O7: GrisentiLu | P7: De zordoMa | Q7: VignoloSi | R7: RinkerDa | S7: ZacherlPa | T7: PreiserJu | U7: PötscherMi | V7: WuchererGe | W7: RinkerDa | X7: PreiserJu | Y7: SeewaldJe | Z7: PaceJa | AA7: PötscherMi | AB7: SeewaldJe | AC7: PötscherMi | AD7: JägerRi | AE7: MurnikPe | AF7: RivisAn | AG7: JägerRi | AH7: TelesklavFa | AI7: FormaioniTh | AJ7: WuchererGe | AK7: PreiserJu | AL7: PötscherMi | AM7: De zordoMa | AN7: VignoloSi | AO7: MurnikPe | AP7: JägerRi | AQ7: MoidlMa | AR7: WendnerMa | AS7: MoidlMa | AT7: RinkerDa | AU7: De zordoMa | AV7: LegatKo | AW7: VignoloSi | AX7: JavornikBl | AY7: PuffWo | AZ7: PötscherMi | BA7: TelesklavFa | BB7: RinkerDa | BC7: SeewaldJe | BD7: SeewaldJe | BE7: WeissAl | BF7: JavornikBl | BG7: TelesklavFa | BH7: WuchererGe | BI7: RinkerDa | BJ7: MoidlMa | BK7: WendnerMa | BL7: RinkerDa | BM7: TelesklavFa | BN7: JavornikBl | BO7: PötscherMi | BP7: WendnerMa | BQ7: JägerRi | BR7: WeissAl | BS7: PuffWo | BT7: WeissAl | BU7: WuchererGe | BV7: WendnerMa | BW7: PaceJa | BX7: RinkerDa | BY7: TelesklavFa | BZ7: PuffWo | CA7: CristeliMa | CB7: FleischmannLu | CC7: RinkerDa | CD7: JägerRi | CE7: JeramFi | CF7: PaceJa | CG7: WeissAl | CH7: EislCh | CI7: PuffWo | CJ7: WeissAl | CK7: WeissAl | CL7: EislCh | CM7: PuffWo | CN7: PuffWo | CO7: WeissAl | CP7: PuffWo | CQ7: MoidlMa | CR7: PuffWo | CS7: SeewaldJe | CT7: FleischmannLu | CU7: WeissAl | CV7: PuffWo | CW7: MoidlMa | CX7: FleischmannLu | CY7: SeewaldJe
A8: BenvegnuAn | B8: LazzeriAl | D8: RuetzMa | G8: RezekGr | H8: BenvegnuAn | J8: HlavatyAl | L8: FajdigaAl | M8: OrelSt | O8: HolzerTo | Q8: FajdigaAl | S8: BulovecMi | T8: KummerSt | V8: BajtMi | W8: HlavatyAl | Y8: LazzeriAl | AA8: HolzerTo | AB8: KainbergerJu | AC8: BassoNi | AE8: GiacomozziFe | AH8: FajdigaAl | AL8: PinieOm | AM8: BenvegnuAn | AQ8: FajdigaAl | AS8: BenvegnuAn | AV8: LehnerMo | AX8: KainbergerJu | AY8: HolzerDa | AZ8: LesniakBo | BA8: SchweighoferMa | BB8: PinieOm | BD8: BajtMi | BE8: KummerSt | BF8: FajdigaAl | BH8: HlavatyAl | BK8: MoschenAn | BM8: BulovecMi | BN8: LegaSi | BO8: RuetzMa | BR8: OrelSt | BS8: BrockAd | BY8: MoschenAn | BZ8: BrockAd | CC8: HlavatyAl | CD8: OrelSt | CE8: PinieOm | CF8: OrelSt | CH8: HlavatyAl | CI8: BrockAd | CJ8: HlavatyAl | CK8: BrockAd | CL8: SchauerJa | CM8: KainbergerJu | CN8: HolzerTo | CO8: LazzeriAl | CP8: HolzerTo | CQ8: HlavatyAl | CR8: BajtMi | CS8: HlavatyAl
A9: RiccoSt | B9: SoraperraSi | D9: VoicanCh | G9: VoicanCh | H9: GiacomozziFe | J9: SchweighoferMa | L9: MoidlDa | M9: SchweighoferMa | O9: SpiegelSe | Q9: LesniakBo | S9: KummerSt | T9: SchweighoferMa | V9: BulovecMi | W9: OrelSt | Y9: MoschenAn | AA9: SchauerJa | AB9: WuntschekDo | AC9: LegaSi | AE9: HlavatyAl | AH9: LesniakBo | AL9: RuetzMa | AM9: PinieOm | AQ9: SchweighoferMa | AS9: EggerTh | AV9: MoidlDa | AX9: RuetzMa | AY9: VoicanCh | AZ9: MilovanovicJa | BA9: WuntschekDo | BB9: SpiegelSe | BD9: LazzeriAl | BE9: PinieOm | BF9: VoicanCh | BH9: HolzerTo | BK9: StefenelliFe | BM9: OrelSt | BN9: StefenelliFe | BO9: VoicanCh | BR9: RezekGr | BS9: WidmannFl | BY9: PirasAn | BZ9: LehnerMo | CC9: KainbergerJu | CD9: PinieOm | CE9: SchauerJa | CF9: RezekGr | CH9: VoicanCh | CI9: BulovecMi | CJ9: VirtaTu | CK9: PinieOm | CL9: VirtaTu | CM9: PinieOm | CN9: SchauerJa | CO9: PinieOm | CP9: SchauerJa | CQ9: PinieOm | CR9: SchauerJa | CS9: LazzeriAl
A10: AbeltinoSi | B10: De zordoMa | D10: LegatKo | G10: PreiserJu | H10: PaceJa | J10: LegatKo | L10: ArlicMa | M10: JavornikBl | O10: HesinaCh | Q10: MarkizetiGr | S10: TelesklavFa | T10: LegatKo | V10: KanyoTa | W10: LegatKo | Y10: SchonaklenerPa | AA10: JägerRi | AB10: HesinaCh | AC10: FormaioniTh | AE10: De zordoMa | AH10: BrondiPa | AL10: BrondiPa | AM10: GrisentiLu | AQ10: BergantAn | AS10: RivisAn | AV10: MattheyPh | AX10: EislCh | AY10: LegatKo | AZ10: JavornikBl | BA10: KlemmAn | BB10: BrondiPa | BD10: AbeltinoSi | BE10: FecchioFe | BF10: DieberDo | BH10: TelesklavFa | BK10: FecchioFe | BM10: ArlicMa | BN10: BrondiPa | BO10: LegatKo | BR10: JavornikBl | BS10: KanyoTa | BY10: FormaioniTh | BZ10: DieberDo | CC10: EislCh | CD10: PuffWo | CE10: RinkerDa | CF10: ArlicMa | CH10: MoidlMa | CI10: JeramFi | CJ10: FleischmannLu | CK10: CristeliMa | CL10: FleischmannLu | CM10: FleischmannLu | CN10: De zordoMa | CO10: De zordoMa | CP10: FleischmannLu | CQ10: SeewaldJe | CR10: FleischmannLu | CS10: MoidlMa
A11: De zordoMa | B11: GrisentiLu | D11: MattheyPh | G11: WeissAl | H11: VignoloSi | J11: PreiserJu | L11: MoidlMa | M11: MarkizetiGr | O11: RinkerDa | Q11: WuchererGe | S11: WendnerMa | T11: WeissAl | V11: WendnerMa | W11: SchonaklenerPa | Y11: WendnerMa | AA11: MartinFl | AB11: WuchererGe | AC11: VignoloSi | AE11: SeewaldJe | AH11: PaceJa | AL11: HesinaCh | AM11: RivisAn | AQ11: TelesklavFa | AS11: WiestAl | AV11: MoidlMa | AX11: RinkerDa | AY11: WeissAl | AZ11: JeramFi | BA11: MarkizetiGr | BB11: HesinaCh | BD11: MurnikPe | BE11: WuchererGe | BF11: MarkizetiGr | BH11: WeissAl | BK11: WeissAl | BM11: BergantAn | BN11: VignoloSi | BO11: WeissAl | BR11: TelesklavFa | BS11: WuchererGe | BY11: PaceJa | BZ11: WeissAl | CC11: SeewaldJe | CD11: WuchererGe | CE11: SeewaldJe | CF11: PuffWo | CH11: WeissAl | CI11: SeewaldJe | CJ11: PuffWo | CK11: EislCh | CL11: RinkerDa | CM11: MoidlMa | CN11: FleischmannLu | CO11: EislCh | CP11: MoidlMa | CQ11: WeissAl | CR11: JeramFi | CS11: WeissAl
A12: KainbergerJu | D12: GiacomozziFe | G12: MeixnerSe | H12: KainbergerJu | J12: BrockAd | M12: HlavatyAl | O12: BulovecMi | Q12: BrockAd | S12: KainbergerJu | T12: BassoNi | V12: KainbergerJu | W12: BenvegnuAn | Y12: SchauerJa | AB12: BulovecMi | AC12: RivisFe | AE12: MoidlDa | AH12: PirasAn | AL12: BulovecMi | AM12: KummerSt | AQ12: HlavatyAl | AS12: SoraperraSi | AV12: RivisFe | AX12: SchauerJa | AY12: RuetzMa | AZ12: HolzerTo | BA12: MeixnerSe | BB12: BajtMi | BD12: HlavatyAl | BE12: LehnerMo | BF12: BrockAd | BK12: BajtMi | BM12: VoicanCh | BN12: BajtMi | BO12: KainbergerJu | BR12: BenvegnuAn | BS12: PirasAn | BY12: HolzerTo | BZ12: MoidlDa | CC12: HolzerTo | CD12: EggerTh | CH12: BajtMi | CI12: HolzerTo | CJ12: BajtMi | CK12: HolzerTo | CL12: OrelSt
A13: PirasAn | D13: LazzeriAl | G13: MoidlDa | H13: PirasAn | J13: MeixnerSe | M13: VoicanCh | O13: WenuschHe | Q13: VoicanCh | S13: WidmannFl | T13: EggerTh | V13: MoidlDa | W13: StefenelliFe | Y13: VoicanCh | AB13: RezekGr | AC13: StefenelliFe | AE13: VoicanCh | AH13: VirtaTu | AL13: MilovanovicJa | AM13: OrelSt | AQ13: MeixnerSe | AS13: VirtaTu | AV13: VirtaTu | AX13: SpiegelSe | AY13: SchauerJa | AZ13: SpiegelSe | BA13: WidmannFl | BB13: BrockAd | BD13: WuntschekDo | BE13: VirtaTu | BF13: SchweighoferMa | BK13: HlavatyAl | BM13: WidmannFl | BN13: MeixnerSe | BO13: MoschenAn | BR13: LazzeriAl | BS13: StefenelliFe | BY13: StefenelliFe | BZ13: SchauerJa | CC13: VoicanCh | CD13: RuetzMa | CH13: SchauerJa | CI13: VirtaTu | CJ13: PinieOm | CK13: OrelSt | CL13: RezekGr
A14: CusinFe | D14: AbeltinoSi | G14: MoidlMa | H14: WendnerMa | J14: KanyoTa | M14: SchonaklenerPa | O14: KanyoTa | Q14: LegatKo | S14: HesinaCh | T14: De zordoMa | V14: MattheyPh | W14: De zordoMa | Y14: MoidlMa | AB14: MarkizetiGr | AC14: AbeltinoSi | AE14: DieberDo | AH14: CristeliMa | AL14: JavornikBl | AM14: PuffWo | AQ14: KanyoTa | AS14: De zordoMa | AV14: EislCh | AX14: FecchioFe | AY14: JägerRi | AZ14: JägerRi | BA14: SeewaldJe | BB14: JeramFi | BD14: LegatKo | BE14: De zordoMa | BF14: KanyoTa | BK14: MurnikPe | BM14: MoidlMa | BN14: JeramFi | BO14: PaceJa | BR14: CristeliMa | BS14: BrondiPa | BY14: BrondiPa | BZ14: LegatKo | CC14: JägerRi | CD14: BrondiPa | CH14: JeramFi | CI14: EislCh | CJ14: De zordoMa | CK14: FleischmannLu | CL14: BergantAn
A15: RivisAn | D15: CristeliMa | G15: SchonaklenerPa | H15: ZacherlPa | J15: ZacherlPa | M15: SeewaldJe | O15: LegatKo | Q15: SchonaklenerPa | S15: KanyoTa | T15: FormaioniTh | V15: MoidlMa | W15: FormaioniTh | Y15: PreiserJu | AB15: PuffWo | AC15: RivisAn | AE15: WeissAl | AH15: FormaioniTh | AL15: JeramFi | AM15: WuchererGe | AQ15: WeissAl | AS15: PaceJa | AV15: RinkerDa | AX15: JägerRi | AY15: RinkerDa | AZ15: RinkerDa | BA15: WendnerMa | BB15: KanyoTa | BD15: MarkizetiGr | BE15: MoidlMa | BF15: WendnerMa | BK15: PuffWo | BM15: SeewaldJe | BN15: KanyoTa | BO15: SeewaldJe | BR15: FormaioniTh | BS15: GrisentiLu | BY15: JägerRi | BZ15: MattheyPh | CC15: WeissAl | CD15: FleischmannLu | CH15: SeewaldJe | CI15: RinkerDa | CJ15: JeramFi | CK15: PuffWo | CL15: PuffWo
A16: LesniakBo | D16: HolzerTo | G16: MoschenAn | H16: LazzeriAl | J16: HolzerTo | M16: LehnerMo | O16: MeixnerSe | Q16: LehnerMo | S16: PinieOm | T16: RiccoSt | V16: LehnerMo | W16: BassoNi | Y16: HlavatyAl | AB16: BrockAd | AC16: KummerSt | AE16: LegaSi | AH16: LegaSi | AL16: SchauerJa | AM16: RuetzMa | AQ16: BrockAd | AS16: HolzerTo | AV16: FajdigaAl | AX16: GiacomozziFe | AY16: MoschenAn | AZ16: LazzeriAl | BA16: MoschenAn | BB16: KainbergerJu | BD16: LegaSi | BE16: BajtMi | BF16: HuberRe | BK16: HolzerTo | BM16: LazzeriAl | BN16: HlavatyAl | BO16: HolzerTo | BR16: MoschenAn | BS16: BulovecMi | BY16: GiacomozziFe | BZ16: HolzerTo | CC16: BajtMi | CD16: BulovecMi | CH16: BulovecMi | CI16: PinieOm | CJ16: LazzeriAl | CK16: KainbergerJu
A17: MilovanovicJa | D17: PinieOm | G17: RiccoSt | H17: RivisFe | J17: StefenelliFe | M17: SchauerJa | O17: WuntschekDo | Q17: PirasAn | S17: StefenelliFe | T17: VirtaTu | V17: WenuschHe | W17: MoidlDa | Y17: WenuschHe | AB17: HlavatyAl | AC17: MilovanovicJa | AE17: RivisFe | AH17: SoraperraSi | AL17: WidmannFl | AM17: StefenelliFe | AQ17: OrelSt | AS17: SpiegelSe | AV17: OrelSt | AX17: PinieOm | AY17: PinieOm | AZ17: PirasAn | BA17: RuetzMa | BB17: LehnerMo | BD17: SchauerJa | BE17: WidmannFl | BF17: SoraperraSi | BK17: PirasAn | BM17: SchauerJa | BN17: WenuschHe | BO17: SoraperraSi | BR17: RuetzMa | BS17: MilovanovicJa | BY17: RuetzMa | BZ17: RuetzMa | CC17: RuetzMa | CD17: RezekGr | CH17: RezekGr | CI17: RezekGr | CJ17: OrelSt | CK17: SchauerJa
A18: BergantAn | D18: HesinaCh | G18: EislCh | H18: De zordoMa | J18: JägerRi | M18: MattheyPh | O18: MoidlMa | Q18: MattheyPh | S18: CristeliMa | T18: FecchioFe | V18: DieberDo | W18: AbeltinoSi | Y18: AngyalBo | AB18: WeissAl | AC18: MurnikPe | AE18: RivisAn | AH18: CusinFe | AL18: MattheyPh | AM18: HesinaCh | AQ18: AngyalBo | AS18: LegatKo | AV18: MurnikPe | AX18: CusinFe | AY18: BrondiPa | AZ18: BrondiPa | BA18: GrisentiLu | BB18: EislCh | BD18: RinkerDa | BE18: ArlicMa | BF18: FecchioFe | BK18: BrondiPa | BM18: BrondiPa | BN18: EislCh | BO18: FecchioFe | BR18: De zordoMa | BS18: AbeltinoSi | BY18: CristeliMa | BZ18: HesinaCh | CC18: CusinFe | CD18: ArlicMa | CH18: BergantAn | CI18: ArlicMa | CJ18: ArlicMa | CK18: RinkerDa
A19: MarkizetiGr | D19: PaceJa | G19: ZacherlPa | H19: RivisAn | J19: PaceJa | M19: RinkerDa | O19: PreiserJu | Q19: WiestAl | S19: CusinFe | T19: RivisAn | V19: SchonaklenerPa | W19: SeewaldJe | Y19: DieberDo | AB19: WendnerMa | AC19: WendnerMa | AE19: WiestAl | AH19: VignoloSi | AL19: MoidlMa | AM19: RinkerDa | AQ19: MattheyPh | AS19: PreiserJu | AV19: PuffWo | AX19: FormaioniTh | AY19: De zordoMa | AZ19: PaceJa | BA19: HesinaCh | BB19: MattheyPh | BD19: VignoloSi | BE19: PuffWo | BF19: JägerRi | BK19: JägerRi | BM19: De zordoMa | BN19: MoidlMa | BO19: RinkerDa | BR19: RinkerDa | BS19: MurnikPe | BY19: FecchioFe | BZ19: RinkerDa | CC19: FecchioFe | CD19: BergantAn | CH19: CristeliMa | CI19: De zordoMa | CJ19: BergantAn | CK19: SeewaldJe
A20: OrelSt | D20: BenvegnuAn | G20: SpiegelSe | H20: OrelSt | J20: EggerTh | M20: SoraperraSi | O20: LazzeriAl | Q20: MoschenAn | S20: RivisFe | T20: LazzeriAl | V20: BrockAd | W20: RuetzMa | Y20: LehnerMo | AB20: HolzerTo | AC20: MoschenAn | AE20: KainbergerJu | AH20: BenvegnuAn | AL20: MoschenAn | AM20: SoraperraSi | AQ20: PinieOm | AS20: GiacomozziFe | AV20: RiccoSt | AX20: MoidlDa | AY20: LegaSi | AZ20: RiccoSt | BA20: KainbergerJu | BB20: LesniakBo | BD20: BulovecMi | BE20: BulovecMi | BF20: MoschenAn | BK20: LegaSi | BM20: GiacomozziFe | BN20: EggerTh | BO20: BajtMi | BR20: GiacomozziFe | BS20: LegaSi | BY20: BenvegnuAn | BZ20: MoschenAn | CC20: KummerSt | CD20: BrockAd
A21: WenuschHe | D21: MoschenAn | G21: StefenelliFe | H21: WidmannFl | J21: PirasAn | M21: VirtaTu | O21: PirasAn | Q21: SchauerJa | S21: VirtaTu | T21: MoschenAn | V21: RuetzMa | W21: WidmannFl | Y21: LesniakBo | AB21: SpiegelSe | AC21: OrelSt | AE21: MeixnerSe | AH21: LazzeriAl | AL21: VirtaTu | AM21: VirtaTu | AQ21: StefenelliFe | AS21: RiccoSt | AV21: SoraperraSi | AX21: OrelSt | AY21: RivisFe | AZ21: StefenelliFe | BA21: OrelSt | BB21: VirtaTu | BD21: WidmannFl | BE21: HolzerTo | BF21: RuetzMa | BK21: PinieOm | BM21: RuetzMa | BN21: GiacomozziFe | BO21: OrelSt | BR21: VirtaTu | BS21: SoraperraSi | BY21: RiccoSt | BZ21: WidmannFl | CC21: LesniakBo | CD21: VoicanCh
A22: MoidlMa | D22: BrondiPa | G22: AbeltinoSi | H22: GrisentiLu | J22: AbeltinoSi | M22: CristeliMa | O22: FleischmannLu | Q22: De zordoMa | S22: PaceJa | T22: JägerRi | V22: SeewaldJe | W22: HesinaCh | Y22: ArlicMa | AB22: BrondiPa | AC22: SeewaldJe | AE22: MoidlMa | AH22: FecchioFe | AL22: CristeliMa | AM22: FecchioFe | AQ22: GrisentiLu | AS22: BrondiPa | AV22: De zordoMa | AX22: PötscherMi | AY22: RivisAn | AZ22: AbeltinoSi | BA22: PuffWo | BB22: BergantAn | BD22: ArlicMa | BE22: BergantAn | BF22: De zordoMa | BK22: CusinFe | BM22: AbeltinoSi | BN22: AbeltinoSi | BO22: ArlicMa | BR22: BrondiPa | BS22: CusinFe | BY22: GrisentiLu | BZ22: FleischmannLu | CC22: JavornikBl | CD22: KanyoTa
A23: SchonaklenerPa | D23: CusinFe | G23: CristeliMa | H23: WuchererGe | J23: WiestAl | M23: PaceJa | O23: VignoloSi | Q23: SeewaldJe | S23: RivisAn | T23: RinkerDa | V23: TelesklavFa | W23: TelesklavFa | Y23: MattheyPh | AB23: RinkerDa | AC23: WiestAl | AE23: WendnerMa | AH23: GrisentiLu | AL23: CusinFe | AM23: MantovaniDa | AQ23: PaceJa | AS23: FleischmannLu | AV23: PaceJa | AX23: PuffWo | AY23: VignoloSi | AZ23: GrisentiLu | BA23: WuchererGe | BB23: De zordoMa | BD23: PuffWo | BE23: SeewaldJe | BF23: HesinaCh | BK23: De zordoMa | BM23: FormaioniTh | BN23: FormaioniTh | BO23: WuchererGe | BR23: RivisAn | BS23: RivisAn | BY23: WiestAl | BZ23: TelesklavFa | CC23: MurnikPe | CD23: WeissAl
A24: BrockAd | G24: OrelSt | H24: BajtMi | J24: BulovecMi | M24: EggerTh | O24: MilovanovicJa | Q24: RiccoSt | S24: EggerTh | T24: PinieOm | V24: PinieOm | W24: SoraperraSi | Y24: HolzerTo | AB24: RuetzMa | AC24: LehnerMo | AE24: LazzeriAl | AL24: EggerTh | AM24: LazzeriAl | AQ24: LazzeriAl | AS24: BajtMi | AV24: BenvegnuAn | AY24: BenvegnuAn | AZ24: GiacomozziFe | BA24: LazzeriAl | BB24: RiccoSt | BD24: LehnerMo | BE24: LegaSi | BF24: GiacomozziFe | BK24: FajdigaAl | BM24: LesniakBo | BO24: BulovecMi | BS24: HolzerTo | BY24: LegaSi | BZ24: OrelSt | CC24: BenvegnuAn | CD24: KainbergerJu
A25: MeixnerSe | G25: PirasAn | H25: VirtaTu | J25: WuntschekDo | M25: MoschenAn | O25: SchweighoferMa | Q25: SpiegelSe | S25: RiccoSt | T25: PirasAn | V25: VirtaTu | W25: WuntschekDo | Y25: WuntschekDo | AB25: SchauerJa | AC25: MeixnerSe | AE25: StefenelliFe | AL25: PirasAn | AM25: LegaSi | AQ25: PirasAn | AS25: SchauerJa | AV25: PirasAn | AY25: GiacomozziFe | AZ25: MoschenAn | BA25: LehnerMo | BB25: StefenelliFe | BD25: MoidlDa | BE25: RuetzMa | BF25: RiccoSt | BK25: GiacomozziFe | BM25: VirtaTu | BO25: RezekGr | BS25: SpiegelSe | BY25: SoraperraSi | BZ25: PinieOm | CC25: OrelSt | CD25: MoschenAn
A26: WendnerMa | G26: GrisentiLu | H26: BergantAn | J26: ArlicMa | M26: AbeltinoSi | O26: JeramFi | Q26: FleischmannLu | S26: AbeltinoSi | T26: FleischmannLu | V26: CristeliMa | W26: BrondiPa | Y26: JägerRi | AB26: De zordoMa | AC26: KanyoTa | AE26: CristeliMa | AL26: AbeltinoSi | AM26: CusinFe | AQ26: BrondiPa | AS26: ArlicMa | AV26: BrondiPa | AY26: CristeliMa | AZ26: FormaioniTh | BA26: FleischmannLu | BB26: FecchioFe | BD26: EislCh | BE26: CusinFe | BF26: FormaioniTh | BK26: JeramFi | BM26: JavornikBl | BO26: MarkizetiGr | BS26: MattheyPh | BY26: De zordoMa | BZ26: BrondiPa | CC26: De zordoMa | CD26: EislCh
A27: ZacherlPa | G27: WuchererGe | H27: FecchioFe | J27: BergantAn | M27: De zordoMa | O27: WuchererGe | Q27: JägerRi | S27: FecchioFe | T27: GrisentiLu | V27: RinkerDa | W27: WuchererGe | Y27: PötscherMi | AB27: PaceJa | AC27: MoidlMa | AE27: FormaioniTh | AL27: GrisentiLu | AM27: VignoloSi | AQ27: FecchioFe | AS27: SeewaldJe | AV27: CristeliMa | AY27: FormaioniTh | AZ27: VignoloSi | BA27: MattheyPh | BB27: WiestAl | BD27: MoidlMa | BE27: RinkerDa | BF27: GrisentiLu | BK27: RivisAn | BM27: PaceJa | BO27: TelesklavFa | BS27: MoidlMa | BY27: RivisAn | BZ27: CristeliMa | CC27: PuffWo | CD27: SeewaldJe
A28: HolzerTo | G28: PinieOm | M28: GiacomozziFe | O28: BajtMi | S28: GiacomozziFe | T28: BrockAd | V28: HolzerTo | W28: EggerTh | Y28: BajtMi | AB28: BenvegnuAn | AC28: PirasAn | AL28: LehnerMo | AM28: MoschenAn | AS28: MilovanovicJa | AV28: BulovecMi | AY28: MilovanovicJa | AZ28: EggerTh | BA28: LegaSi | BB28: SoraperraSi | BD28: KummerSt | BE28: LazzeriAl | BF28: EggerTh | BK28: KainbergerJu | BS28: HlavatyAl | CC28: BulovecMi | CD28: HolzerTo
A29: LegaSi | G29: RivisFe | M29: PirasAn | O29: RuetzMa | S29: SoraperraSi | T29: WidmannFl | V29: LegaSi | W29: FajdigaAl | Y29: BulovecMi | AB29: SoraperraSi | AC29: RiccoSt | AL29: WuntschekDo | AM29: RivisFe | AS29: StefenelliFe | AV29: WidmannFl | AY29: WuntschekDo | AZ29: VirtaTu | BA29: SoraperraSi | BB29: WuntschekDo | BD29: StefenelliFe | BE29: SchauerJa | BF29: PirasAn | BK29: LazzeriAl | BS29: LehnerMo | CC29: RezekGr | CD29: LehnerMo
A30: MartinFl | G30: BrondiPa | M30: CusinFe | O30: ArlicMa | S30: BrondiPa | T30: SeewaldJe | V30: CusinFe | W30: CristeliMa | Y30: CristeliMa | AB30: CristeliMa | AC30: CristeliMa | AL30: KanyoTa | AM30: CristeliMa | AS30: CusinFe | AV30: JeramFi | AY30: JeramFi | AZ30: CristeliMa | BA30: CristeliMa | BB30: CristeliMa | BD30: CristeliMa | BE30: CristeliMa | BF30: PaceJa | BK30: AbeltinoSi | BS30: EislCh | CC30: BergantAn | CD30: LegatKo
A31: PaceJa | G31: VignoloSi | M31: RivisAn | O31: BergantAn | S31: VignoloSi | T31: TelesklavFa | V31: JägerRi | W31: JavornikBl | Y31: CusinFe | AB31: CusinFe | AC31: FecchioFe | AL31: TelesklavFa | AM31: FormaioniTh | AS31: JeramFi | AV31: MiklicGr | AY31: MarkizetiGr | AZ31: FecchioFe | BA31: CusinFe | BB31: TelesklavFa | BD31: WuchererGe | BE31: JägerRi | BF31: RivisAn | BK31: GrisentiLu | BS31: SeewaldJe | CC31: JeramFi | CD31: WendnerMa
T32: LesniakBo | V32: RiccoSt | AC32: GiacomozziFe | AY32: BrockAd | AZ32: BenvegnuAn | BA32: BenvegnuAn | BB32: GiacomozziFe | BD32: BenvegnuAn | BE32: BenvegnuAn
T33: RezekGr | V33: StefenelliFe | AC33: LazzeriAl | AY33: OrelSt | AZ33: SoraperraSi | BA33: SpiegelSe | BB33: PirasAn | BD33: MoschenAn | BE33: StefenelliFe
T34: BergantAn | V34: AbeltinoSi | AC34: GrisentiLu | AY34: DieberDo | AZ34: CusinFe | BA34: FormaioniTh | BB34: FormaioniTh | BD34: CusinFe | BE34: AbeltinoSi
T35: JeramFi | V35: BrondiPa | AC35: PaceJa | AY35: MattheyPh | AZ35: De zordoMa | BA35: JägerRi | BB35: RivisAn | BD35: GrisentiLu | BE35: FleischmannLu

Sheet AHL_DAT_STRING
A3: 2023-09-16 | B3: 2023-09-19 | C3: 2023-09-22 | D3: 2023-09-23 | E3: 2023-09-24 | F3: 2023-09-26 | G3: 2023-09-21 | H3: 2023-09-28 | I3: 2023-09-29 | J3: 2023-09-30 | K3: 2023-09-27 | L3: 2023-10-01 | M3: 2023-10-05 | N3: 2023-10-06 | O3: 2023-10-07 | P3: 2023-10-08 | Q3: 2023-10-14 | R3: 2023-10-15 | S3: 2023-10-12 | T3: 2023-10-21 | U3: 2023-10-17 | V3: 2023-10-19 | W3: 2023-11-01 | X3: 2023-11-03 | Y3: 2023-11-04 | Z3: 2023-11-05 | AA3: 2023-10-24 | AB3: 2023-10-26 | AC3: 2023-10-28 | AD3: 2023-11-17 | AE3: 2023-11-18 | AF3: 2023-11-14 | AG3: 2023-11-15 | AH3: 2023-11-16 | AI3: 2023-11-19 | AJ3: 2023-11-24 | AK3: 2023-11-21 | AL3: 2023-11-23 | AM3: 2023-11-25 | AN3: 2023-11-26 | AO3: 2023-11-28 | AP3: 2023-11-29 | AQ3: 2023-11-30 | AR3: 2023-12-01 | AS3: 2023-12-02 | AT3: 2023-12-03 | AU3: 2023-12-05 | AV3: 2023-12-09 | AW3: 2023-12-06 | AX3: 2023-12-07 | AY3: 2023-12-19 | AZ3: 2023-12-21 | BA3: 2023-12-26 | BB3: 2023-12-28 | BC3: 2023-12-23 | BD3: 2023-12-30 | BE3: 2024-01-05 | BF3: 2024-01-03 | BG3: 2024-01-02 | BH3: 2024-01-13 | BI3: 2024-01-10 | BJ3: 2024-01-11 | BK3: 2024-01-20 | BL3: 2024-01-17 | BM3: 2024-01-18 | BN3: 2024-01-27 | BO3: 2024-01-25 | BP3: 2024-02-02 | BQ3: 2024-01-31 | BR3: 2024-02-01 | BS3: 2024-02-03 | BT3: 2024-02-08 | BU3: 2024-02-10 | BV3: 2024-02-13 | BW3: 2024-02-12 | BX3: 2024-02-14 | BY3: 2024-02-15 | BZ3: 2024-02-17 | CA3: 2024-02-18 | CB3: 2024-02-20 | CC3: 2024-02-22 | CD3: 2024-02-24 | CE3: 2024-02-27 | CF3: 2024-02-29 | CG3: 2024-03-02 | CH3: 2024-03-05 | CI3: 2024-03-07 | CJ3: 2024-03-09 | CK3: 2024-03-12 | CL3: 2024-03-14 | CM3: 2024-03-16 | CN3: 2024-03-19 | CO3: 2024-03-21 | CP3: 2024-03-23 | CQ3: 2024-03-26 | CR3: 2024-03-28 | CS3: 2024-03-30 | CT3: 2024-04-02 | CU3: 2024-04-04 | CV3: 2024-04-06 | CW3: 2024-04-09 | CX3: 2024-04-11 | CY3: 2024-04-13
