Workbook

Sheet AHL
A1: =COUNTIF(A4:A50,"<>") -> 34 | B1: =COUNTIF(B4:B50,"<>") -> 34 | C1: =COUNTIF(C4:C50,"<>") -> 30 | D1: =COUNTIF(D4:D50,"<>") -> 30 | E1: =COUNTIF(E4:E50,"<>") -> 30 | F1: =COUNTIF(F4:F50,"<>") -> 29 | G1: =COUNTIF(G4:G50,"<>") -> 28 | H1: =COUNTIF(H4:H50,"<>") -> 27 | ... BI1: =COUNTIF(BI4:BI50,"<>") -> 1
A2: it | B2: au | C2: au | D2: au | E2: au | F2: au | G2: it | H2: it | I2: au | J2: au | K2: au | L2: it | M2: it | N2: it | O2: it | P2: it | Q2: it | R2: it | S2: it | T2: au | U2: sl | V2: it | W2: it | X2: sl | Y2: sl | Z2: it | AA2: it | AB2: it | AC2: au | AD2: au | AE2: au | AF2: au | AG2: sl | AH2: sl | AI2: sl | AJ2: au | AK2: sl | AL2: sl | AM2: it | AN2: au | AO2: sl | AP2: it | AQ2: au | AR2: it | AS2: au | AT2: au | AU2: au | AV2: sl | AW2: au | AX2: au | AY2: sl | AZ2: au | BA2: it | BB2: it | BC2: sl | BD2: au | BE2: au | BF2: au | BG2: au | BH2: au | BI2: au
A3: LazzeriAl | B3: Huber rRe | C3: WinklerDa | D3: UnterwegerDo | E3: OrelSt | F3: StrimitzerDa | G3: MoschenAn | H3: BrondiPa | I3: DivisDo | J3: WuchererGe | K3: RinkerDa | L3: FecchioFe | M3: PinieOm | N3: GrisentiLu | O3: RivisAn | P3: AbeltinoSi | Q3: VirtaTu | R3: IlmerNo | S3: CristeliMa | T3: VeselkaMa | U3: BulovecMi | V3: StefenelliFe | W3: RivisFe | X3: SnojTa | Y3: BergantAn | Z3: BrondiMa | AA3: BenvegnuAn | AB3: PirasAn | AC3: SpiegelSe | AD3: BrockAd | AE3: PreiserJu | AF3: WendnerMa | AG3: LebenJa | AH3: ArlicMa | AI3: MarkizetiGr | AJ3: LegatKo | AK3: MiklicGr | AL3: MetzingerFi | AM3: CusinFe | AN3: HolzerTo | AO3: MurnikPe | AP3: GiacomozziFe | AQ3: HlavatyAl | AR3: FleischmannLu | AS3: RuetzMa | AT3: Steiner fFe | AU3: VoicanCh | AV3: JeramFi | AW3: SeewaldJe | AX3: ZacherlPa | AY3: BergeljNi | AZ3: Dummermuth-haasEl | BA3: SoraperraSi | BB3: CalloviniAn | BC3: BajtMi | BD3: WidmannFl | BE3: MoidlMa | BF3: KeldererMo | BG3: MoidlDa | BH3: MattheyPh | BI3: SparerDa
A4: 2025-09-20 | B4: 2025-09-20 | C4: 2025-09-20 | D4: 2025-09-26 | E4: 2025-09-25 | F4: 2025-09-20 | G4: 2025-09-20 | H4: 2025-09-20 | I4: 2025-09-20 | J4: 2025-09-26 | K4: 2025-09-27 | L4: 2025-09-20 | M4: 2025-09-20 | N4: 2025-09-20 | O4: 2025-09-21 | P4: 2025-09-20 | Q4: 2025-09-20 | R4: 2025-09-20 | S4: 2025-10-02 | T4: 2025-09-27 | U4: 2025-09-26 | V4: 2025-09-20 | W4: 2025-09-21 | X4: 2025-09-27 | Y4: 2025-09-27 | Z4: 2025-09-21 | AA4: 2025-09-21 | AB4: 2025-09-20 | AC4: 2025-09-27 | AD4: 2025-09-20 | AE4: 2025-09-20 | AF4: 2025-09-20 | AG4: 2025-09-27 | AH4: 2025-10-02 | AI4: 2025-09-27 | AJ4: 2025-10-11 | AK4: 2025-09-26 | AL4: 2025-10-02 | AM4: 2025-09-20 | AN4: 2025-09-25 | AO4: 2025-10-02 | AP4: 2025-10-11 | AQ4: 2025-10-04 | AR4: 2025-10-11 | AS4: 2025-09-20 | AT4: 2025-09-25 | AU4: 2025-10-04 | AV4: 2025-09-27 | AW4: 2025-10-14 | AX4: 2025-10-04 | AY4: 2025-10-16 | AZ4: 2025-10-28 | BA4: 2025-10-18 | BB4: 2025-12-04 | BC4: 2025-10-14 | BD4: 2025-10-25 | BE4: 2025-10-23 | BF4: 2025-12-30 | BG4: 2025-12-30 | BH4: 2025-12-30 | BI4: 2026-02-21
A5: 2025-09-25 | B5: 2025-09-25 | C5: 2025-09-27 | D5: 2025-10-04 | E5: 2025-10-04 | F5: 2025-09-27 | G5: 2025-09-27 | H5: 2025-09-25 | I5: 2025-10-01 | J5: 2025-09-25 | K5: 2025-09-25 | L5: 2025-09-25 | M5: 2025-09-27 | N5: 2025-09-25 | O5: 2025-09-27 | P5: 2025-09-27 | Q5: 2025-09-27 | R5: 2025-09-27 | S5: 2025-10-04 | T5: 2025-09-25 | U5: 2025-10-02 | V5: 2025-09-25 | W5: 2025-09-27 | X5: 2025-09-25 | Y5: 2025-09-25 | Z5: 2025-10-02 | AA5: 2025-09-25 | AB5: 2025-09-27 | AC5: 2025-09-25 | AD5: 2025-09-27 | AE5: 2025-09-27 | AF5: 2025-10-09 | AG5: 2025-09-25 | AH5: 2025-10-04 | AI5: 2025-09-25 | AJ5: 2025-10-18 | AK5: 2025-09-27 | AL5: 2025-10-04 | AM5: 2025-10-02 | AN5: 2025-10-01 | AO5: 2025-10-04 | AP5: 2025-10-16 | AQ5: 2025-10-09 | AR5: 2025-10-07 | AS5: 2025-09-27 | AT5: 2025-10-14 | AU5: 2025-10-09 | AV5: 2025-09-25 | AW5: 2025-11-18 | AX5: 2025-10-18 | AY5: 2025-11-20 | AZ5: 2025-11-22 | BA5: 2025-11-20 | BB5: 2025-12-22 | BC5: 2025-11-20 | BD5: 2025-11-14 | BE5: 2025-11-27
A6: 2025-10-04 | B6: 2025-10-02 | C6: 2025-10-01 | D6: 2025-10-11 | E6: 2025-10-11 | F6: 2025-10-11 | G6: 2025-10-04 | H6: 2025-10-02 | I6: 2025-10-09 | J6: 2025-10-04 | K6: 2025-10-01 | L6: 2025-10-02 | M6: 2025-10-02 | N6: 2025-10-04 | O6: 2025-10-02 | P6: 2025-10-02 | Q6: 2025-10-04 | R6: 2025-10-04 | S6: 2025-11-01 | T6: 2025-10-10 | U6: 2025-10-04 | V6: 2025-10-02 | W6: 2025-10-04 | X6: 2025-10-02 | Y6: 2025-10-02 | Z6: 2025-09-27 | AA6: 2025-10-04 | AB6: 2025-10-02 | AC6: 2025-10-04 | AD6: 2025-10-10 | AE6: 2025-10-17 | AF6: 2025-10-18 | AG6: 2025-10-02 | AH6: 2025-10-18 | AI6: 2025-10-09 | AJ6: 2025-10-30 | AK6: 2025-09-25 | AL6: 2025-10-11 | AM6: 2025-10-09 | AN6: 2025-10-09 | AO6: 2025-10-18 | AP6: 2025-10-18 | AQ6: 2025-10-18 | AR6: 2025-10-31 | AS6: 2025-11-01 | AT6: 2025-11-01 | AU6: 2025-10-17 | AV6: 2025-10-04 | AW6: 2025-11-29 | AX6: 2025-12-06 | AY6: 2025-11-27 | AZ6: 2025-12-26 | BA6: 2025-12-18 | BB6: 2026-01-22 | BC6: 2025-12-18 | BD6: 2026-01-02 | BE6: 2025-12-30
A7: 2025-10-11 | B7: 2025-10-11 | C7: 2025-10-02 | D7: 2025-10-16 | E7: 2025-10-16 | F7: 2025-10-09 | G7: 2025-10-10 | H7: 2025-10-04 | I7: 2025-10-14 | J7: 2025-10-11 | K7: 2025-10-11 | L7: 2025-10-04 | M7: 2025-10-07 | N7: 2025-10-07 | O7: 2025-10-04 | P7: 2025-10-11 | Q7: 2025-10-10 | R7: 2025-10-11 | S7: 2025-10-11 | T7: 2025-10-18 | U7: 2025-10-11 | V7: 2025-10-11 | W7: 2025-10-11 | X7: 2025-10-10 | Y7: 2025-10-11 | Z7: 2025-10-11 | AA7: 2025-10-09 | AB7: 2025-10-14 | AC7: 2025-10-09 | AD7: 2025-10-14 | AE7: 2025-10-25 | AF7: 2025-10-25 | AG7: 2025-10-11 | AH7: 2025-10-23 | AI7: 2025-10-14 | AJ7: 2025-10-09 | AK7: 2025-10-02 | AL7: 2025-10-23 | AM7: 2025-10-23 | AN7: 2025-10-25 | AO7: 2025-10-30 | AP7: 2025-10-25 | AQ7: 2025-10-30 | AR7: 2025-11-13 | AS7: 2025-11-15 | AT7: 2025-10-23 | AU7: 2025-11-01 | AV7: 2025-10-10 | AW7: 2025-12-20 | AX7: 2025-12-30 | AY7: 2026-01-06 | AZ7: 2026-01-02 | BA7: 2026-01-22 | BB7: 2026-02-24
A8: 2025-10-07 | B8: 2025-10-09 | C8: 2025-10-11 | D8: 2025-10-18 | E8: 2025-10-18 | F8: 2025-10-18 | G8: 2025-10-14 | H8: 2025-09-27 | I8: 2025-10-16 | J8: 2025-10-14 | K8: 2025-10-09 | L8: 2025-10-10 | M8: 2025-10-14 | N8: 2025-10-16 | O8: 2025-10-11 | P8: 2025-10-18 | Q8: 2025-10-23 | R8: 2025-10-07 | S8: 2025-10-10 | T8: 2025-10-25 | U8: 2025-10-09 | V8: 2025-10-07 | W8: 2025-10-16 | X8: 2025-10-25 | Y8: 2025-10-18 | Z8: 2025-10-23 | AA8: 2025-10-14 | AB8: 2025-10-18 | AC8: 2025-10-16 | AD8: 2025-10-18 | AE8: 2025-10-26 | AF8: 2025-10-16 | AG8: 2025-10-18 | AH8: 2025-10-30 | AI8: 2025-10-31 | AJ8: 2025-10-16 | AK8: 2025-10-14 | AL8: 2025-10-30 | AM8: 2025-10-18 | AN8: 2025-11-12 | AO8: 2025-11-01 | AP8: 2025-10-30 | AQ8: 2025-11-01 | AR8: 2025-11-20 | AS8: 2025-11-22 | AT8: 2025-10-16 | AU8: 2025-11-20 | AV8: 2025-10-23 | AW8: 2026-01-04 | AX8: 2026-01-06 | AY8: 2026-01-31 | AZ8: 2026-01-31 | BA8: 2026-02-19
A9: 2025-10-16 | B9: 2025-10-18 | C9: 2025-10-09 | D9: 2025-10-25 | E9: 2025-10-07 | F9: 2025-10-23 | G9: 2025-10-18 | H9: 2025-10-16 | I9: 2025-10-25 | J9: 2025-10-18 | K9: 2025-10-17 | L9: 2025-10-14 | M9: 2025-11-01 | N9: 2025-10-18 | O9: 2025-10-25 | P9: 2025-11-01 | Q9: 2025-10-30 | R9: 2025-10-18 | S9: 2025-11-15 | T9: 2025-10-26 | U9: 2025-10-16 | V9: 2025-11-01 | W9: 2025-10-25 | X9: 2025-10-26 | Y9: 2025-10-25 | Z9: 2025-10-30 | AA9: 2025-10-18 | AB9: 2025-11-01 | AC9: 2025-11-01 | AD9: 2025-10-25 | AE9: 2025-11-01 | AF9: 2025-11-14 | AG9: 2025-10-31 | AH9: 2025-10-11 | AI9: 2025-10-23 | AJ9: 2025-11-09 | AK9: 2025-10-25 | AL9: 2025-11-13 | AM9: 2025-11-01 | AN9: 2025-11-29 | AO9: 2025-11-13 | AP9: 2025-11-08 | AQ9: 2025-11-22 | AR9: 2025-12-04 | AS9: 2025-11-29 | AT9: 2025-11-22 | AU9: 2025-11-25 | AV9: 2025-11-29 | AW9: 2025-12-26 | AX9: 2026-01-24 | AY9: 2026-02-07 | AZ9: 2026-02-05
A10: 2025-10-25 | B10: 2025-10-23 | C10: 2025-10-17 | D10: 2025-11-01 | E10: 2025-10-29 | F10: 2025-10-28 | G10: 2025-10-25 | H10: 2025-10-25 | I10: 2025-11-01 | J10: 2025-11-01 | K10: 2025-10-25 | L10: 2025-10-25 | M10: 2025-10-23 | N10: 2025-10-25 | O10: 2025-11-01 | P10: 2025-10-23 | Q10: 2025-11-01 | R10: 2025-10-25 | S10: 2025-11-20 | T10: 2025-11-05 | U10: 2025-10-23 | V10: 2025-11-27 | W10: 2025-11-01 | X10: 2025-10-16 | Y10: 2025-10-16 | Z10: 2025-11-01 | AA10: 2025-10-25 | AB10: 2025-10-23 | AC10: 2025-10-23 | AD10: 2025-10-26 | AE10: 2025-10-04 | AF10: 2025-11-25 | AG10: 2025-10-16 | AH10: 2025-11-07 | AI10: 2025-11-07 | AJ10: 2025-11-20 | AK10: 2025-10-30 | AL10: 2025-11-20 | AM10: 2025-11-15 | AN10: 2025-12-13 | AO10: 2025-11-20 | AP10: 2025-11-15 | AQ10: 2025-11-29 | AR10: 2025-11-23 | AS10: 2025-12-06 | AT10: 2025-11-29 | AU10: 2025-12-06 | AV10: 2025-12-20 | AW10: 2026-01-24 | AX10: 2026-01-29 | AY10: 2026-02-19 | AZ10: 2026-02-19
A11: 2025-10-23 | B11: 2025-10-28 | C11: 2025-10-25 | D11: 2025-10-30 | E11: 2025-10-14 | F11: 2025-10-16 | G11: 2025-10-29 | H11: 2025-10-07 | I11: 2025-10-11 | J11: 2025-10-29 | K11: 2025-11-01 | L11: 2025-10-30 | M11: 2025-11-15 | N11: 2025-11-01 | O11: 2025-10-30 | P11: 2025-10-09 | Q11: 2025-11-09 | R11: 2025-10-30 | S11: 2025-11-27 | T11: 2025-11-12 | U11: 2025-10-30 | V11: 2025-11-15 | W11: 2025-10-23 | X11: 2025-11-13 | Y11: 2025-11-07 | Z11: 2025-11-08 | AA11: 2025-10-30 | AB11: 2025-11-13 | AC11: 2025-10-28 | AD11: 2025-11-01 | AE11: 2025-11-15 | AF11: 2025-11-29 | AG11: 2025-11-27 | AH11: 2025-11-08 | AI11: 2025-11-08 | AJ11: 2025-11-13 | AK11: 2025-11-13 | AL11: 2025-11-27 | AM11: 2025-11-22 | AN11: 2025-12-20 | AO11: 2025-12-06 | AP11: 2025-11-22 | AQ11: 2025-12-20 | AR11: 2025-12-20 | AS11: 2025-12-20 | AT11: 2025-12-13 | AU11: 2025-12-16 | AV11: 2025-12-30 | AW11: 2026-02-04 | AX11: 2026-02-19
A12: 2025-10-30 | B12: 2025-10-14 | C12: 2025-10-31 | D12: 2025-11-18 | E12: 2025-11-09 | F12: 2025-10-25 | G12: 2025-11-11 | H12: 2025-10-29 | I12: 2025-11-22 | J12: 2025-10-16 | K12: 2025-11-15 | L12: 2025-11-08 | M12: 2025-11-22 | N12: 2025-10-14 | O12: 2025-10-16 | P12: 2025-11-11 | Q12: 2025-11-15 | R12: 2025-11-13 | S12: 2025-11-30 | T12: 2025-11-22 | U12: 2025-11-07 | V12: 2025-11-09 | W12: 2025-11-22 | X12: 2025-11-27 | Y12: 2025-11-08 | Z12: 2025-11-15 | AA12: 2025-11-11 | AB12: 2025-11-20 | AC12: 2025-11-22 | AD12: 2025-11-05 | AE12: 2025-11-22 | AF12: 2025-12-04 | AG12: 2025-11-20 | AH12: 2025-11-20 | AI12: 2025-11-20 | AJ12: 2025-11-29 | AK12: 2025-11-22 | AL12: 2025-12-06 | AM12: 2025-11-29 | AN12: 2025-12-28 | AO12: 2025-12-18 | AP12: 2025-12-06 | AQ12: 2025-12-28 | AR12: 2025-12-28 | AS12: 2025-12-30 | AT12: 2025-12-28 | AU12: 2026-01-08 | AV12: 2026-01-08 | AW12: 2026-02-17
A13: 2025-11-08 | B13: 2025-11-12 | C13: 2025-10-23 | D13: 2025-11-22 | E13: 2025-11-18 | F13: 2025-11-15 | G13: 2025-11-15 | H13: 2025-10-23 | I13: 2025-11-26 | J13: 2025-11-09 | K13: 2025-11-20 | L13: 2025-11-15 | M13: 2025-11-28 | N13: 2025-11-11 | O13: 2025-11-15 | P13: 2025-11-20 | Q13: 2025-11-20 | R13: 2025-11-27 | S13: 2025-12-06 | T13: 2025-11-15 | U13: 2025-11-08 | V13: 2025-12-07 | W13: 2025-11-29 | X13: 2025-11-15 | Y13: 2025-11-20 | Z13: 2025-11-22 | AA13: 2025-11-15 | AB13: 2025-11-27 | AC13: 2025-11-15 | AD13: 2025-11-22 | AE13: 2025-11-29 | AF13: 2025-12-18 | AG13: 2025-12-20 | AH13: 2025-11-27 | AI13: 2025-11-29 | AJ13: 2025-12-16 | AK13: 2025-11-27 | AL13: 2025-12-28 | AM13: 2025-12-07 | AN13: 2026-01-04 | AO13: 2025-12-28 | AP13: 2025-12-18 | AQ13: 2026-01-02 | AR13: 2026-01-06 | AS13: 2026-01-06 | AT13: 2026-01-04 | AU13: 2025-12-20 | AV13: 2026-01-22 | AW13: 2026-02-28
A14: 2025-11-13 | B14: 2025-11-15 | C14: 2025-11-05 | D14: 2025-11-23 | E14: 2025-11-22 | F14: 2025-11-22 | G14: 2025-11-27 | H14: 2025-11-15 | I14: 2025-11-15 | J14: 2025-11-14 | K14: 2025-11-26 | L14: 2025-11-27 | M14: 2025-12-06 | N14: 2025-11-22 | O14: 2025-11-22 | P14: 2025-11-27 | Q14: 2025-11-27 | R14: 2025-11-05 | S14: 2025-11-09 | T14: 2025-11-29 | U14: 2025-11-22 | V14: 2025-12-20 | W14: 2025-12-06 | X14: 2025-12-18 | Y14: 2025-11-29 | Z14: 2025-12-18 | AA14: 2025-11-27 | AB14: 2025-12-04 | AC14: 2025-12-03 | AD14: 2025-11-29 | AE14: 2025-12-06 | AF14: 2025-12-22 | AG14: 2025-12-26 | AH14: 2025-12-18 | AI14: 2025-12-18 | AJ14: 2025-12-22 | AK14: 2025-12-20 | AL14: 2026-01-08 | AM14: 2025-12-20 | AN14: 2026-01-17 | AO14: 2026-01-08 | AP14: 2025-12-22 | AQ14: 2026-01-06 | AR14: 2026-01-29 | AS14: 2026-01-31 | AT14: 2026-01-10 | AU14: 2026-01-24
A15: 2025-11-20 | B15: 2025-11-20 | C15: 2025-11-26 | D15: 2025-11-15 | E15: 2025-11-23 | F15: 2025-11-23 | G15: 2025-12-04 | H15: 2025-11-20 | I15: 2025-11-27 | J15: 2025-11-22 | K15: 2025-12-03 | L15: 2025-12-06 | M15: 2025-12-28 | N15: 2025-11-15 | O15: 2025-12-06 | P15: 2025-12-06 | Q15: 2025-12-04 | R15: 2025-11-09 | S15: 2025-11-28 | T15: 2025-12-13 | U15: 2025-11-29 | V15: 2025-11-22 | W15: 2025-11-09 | X15: 2025-12-22 | Y15: 2025-11-01 | Z15: 2025-12-30 | AA15: 2025-12-06 | AB15: 2025-12-20 | AC15: 2025-11-23 | AD15: 2025-12-06 | AE15: 2025-12-13 | AF15: 2025-12-30 | AG15: 2025-12-30 | AH15: 2026-01-27 | AI15: 2025-12-22 | AJ15: 2026-01-27 | AK15: 2025-12-13 | AL15: 2025-12-26 | AM15: 2025-12-13 | AN15: 2026-01-24 | AO15: 2026-01-24 | AP15: 2025-12-28 | AQ15: 2026-01-29 | AR15: 2026-01-04 | AS15: 2026-02-17 | AT15: 2026-01-24 | AU15: 2026-02-21
A16: 2025-11-27 | B16: 2025-11-26 | C16: 2025-11-13 | D16: 2025-11-30 | E16: 2025-11-13 | F16: 2025-11-29 | G16: 2025-12-13 | H16: 2025-11-27 | I16: 2025-12-03 | J16: 2025-11-23 | K16: 2025-12-06 | L16: 2025-12-18 | M16: 2026-01-02 | N16: 2025-11-28 | O16: 2025-12-13 | P16: 2025-12-18 | Q16: 2025-12-20 | R16: 2025-12-20 | S16: 2025-12-20 | T16: 2025-12-20 | U16: 2025-11-14 | V16: 2025-12-28 | W16: 2025-12-18 | X16: 2025-12-20 | Y16: 2025-12-18 | Z16: 2026-01-02 | AA16: 2025-12-18 | AB16: 2025-12-28 | AC16: 2025-12-13 | AD16: 2025-11-25 | AE16: 2025-12-20 | AF16: 2026-01-04 | AG16: 2026-01-06 | AH16: 2025-12-20 | AI16: 2026-01-02 | AJ16: 2026-01-04 | AK16: 2026-01-04 | AL16: 2026-01-04 | AM16: 2026-01-29 | AN16: 2026-02-05 | AO16: 2026-01-31 | AP16: 2026-01-02 | AQ16: 2026-02-07 | AR16: 2026-01-24 | AS16: 2026-02-21 | AT16: 2026-01-31 | AU16: 2026-02-19
A17: 2025-12-06 | B17: 2025-11-29 | C17: 2025-11-29 | D17: 2025-12-04 | E17: 2025-11-30 | F17: 2025-12-06 | G17: 2025-12-20 | H17: 2025-12-18 | I17: 2025-11-23 | J17: 2025-11-13 | K17: 2025-12-18 | L17: 2025-12-22 | M17: 2026-01-04 | N17: 2025-12-07 | O17: 2025-12-20 | P17: 2025-12-22 | Q17: 2025-12-28 | R17: 2025-12-26 | S17: 2025-12-28 | T17: 2025-11-25 | U17: 2025-12-18 | V17: 2025-12-30 | W17: 2025-12-22 | X17: 2025-12-28 | Y17: 2025-12-22 | Z17: 2026-01-06 | AA17: 2025-12-22 | AB17: 2026-01-04 | AC17: 2025-12-10 | AD17: 2025-12-13 | AE17: 2025-12-26 | AF17: 2026-01-10 | AG17: 2025-12-13 | AH17: 2025-12-26 | AI17: 2026-01-29 | AJ17: 2026-01-10 | AK17: 2026-01-17 | AL17: 2026-01-22 | AM17: 2026-01-24 | AN17: 2026-02-21 | AO17: 2026-02-17 | AP17: 2026-01-04 | AQ17: 2026-02-26 | AR17: 2026-02-07 | AS17: 2026-02-19 | AT17: 2026-02-21 | AU17: 2026-03-07
A18: 2025-12-13 | B18: 2025-12-06 | C18: 2025-11-15 | D18: 2025-12-16 | E18: 2025-12-18 | F18: 2025-12-04 | G18: 2025-11-29 | H18: 2025-12-28 | I18: 2025-12-13 | J18: 2025-11-30 | K18: 2025-12-22 | L18: 2025-12-26 | M18: 2026-01-08 | N18: 2025-12-18 | O18: 2025-12-22 | P18: 2025-12-28 | Q18: 2026-01-02 | R18: 2025-12-30 | S18: 2026-01-04 | T18: 2025-12-06 | U18: 2025-12-22 | V18: 2026-01-04 | W18: 2026-01-02 | X18: 2026-01-04 | Y18: 2025-12-30 | Z18: 2025-12-13 | AA18: 2025-12-28 | AB18: 2026-01-14 | AC18: 2025-12-26 | AD18: 2025-12-20 | AE18: 2025-12-28 | AF18: 2026-01-22 | AG18: 2026-01-31 | AH18: 2026-01-02 | AI18: 2026-01-17 | AJ18: 2026-02-01 | AK18: 2026-01-31 | AL18: 2026-01-29 | AM18: 2026-02-07 | AN18: 2026-02-25 | AO18: 2026-02-21 | AQ18: 2026-02-21
A19: 2025-12-20 | B19: 2025-11-22 | C19: 2025-12-18 | D19: 2025-12-22 | E19: 2025-12-22 | F19: 2025-11-12 | G19: 2025-12-26 | H19: 2026-01-02 | I19: 2025-12-20 | J19: 2025-11-18 | K19: 2025-12-10 | L19: 2025-12-28 | M19: 2025-12-07 | N19: 2025-12-22 | O19: 2026-01-02 | P19: 2026-01-02 | Q19: 2026-01-06 | R19: 2026-01-02 | S19: 2026-01-08 | T19: 2025-12-28 | U19: 2025-12-28 | V19: 2026-01-17 | W19: 2026-01-06 | X19: 2026-01-08 | Y19: 2026-01-04 | Z19: 2025-12-26 | AA19: 2026-01-02 | AB19: 2025-12-18 | AC19: 2026-01-02 | AD19: 2026-01-06 | AE19: 2026-01-06 | AF19: 2026-01-29 | AG19: 2026-01-29 | AH19: 2026-01-04 | AI19: 2026-01-06 | AJ19: 2026-02-05 | AK19: 2026-02-07 | AL19: 2026-02-05 | AM19: 2026-02-21 | AN19: 2026-03-07
A20: 2025-12-30 | B20: 2025-11-23 | C20: 2025-12-22 | D20: 2025-12-13 | E20: 2026-01-27 | F20: 2025-12-18 | G20: 2025-12-30 | H20: 2026-01-04 | I20: 2025-12-10 | J20: 2025-12-16 | K20: 2025-12-28 | L20: 2025-12-30 | M20: 2025-12-22 | N20: 2025-12-28 | O20: 2026-01-14 | P20: 2026-01-04 | Q20: 2025-12-13 | R20: 2026-01-06 | S20: 2025-12-22 | T20: 2026-01-04 | U20: 2026-01-04 | V20: 2026-01-27 | W20: 2026-01-10 | X20: 2026-01-17 | Y20: 2026-01-20 | Z20: 2026-01-17 | AA20: 2026-01-06 | AB20: 2026-01-24 | AC20: 2026-01-06 | AD20: 2026-01-10 | AE20: 2026-01-24 | AF20: 2026-02-05 | AG20: 2026-02-07 | AH20: 2026-01-20 | AI20: 2026-01-31 | AJ20: 2026-02-07 | AK20: 2026-02-19 | AL20: 2026-02-21 | AM20: 2026-02-28
A21: 2026-01-02 | B21: 2025-12-18 | C21: 2025-11-27 | D21: 2025-11-28 | E21: 2025-12-26 | F21: 2025-12-22 | G21: 2026-01-02 | H21: 2026-01-08 | I21: 2025-12-28 | J21: 2025-12-26 | K21: 2026-01-02 | L21: 2026-01-02 | M21: 2026-01-22 | N21: 2026-01-02 | O21: 2026-01-22 | P21: 2026-01-14 | Q21: 2025-12-26 | R21: 2026-01-22 | S21: 2026-01-29 | T21: 2026-01-08 | U21: 2026-01-08 | V21: 2026-01-31 | W21: 2026-01-22 | X21: 2026-01-31 | Y21: 2026-01-22 | Z21: 2026-01-31 | AA21: 2026-02-05 | AB21: 2026-01-31 | AC21: 2026-01-17 | AD21: 2026-01-24 | AE21: 2026-01-31 | AF21: 2026-02-10 | AG21: 2026-02-19 | AH21: 2026-02-05 | AI21: 2026-02-17 | AJ21: 2026-02-19 | AK21: 2026-03-03 | AL21: 2026-03-03
A22: 2026-01-06 | B22: 2025-12-22 | C22: 2025-12-03 | D22: 2025-12-26 | E22: 2025-12-30 | F22: 2025-12-26 | G22: 2026-01-14 | H22: 2025-12-22 | I22: 2025-12-30 | J22: 2025-12-30 | K22: 2026-01-06 | L22: 2026-01-06 | M22: 2026-01-27 | N22: 2026-01-06 | O22: 2026-01-17 | P22: 2026-01-22 | Q22: 2026-01-17 | R22: 2026-01-11 | S22: 2025-12-26 | T22: 2025-12-18 | U22: 2026-01-29 | V22: 2026-01-22 | W22: 2026-01-31 | X22: 2026-01-24 | Y22: 2026-01-31 | Z22: 2026-02-17 | AA22: 2026-02-19 | AB22: 2026-01-06 | AC22: 2026-01-24 | AD22: 2026-01-31 | AE22: 2026-02-19 | AF22: 2026-02-21 | AG22: 2026-02-26 | AH22: 2026-02-26 | AI22: 2026-03-03 | AJ22: 2026-02-28
A23: 2026-01-10 | B23: 2025-12-10 | C23: 2025-12-26 | D23: 2025-12-30 | E23: 2026-01-04 | F23: 2025-12-30 | G23: 2026-01-11 | H23: 2026-01-24 | I23: 2026-01-02 | J23: 2026-01-17 | K23: 2026-01-11 | L23: 2026-01-17 | M23: 2026-01-31 | N23: 2026-01-22 | O23: 2026-01-29 | P23: 2026-01-29 | Q23: 2026-01-24 | R23: 2026-02-17 | S23: 2026-02-05 | T23: 2026-01-24 | U23: 2026-01-27 | V23: 2026-02-07 | W23: 2026-01-29 | X23: 2026-02-05 | Y23: 2026-02-10 | Z23: 2026-02-25 | AA23: 2026-02-26 | AB23: 2026-02-07 | AC23: 2026-01-29 | AD23: 2026-02-05 | AE23: 2026-02-25 | AF23: 2026-03-03
A24: 2025-12-26 | B24: 2025-12-26 | C24: 2025-12-30 | D24: 2026-01-04 | E24: 2026-01-06 | F24: 2026-01-04 | G24: 2026-01-29 | H24: 2026-01-29 | I24: 2026-01-06 | J24: 2026-01-22 | K24: 2026-01-20 | L24: 2026-01-24 | M24: 2026-01-29 | N24: 2026-02-07 | O24: 2026-02-07 | P24: 2026-02-07 | Q24: 2026-02-17 | R24: 2026-02-04 | S24: 2026-02-19 | T24: 2026-01-31 | U24: 2026-02-07 | V24: 2026-02-19 | W24: 2026-02-17 | X24: 2026-02-19 | Y24: 2026-02-21 | Z24: 2026-02-19 | AA24: 2026-02-17 | AB24: 2026-02-21 | AC24: 2026-02-04 | AD24: 2026-02-28 | AE24: 2026-03-07
A25: 2025-12-22 | B25: 2025-12-28 | C25: 2026-01-02 | D25: 2026-01-17 | E25: 2026-01-22 | F25: 2026-01-10 | G25: 2026-01-31 | H25: 2025-12-30 | I25: 2026-01-17 | J25: 2026-01-29 | K25: 2026-01-29 | L25: 2026-01-27 | M25: 2026-02-07 | N25: 2026-02-21 | O25: 2026-02-17 | P25: 2026-02-25 | Q25: 2026-02-19 | R25: 2026-02-21 | S25: 2026-02-26 | T25: 2026-02-10 | U25: 2026-02-19 | V25: 2026-02-24 | W25: 2026-02-07 | X25: 2026-02-21 | Y25: 2026-03-03 | Z25: 2026-03-05 | AA25: 2026-03-05 | AB25: 2026-02-28 | AC25: 2026-02-17
A26: 2026-01-17 | B26: 2025-12-30 | C26: 2026-01-06 | D26: 2026-01-22 | E26: 2026-02-01 | F26: 2026-01-17 | G26: 2026-01-08 | H26: 2026-01-31 | I26: 2026-01-31 | J26: 2026-02-01 | K26: 2026-02-17 | L26: 2026-01-29 | M26: 2026-02-19 | N26: 2026-02-26 | O26: 2026-02-21 | P26: 2026-02-19 | Q26: 2026-02-26 | R26: 2026-02-26 | S26: 2026-02-17 | T26: 2026-02-26 | U26: 2026-02-21 | V26: 2026-02-28 | W26: 2026-02-26
A27: 2026-01-24 | B27: 2026-01-04 | C27: 2026-01-17 | D27: 2026-01-29 | E27: 2026-01-29 | F27: 2026-01-31 | G27: 2026-02-07 | H27: 2026-01-27 | I27: 2026-02-17 | J27: 2026-01-08 | K27: 2026-02-05 | L27: 2026-02-07 | M27: 2026-02-26 | N27: 2026-02-05 | O27: 2026-02-19 | P27: 2026-03-05 | Q27: 2026-03-07 | R27: 2026-03-07 | S27: 2026-03-07 | T27: 2026-03-05
A28: 2026-01-29 | B28: 2026-01-10 | C28: 2026-01-11 | D28: 2026-02-01 | E28: 2026-02-07 | F28: 2026-01-06 | G28: 2026-02-17 | H28: 2026-02-17 | I28: 2026-02-21 | J28: 2026-02-07 | K28: 2026-02-21 | L28: 2026-02-19 | M28: 2026-02-21 | N28: 2026-02-14 | O28: 2026-02-26
A29: 2026-01-31 | B29: 2026-01-20 | C29: 2026-01-24 | D29: 2026-01-02 | E29: 2026-02-17 | F29: 2026-02-05 | G29: 2026-02-19 | H29: 2026-02-21 | I29: 2026-02-26 | J29: 2026-02-21 | K29: 2026-02-19 | L29: 2026-02-26
A30: 2026-02-05 | B30: 2026-01-24 | C30: 2026-01-31 | D30: 2026-02-05 | E30: 2026-02-21 | F30: 2026-02-24 | G30: 2026-02-26 | H30: 2026-02-28 | I30: 2026-03-07 | J30: 2026-03-03 | K30: 2026-02-25
A31: 2026-02-17 | B31: 2026-01-29 | C31: 2026-02-05 | D31: 2026-02-17 | E31: 2026-02-10 | F31: 2026-02-14 | G31: 2026-03-07
A32: 2026-02-07 | B32: 2026-02-04 | C32: 2026-02-25 | D32: 2026-02-26 | E32: 2026-02-25 | F32: 2026-03-05
A33: 2026-02-21 | B33: 2026-02-17 | C33: 2026-03-05 | D33: 2026-03-03 | E33: 2026-03-03
A34: 2026-02-25 | B34: 2026-02-24
A35: 2026-02-14 | B35: 2026-02-28
A36: 2026-02-19 | B36: 2026-02-14
A37: 2026-03-05 | B37: 2026-03-05

Sheet AHL_DAT
A3: 2025-09-20 | B3: 2025-09-21 | C3: 2025-09-26 | D3: 2025-09-27 | E3: 2025-09-25 | F3: 2025-10-01 | G3: 2025-10-02 | H3: 2025-10-04 | I3: 2025-10-10 | J3: 2025-10-11 | K3: 2025-10-07 | L3: 2025-10-09 | M3: 2025-10-14 | N3: 2025-10-16 | O3: 2025-10-17 | P3: 2025-10-18 | Q3: 2025-10-25 | R3: 2025-10-26 | S3: 2025-10-31 | T3: 2025-11-01 | U3: 2025-10-23 | V3: 2025-10-28 | W3: 2025-10-30 | X3: 2025-10-29 | Y3: 2025-11-05 | Z3: 2025-11-07 | AA3: 2025-11-08 | AB3: 2025-11-09 | AC3: 2025-11-11 | AD3: 2025-11-12 | AE3: 2025-11-13 | AF3: 2025-11-14 | AG3: 2025-11-15 | AH3: 2025-11-18 | AI3: 2025-11-20 | AJ3: 2025-11-22 | AK3: 2025-11-23 | AL3: 2025-11-25 | AM3: 2025-11-26 | AN3: 2025-11-27 | AO3: 2025-11-28 | AP3: 2025-11-29 | AQ3: 2025-11-30 | AR3: 2025-12-03 | AS3: 2025-12-04 | AT3: 2025-12-06 | AU3: 2025-12-07 | AV3: 2025-12-13 | AW3: 2025-12-16 | AX3: 2025-12-18 | AY3: 2025-12-20 | AZ3: 2025-12-22 | BA3: 2025-12-10 | BB3: 2026-01-27 | BC3: 2025-12-26 | BD3: 2025-12-28 | BE3: 2025-12-30 | BF3: 2026-01-02 | BG3: 2026-01-04 | BH3: 2026-01-06 | BI3: 2026-01-08 | BJ3: 2026-01-10 | BK3: 2026-01-14 | BL3: 2026-01-17 | BM3: 2026-01-11 | BN3: 2026-01-20 | BO3: 2026-01-22 | BP3: 2026-01-24 | BQ3: 2026-01-29 | BR3: 2026-01-31 | BS3: 2026-02-01 | BT3: 2026-02-04 | BU3: 2026-02-05 | BV3: 2026-02-07 | BW3: 2026-02-17 | BX3: 2026-02-10 | BY3: 2026-02-21 | BZ3: 2026-02-25 | CA3: 2026-02-19 | CB3: 2026-02-24 | CC3: 2026-02-26 | CD3: 2026-02-28 | CE3: 2026-02-14 | CF3: 2026-02-12 | CG3: 2026-03-05 | CH3: 2026-03-07
A4: MoschenAn | B4: BenvegnuAn | C4: BulovecMi | D4: MoschenAn | E4: OrelSt | F4: HolzerTo | G4: MetzingerFi | H4: BulovecMi | I4: BrockAd | J4: MetzingerFi | K4: LazzeriAl | L4: HlavatyAl | M4: Huber rRe | N4: BulovecMi | O4: VoicanCh | P4: PirasAn | Q4: MoschenAn | R4: BrockAd | S4: LebenJa | T4: RuetzMa | U4: Huber rRe | V4: Huber rRe | W4: MetzingerFi | X4: MoschenAn | Y4: BrockAd | Z4: BergantAn | AA4: GiacomozziFe | AB4: OrelSt | AC4: BenvegnuAn | AD4: HolzerTo | AE4: MetzingerFi | AF4: BulovecMi | AG4: GiacomozziFe | AH4: OrelSt | AI4: MetzingerFi | AJ4: GiacomozziFe | AK4: OrelSt | AL4: BrockAd | AM4: Huber rRe | AN4: MetzingerFi | AO4: PinieOm | AP4: BrockAd | AQ4: OrelSt | AR4: SpiegelSe | AS4: MoschenAn | AT4: GiacomozziFe | AU4: PinieOm | AV4: LazzeriAl | AW4: UnterwegerDo | AX4: BergantAn | AY4: LazzeriAl | AZ4: OrelSt | BA4: Huber rRe | BB4: BulovecMi | BC4: LebenJa | BD4: HlavatyAl | BE4: UnterwegerDo | BF4: HlavatyAl | BG4: OrelSt | BH4: HlavatyAl | BI4: MetzingerFi | BJ4: BrockAd | BK4: MoschenAn | BL4: LazzeriAl | BM4: MoschenAn | BN4: BergantAn | BO4: BergantAn | BP4: SpiegelSe | BQ4: HlavatyAl | BR4: BrockAd | BS4: OrelSt | BT4: Huber rRe | BU4: UnterwegerDo | BV4: PirasAn | BW4: MoschenAn | BX4: BergantAn | BY4: BulovecMi | BZ4: HolzerTo | CA4: LebenJa | CB4: Huber rRe | CC4: PinieOm | CD4: BrockAd | CE4: UnterwegerDo | CF4: BergantAn | CG4: Huber rRe | CH4: HolzerTo
A5: StefenelliFe | B5: RivisFe | C5: UnterwegerDo | D5: PinieOm | E5: SpiegelSe | F5: WinklerDa | G5: SnojTa | H5: LazzeriAl | I5: SnojTa | J5: UnterwegerDo | K5: OrelSt | L5: VoicanCh | M5: OrelSt | N5: SnojTa | O5: WinklerDa | P5: SoraperraSi | Q5: RivisFe | R5: SnojTa | S5: WinklerDa | T5: VoicanCh | U5: WinklerDa | V5: SpiegelSe | W5: UnterwegerDo | X5: OrelSt | Y5: WinklerDa | Z5: BulovecMi | AA5: LazzeriAl | AB5: VirtaTu | AC5: MoschenAn | AD5: Huber rRe | AE5: SnojTa | AF5: WidmannFl | AG5: MoschenAn | AH5: UnterwegerDo | AI5: VoicanCh | AJ5: RuetzMa | AK5: UnterwegerDo | AL5: VoicanCh | AM5: WinklerDa | AN5: SnojTa | AO5: UnterwegerDo | AP5: HlavatyAl | AQ5: UnterwegerDo | AR5: WinklerDa | AS5: PirasAn | AT5: LazzeriAl | AU5: StefenelliFe | AV5: MoschenAn | AW5: VoicanCh | AX5: OrelSt | AY5: StefenelliFe | AZ5: UnterwegerDo | BA5: SpiegelSe | BB5: OrelSt | BC5: MetzingerFi | BD5: HolzerTo | BE5: WinklerDa | BF5: UnterwegerDo | BG5: UnterwegerDo | BH5: PirasAn | BI5: SnojTa | BJ5: Huber rRe | BK5: PirasAn | BL5: VirtaTu | BM5: WinklerDa | BN5: Huber rRe | BO5: MetzingerFi | BP5: VirtaTu | BQ5: OrelSt | BR5: LebenJa | BS5: UnterwegerDo | BT5: SpiegelSe | BU5: WinklerDa | BV5: StefenelliFe | BW5: SpiegelSe | BX5: OrelSt | BY5: SnojTa | BZ5: LazzeriAl | CA5: VoicanCh | CB5: StefenelliFe | CC5: VirtaTu | CD5: Huber rRe | CE5: WinklerDa | CF5: MetzingerFi | CG5: WinklerDa | CH5: VoicanCh
A6: AbeltinoSi | B6: BrondiMa | C6: MiklicGr | D6: BrondiPa | E6: RinkerDa | F6: DivisDo | G6: MiklicGr | H6: ArlicMa | I6: JeramFi | J6: LegatKo | K6: BrondiPa | L6: LegatKo | M6: DivisDo | N6: BergeljNi | O6: PreiserJu | P6: AbeltinoSi | Q6: FecchioFe | R6: PreiserJu | S6: FleischmannLu | T6: PreiserJu | U6: MoidlMa | V6: Dummermuth-haasEl | W6: ArlicMa | X6: BrondiPa | Y6: IlmerNo | Z6: ArlicMa | AA6: BrondiMa | AB6: LegatKo | AC6: AbeltinoSi | AD6: StrimitzerDa | AE6: MiklicGr | AF6: WendnerMa | AG6: BrondiPa | AH6: SeewaldJe | AI6: LegatKo | AJ6: Steiner fFe | AK6: StrimitzerDa | AL6: VeselkaMa | AM6: DivisDo | AN6: ArlicMa | AO6: CristeliMa | AP6: LegatKo | AQ6: CristeliMa | AR6: DivisDo | AS6: CalloviniAn | AT6: AbeltinoSi | AU6: CusinFe | AV6: CusinFe | AW6: LegatKo | AX6: ArlicMa | AY6: CristeliMa | AZ6: AbeltinoSi | BA6: DivisDo | BB6: ArlicMa | BC6: ArlicMa | BD6: DivisDo | BE6: StrimitzerDa | BF6: ArlicMa | BG6: SeewaldJe | BH6: PreiserJu | BI6: MurnikPe | BJ6: Steiner fFe | BK6: AbeltinoSi | BL6: BrondiMa | BM6: IlmerNo | BN6: ArlicMa | BO6: JeramFi | BP6: BrondiPa | BQ6: WuchererGe | BR6: BergeljNi | BS6: LegatKo | BT6: IlmerNo | BU6: Dummermuth-haasEl | BV6: CusinFe | BW6: DivisDo | BX6: VeselkaMa | BY6: CusinFe | BZ6: AbeltinoSi | CA6: LegatKo | CB6: CalloviniAn | CC6: CristeliMa | CD6: LegatKo | CE6: PreiserJu | CF6: MarkizetiGr | CG6: StrimitzerDa | CH6: DivisDo
A7: BrondiPa | B7: RivisAn | C7: WuchererGe | D7: IlmerNo | E7: WuchererGe | F7: RinkerDa | G7: MurnikPe | H7: BrondiPa | I7: VeselkaMa | J7: WuchererGe | K7: FleischmannLu | L7: WendnerMa | M7: WuchererGe | N7: StrimitzerDa | O7: RinkerDa | P7: CusinFe | Q7: IlmerNo | R7: VeselkaMa | S7: MarkizetiGr | T7: RinkerDa | U7: Steiner fFe | V7: StrimitzerDa | W7: MiklicGr | X7: WuchererGe | Y7: VeselkaMa | Z7: MarkizetiGr | AA7: FecchioFe | AB7: WuchererGe | AC7: GrisentiLu | AD7: VeselkaMa | AE7: MurnikPe | AF7: WuchererGe | AG7: CusinFe | AH7: WuchererGe | AI7: MarkizetiGr | AJ7: VeselkaMa | AK7: WuchererGe | AL7: WendnerMa | AM7: RinkerDa | AN7: MiklicGr | AO7: GrisentiLu | AP7: PreiserJu | AQ7: WuchererGe | AR7: RinkerDa | AS7: StrimitzerDa | AT7: RivisAn | AU7: GrisentiLu | AV7: RivisAn | AW7: WuchererGe | AX7: WendnerMa | AY7: RivisAn | AZ7: FecchioFe | BA7: RinkerDa | BB7: LegatKo | BC7: PreiserJu | BD7: PreiserJu | BE7: ZacherlPa | BF7: MarkizetiGr | BG7: StrimitzerDa | BH7: ZacherlPa | BI7: WuchererGe | BJ7: StrimitzerDa | BK7: RivisAn | BL7: FecchioFe | BM7: RinkerDa | BN7: RinkerDa | BO7: WendnerMa | BP7: FleischmannLu | BQ7: ZacherlPa | BR7: Dummermuth-haasEl | BS7: WuchererGe | BT7: SeewaldJe | BU7: StrimitzerDa | BV7: RivisAn | BW7: IlmerNo | BX7: WendnerMa | BY7: DivisDo | BZ7: BrondiMa | CA7: PreiserJu | CB7: StrimitzerDa | CC7: IlmerNo | CD7: SeewaldJe | CE7: VeselkaMa | CF7: MiklicGr | CG7: VeselkaMa | CH7: PreiserJu
A8: PinieOm | D8: BergantAn | E8: HolzerTo | G8: Huber rRe | H8: HlavatyAl | I8: MoschenAn | J8: GiacomozziFe | K8: PinieOm | L8: Huber rRe | M8: BenvegnuAn | N8: LazzeriAl | P8: BrockAd | Q8: BrockAd | T8: PinieOm | U8: MetzingerFi | W8: BulovecMi | AA8: BergantAn | AB8: RivisFe | AE8: LazzeriAl | AG8: Huber rRe | AI8: LazzeriAl | AJ8: Huber rRe | AK8: Huber rRe | AN8: BenvegnuAn | AP8: HolzerTo | AS8: UnterwegerDo | AT8: BenvegnuAn | AV8: HolzerTo | AX8: BajtMi | AY8: LebenJa | AZ8: BulovecMi | BB8: PinieOm | BC8: OrelSt | BD8: GiacomozziFe | BE8: KeldererMo | BF8: BenvegnuAn | BG8: BulovecMi | BH8: BenvegnuAn | BI8: BulovecMi | BJ8: LazzeriAl | BL8: HolzerTo | BO8: PinieOm | BP8: SnojTa | BQ8: Huber rRe | BR8: LazzeriAl | BU8: MetzingerFi | BV8: MoschenAn | BW8: LazzeriAl | BY8: BergantAn | BZ8: OrelSt | CA8: RuetzMa | CC8: HlavatyAl | CD8: PirasAn | CE8: Huber rRe | CF8: OrelSt | CG8: BenvegnuAn | CH8: MoschenAn
A9: VirtaTu | D9: LebenJa | E9: Huber rRe | G9: WinklerDa | H9: VoicanCh | I9: VirtaTu | J9: StefenelliFe | K9: StefenelliFe | L9: SpiegelSe | M9: PinieOm | N9: RivisFe | P9: UnterwegerDo | Q9: SnojTa | T9: RivisFe | U9: RivisFe | W9: HlavatyAl | AA9: BulovecMi | AB9: StefenelliFe | AE9: PirasAn | AG9: PinieOm | AI9: LebenJa | AJ9: SpiegelSe | AK9: SpiegelSe | AN9: WinklerDa | AP9: Huber rRe | AS9: VirtaTu | AT9: PinieOm | AV9: UnterwegerDo | AX9: SnojTa | AY9: VoicanCh | AZ9: SnojTa | BB9: StefenelliFe | BC9: UnterwegerDo | BD9: PinieOm | BE9: MoidlDa | BF9: WidmannFl | BG9: SnojTa | BH9: RivisFe | BI9: VoicanCh | BJ9: RivisFe | BL9: SpiegelSe | BO9: RivisFe | BP9: VoicanCh | BQ9: UnterwegerDo | BR9: RuetzMa | BU9: SnojTa | BV9: PinieOm | BW9: VirtaTu | BY9: MetzingerFi | BZ9: WinklerDa | CA9: StefenelliFe | CC9: UnterwegerDo | CD9: StefenelliFe | CE9: LazzeriAl | CF9: UnterwegerDo | CG9: LazzeriAl | CH9: VirtaTu
A10: CusinFe | D10: JeramFi | E10: Steiner fFe | G10: BrondiPa | H10: MurnikPe | I10: CristeliMa | J10: BrondiMa | K10: GrisentiLu | L10: AbeltinoSi | M10: GrisentiLu | N10: BrondiPa | P10: VeselkaMa | Q10: PreiserJu | T10: GrisentiLu | U10: ArlicMa | W10: LegatKo | AA10: ArlicMa | AB10: CristeliMa | AE10: FleischmannLu | AG10: CristeliMa | AI10: AbeltinoSi | AJ10: DivisDo | AK10: DivisDo | AN10: FecchioFe | AP10: MarkizetiGr | AS10: FleischmannLu | AT10: CristeliMa | AV10: DivisDo | AX10: MarkizetiGr | AY10: JeramFi | AZ10: LegatKo | BB10: BrondiPa | BC10: StrimitzerDa | BD10: CristeliMa | BE10: MattheyPh | BF10: Dummermuth-haasEl | BG10: BrondiPa | BH10: FecchioFe | BI10: JeramFi | BJ10: LegatKo | BL10: DivisDo | BO10: GrisentiLu | BP10: MurnikPe | BQ10: RinkerDa | BR10: BrondiMa | BU10: ArlicMa | BV10: AbeltinoSi | BW10: BrondiMa | BY10: MurnikPe | BZ10: PreiserJu | CA10: FecchioFe | CC10: DivisDo | CD10: BrondiPa | CE10: GrisentiLu | CF10: WendnerMa | CG10: AbeltinoSi | CH10: CristeliMa
A11: FecchioFe | D11: MiklicGr | E11: VeselkaMa | G11: BrondiMa | H11: PreiserJu | I11: FecchioFe | J11: FleischmannLu | K11: IlmerNo | L11: RinkerDa | M11: SeewaldJe | N11: RivisAn | P11: WuchererGe | Q11: VeselkaMa | T11: RivisAn | U11: BrondiPa | W11: MurnikPe | AA11: MarkizetiGr | AB11: IlmerNo | AE11: IlmerNo | AG11: RivisAn | AI11: ArlicMa | AJ11: GrisentiLu | AK11: FleischmannLu | AN11: MoidlMa | AP11: SeewaldJe | AS11: WendnerMa | AT11: FecchioFe | AV11: PreiserJu | AX11: VeselkaMa | AY11: MiklicGr | AZ11: WendnerMa | BB11: FecchioFe | BC11: WuchererGe | BD11: FleischmannLu | BE11: MoidlMa | BF11: RivisAn | BG11: FleischmannLu | BH11: FleischmannLu | BI11: VeselkaMa | BJ11: WendnerMa | BL11: StrimitzerDa | BO11: IlmerNo | BP11: PreiserJu | BQ11: WendnerMa | BR11: DivisDo | BU11: LegatKo | BV11: GrisentiLu | BW11: BrondiPa | BY11: WendnerMa | BZ11: RinkerDa | CA11: RinkerDa | CC11: VeselkaMa | CD11: CusinFe | CE11: StrimitzerDa | CF11: WuchererGe | CG11: BrondiMa | CH11: IlmerNo
A12: RuetzMa | D12: VirtaTu | E12: LebenJa | G12: BulovecMi | H12: OrelSt | J12: BergantAn | L12: HolzerTo | M12: BrockAd | N12: GiacomozziFe | P12: HlavatyAl | Q12: GiacomozziFe | T12: HlavatyAl | U12: LazzeriAl | W12: GiacomozziFe | AE12: OrelSt | AG12: SnojTa | AI12: BergantAn | AJ12: BulovecMi | AN12: MoschenAn | AP12: BergantAn | AT12: Huber rRe | AV12: BrockAd | AX12: BulovecMi | AY12: BrockAd | AZ12: BergantAn | BC12: Huber rRe | BD12: PirasAn | BE12: BergantAn | BF12: PinieOm | BG12: PinieOm | BH12: LebenJa | BI12: MoschenAn | BL12: SnojTa | BO12: OrelSt | BP12: BrockAd | BQ12: LebenJa | BR12: BergantAn | BU12: BrockAd | BV12: HlavatyAl | BW12: BenvegnuAn | BY12: HlavatyAl | CA12: LazzeriAl | CC12: BenvegnuAn
A13: WinklerDa | D13: WinklerDa | E13: SnojTa | G13: LebenJa | H13: UnterwegerDo | J13: OrelSt | L13: WinklerDa | M13: PirasAn | N13: SpiegelSe | P13: OrelSt | Q13: WinklerDa | T13: SpiegelSe | U13: PirasAn | W13: VirtaTu | AE13: WinklerDa | AG13: UnterwegerDo | AI13: PirasAn | AJ13: RivisFe | AN13: StefenelliFe | AP13: BulovecMi | AT13: RivisFe | AV13: SpiegelSe | AX13: Huber rRe | AY13: HlavatyAl | AZ13: WinklerDa | BC13: SpiegelSe | BD13: StefenelliFe | BE13: LebenJa | BF13: VirtaTu | BG13: PirasAn | BH13: OrelSt | BI13: PinieOm | BL13: StefenelliFe | BO13: UnterwegerDo | BP13: WinklerDa | BQ13: MoschenAn | BR13: SnojTa | BU13: HolzerTo | BV13: OrelSt | BW13: RivisFe | BY13: PinieOm | CA13: PinieOm | CC13: MoschenAn
A14: DivisDo | D14: AbeltinoSi | E14: MarkizetiGr | G14: AbeltinoSi | H14: WuchererGe | J14: ArlicMa | L14: DivisDo | M14: FecchioFe | N14: DivisDo | P14: LegatKo | Q14: BrondiPa | T14: AbeltinoSi | U14: CusinFe | W14: BrondiMa | AE14: LegatKo | AG14: StrimitzerDa | AI14: BergeljNi | AJ14: MiklicGr | AN14: BrondiPa | AP14: JeramFi | AT14: RinkerDa | AV14: Steiner fFe | AX14: MurnikPe | AY14: PreiserJu | AZ14: MarkizetiGr | BC14: Dummermuth-haasEl | BD14: AbeltinoSi | BE14: JeramFi | BF14: BrondiPa | BG14: LegatKo | BH14: BergeljNi | BI14: BrondiPa | BL14: MiklicGr | BO14: AbeltinoSi | BP14: Steiner fFe | BQ14: CristeliMa | BR14: MiklicGr | BU14: RinkerDa | BV14: LegatKo | BW14: CristeliMa | BY14: BrondiPa | CA14: AbeltinoSi | CC14: FecchioFe
A15: WendnerMa | D15: RinkerDa | E15: MiklicGr | G15: CristeliMa | H15: ZacherlPa | J15: StrimitzerDa | L15: StrimitzerDa | M15: Steiner fFe | N15: GrisentiLu | P15: WendnerMa | Q15: RinkerDa | T15: DivisDo | U15: StrimitzerDa | W15: RivisAn | AE15: WuchererGe | AG15: VeselkaMa | AI15: BrondiPa | AJ15: RivisAn | AN15: CristeliMa | AP15: WendnerMa | AT15: ZacherlPa | AV15: VeselkaMa | AX15: StrimitzerDa | AY15: VeselkaMa | AZ15: StrimitzerDa | BC15: SeewaldJe | BD15: FecchioFe | BE15: WendnerMa | BF15: BrondiMa | BG15: WendnerMa | BH15: MarkizetiGr | BI15: CristeliMa | BL15: RivisAn | BO15: WuchererGe | BP15: VeselkaMa | BQ15: CusinFe | BR15: PreiserJu | BU15: WendnerMa | BV15: WuchererGe | BW15: RivisAn | BY15: Steiner fFe | CA15: BrondiMa | CC15: GrisentiLu
A16: Huber rRe | D16: BrockAd | E16: BergantAn | G16: PinieOm | H16: MetzingerFi | J16: Huber rRe | L16: BenvegnuAn | M16: BajtMi | N16: BergantAn | P16: BergantAn | Q16: BenvegnuAn | T16: BrockAd | U16: PinieOm | W16: BenvegnuAn | AG16: BenvegnuAn | AI16: Huber rRe | AJ16: OrelSt | AN16: LebenJa | AP16: RivisFe | AT16: MetzingerFi | AV16: LebenJa | AX16: GiacomozziFe | AY16: HolzerTo | AZ16: BenvegnuAn | BC16: MoschenAn | BD16: BulovecMi | BE16: Huber rRe | BF16: GiacomozziFe | BG16: HolzerTo | BH16: LazzeriAl | BL16: UnterwegerDo | BO16: SoraperraSi | BP16: HolzerTo | BQ16: BulovecMi | BR16: PirasAn | BU16: BenvegnuAn | BV16: BulovecMi | BW16: OrelSt | BY16: OrelSt | CA16: MoschenAn | CC16: LebenJa
A17: PirasAn | D17: RuetzMa | E17: LazzeriAl | G17: StefenelliFe | H17: MoschenAn | J17: LazzeriAl | L17: BulovecMi | M17: MoschenAn | N17: LebenJa | P17: GiacomozziFe | Q17: BergantAn | T17: UnterwegerDo | U17: VirtaTu | W17: LazzeriAl | AG17: VirtaTu | AI17: SoraperraSi | AJ17: UnterwegerDo | AN17: VirtaTu | AP17: RuetzMa | AT17: VoicanCh | AV17: VirtaTu | AX17: PirasAn | AY17: RuetzMa | AZ17: RivisFe | BC17: WinklerDa | BD17: SnojTa | BE17: OrelSt | BF17: RivisFe | BG17: Huber rRe | BH17: RuetzMa | BL17: WinklerDa | BO17: StefenelliFe | BP17: Huber rRe | BQ17: MetzingerFi | BR17: StefenelliFe | BU17: LazzeriAl | BV17: LebenJa | BW17: UnterwegerDo | BY17: PirasAn | CA17: VirtaTu | CC17: RivisFe
A18: IlmerNo | D18: PreiserJu | E18: BrondiPa | G18: FecchioFe | H18: GrisentiLu | J18: AbeltinoSi | L18: CusinFe | M18: MarkizetiGr | N18: LegatKo | P18: ArlicMa | Q18: GrisentiLu | T18: Steiner fFe | U18: AbeltinoSi | W18: FecchioFe | AG18: BrondiMa | AI18: FleischmannLu | AJ18: StrimitzerDa | AN18: AbeltinoSi | AP18: CusinFe | AT18: MurnikPe | AV18: BrondiMa | AX18: AbeltinoSi | AY18: DivisDo | AZ18: CalloviniAn | BC18: FecchioFe | BD18: Steiner fFe | BE18: DivisDo | BF18: AbeltinoSi | BG18: Steiner fFe | BH18: GrisentiLu | BL18: MarkizetiGr | BO18: CalloviniAn | BP18: SeewaldJe | BQ18: FleischmannLu | BR18: Steiner fFe | BU18: CristeliMa | BV18: FecchioFe | BW18: MarkizetiGr | BY18: IlmerNo | CA18: Dummermuth-haasEl | CC18: ArlicMa
A19: StrimitzerDa | D19: VeselkaMa | E19: JeramFi | G19: RivisAn | H19: JeramFi | J19: DivisDo | L19: MarkizetiGr | M19: MiklicGr | N19: WendnerMa | P19: IlmerNo | Q19: MiklicGr | T19: WuchererGe | U19: BrondiMa | W19: IlmerNo | AG19: FecchioFe | AI19: RinkerDa | AJ19: WuchererGe | AN19: BergeljNi | AP19: StrimitzerDa | AT19: PreiserJu | AV19: MiklicGr | AX19: BrondiPa | AY19: SeewaldJe | AZ19: GrisentiLu | BC19: IlmerNo | BD19: VeselkaMa | BE19: WuchererGe | BF19: GrisentiLu | BG19: VeselkaMa | BH19: IlmerNo | BL19: WuchererGe | BO19: RivisAn | BP19: ZacherlPa | BQ19: MarkizetiGr | BR19: VeselkaMa | BU19: GrisentiLu | BV19: FleischmannLu | BW19: MurnikPe | BY19: WuchererGe | CA19: ZacherlPa | CC19: RivisAn
A20: BrockAd | D20: PirasAn | E20: BenvegnuAn | G20: BergantAn | H20: RivisFe | J20: BulovecMi | N20: OrelSt | P20: Huber rRe | Q20: HolzerTo | T20: PirasAn | U20: BulovecMi | AG20: RuetzMa | AI20: BajtMi | AJ20: BrockAd | AN20: LazzeriAl | AP20: MoschenAn | AT20: BrockAd | AX20: BenvegnuAn | AY20: PirasAn | AZ20: GiacomozziFe | BC20: LazzeriAl | BD20: Huber rRe | BE20: MoschenAn | BF20: LazzeriAl | BG20: GiacomozziFe | BH20: BrockAd | BP20: LazzeriAl | BQ20: LazzeriAl | BR20: RivisFe | BV20: LazzeriAl | BW20: Huber rRe | BY20: LazzeriAl | CA20: BulovecMi
A21: LazzeriAl | D21: RivisFe | E21: StefenelliFe | G21: PirasAn | H21: VirtaTu | J21: LebenJa | N21: UnterwegerDo | P21: MoschenAn | Q21: LazzeriAl | T21: VirtaTu | U21: SpiegelSe | AG21: WinklerDa | AI21: VirtaTu | AJ21: HlavatyAl | AN21: PirasAn | AP21: WinklerDa | AT21: RuetzMa | AX21: WinklerDa | AY21: VirtaTu | AZ21: Huber rRe | BC21: VirtaTu | BD21: VirtaTu | BE21: RuetzMa | BF21: WinklerDa | BG21: StefenelliFe | BH21: VirtaTu | BP21: PirasAn | BQ21: PinieOm | BR21: WinklerDa | BV21: RivisFe | BW21: RuetzMa | BY21: RuetzMa | CA21: SnojTa
A22: GrisentiLu | D22: BrondiMa | E22: FecchioFe | G22: ArlicMa | H22: CristeliMa | J22: IlmerNo | N22: Steiner fFe | P22: StrimitzerDa | Q22: DivisDo | T22: CristeliMa | U22: JeramFi | AG22: PreiserJu | AI22: CristeliMa | AJ22: Dummermuth-haasEl | AN22: DivisDo | AP22: Steiner fFe | AT22: StrimitzerDa | AX22: GrisentiLu | AY22: CusinFe | AZ22: RinkerDa | BC22: BrondiMa | BD22: GrisentiLu | BE22: BrondiMa | BF22: DivisDo | BG22: AbeltinoSi | BH22: BrondiMa | BP22: CusinFe | BQ22: AbeltinoSi | BR22: BrondiPa | BV22: BergeljNi | BW22: RinkerDa | BY22: RinkerDa | CA22: BergeljNi
A23: PreiserJu | D23: RivisAn | E23: GrisentiLu | G23: CusinFe | H23: RivisAn | J23: RivisAn | N23: WuchererGe | P23: ZacherlPa | Q23: RivisAn | T23: CusinFe | U23: MarkizetiGr | AG23: RinkerDa | AI23: MurnikPe | AJ23: PreiserJu | AN23: IlmerNo | AP23: VeselkaMa | AT23: VeselkaMa | AX23: RinkerDa | AY23: IlmerNo | AZ23: RivisAn | BC23: CristeliMa | BD23: RinkerDa | BE23: IlmerNo | BF23: RinkerDa | BG23: CristeliMa | BH23: StrimitzerDa | BP23: FecchioFe | BQ23: BrondiPa | BR23: StrimitzerDa | BV23: MiklicGr | BW23: SeewaldJe | BY23: SparerDa | CA23: MiklicGr
D24: SnojTa | H24: BenvegnuAn | J24: RivisFe | P24: BenvegnuAn | Q24: UnterwegerDo | T24: BergantAn | AG24: SpiegelSe | AJ24: PinieOm | AX24: RivisFe | AY24: MoschenAn | AZ24: LazzeriAl | BD24: BenvegnuAn | BE24: LazzeriAl | BF24: MoschenAn | BG24: BergantAn | BH24: SpiegelSe | BQ24: RivisFe | BR24: MoschenAn | BY24: HolzerTo | CA24: BenvegnuAn
D25: SpiegelSe | H25: SpiegelSe | J25: WinklerDa | P25: LebenJa | Q25: WidmannFl | T25: StefenelliFe | AG25: StefenelliFe | AJ25: StefenelliFe | AX25: SoraperraSi | AY25: SnojTa | AZ25: PinieOm | BD25: MetzingerFi | BE25: StefenelliFe | BF25: SpiegelSe | BG25: MetzingerFi | BH25: WinklerDa | BQ25: SpiegelSe | BR25: PinieOm | BY25: VoicanCh | CA25: SoraperraSi
D26: MarkizetiGr | H26: FecchioFe | J26: CristeliMa | P26: GrisentiLu | Q26: StrimitzerDa | T26: BrondiMa | AG26: DivisDo | AJ26: BrondiMa | AX26: BrondiMa | AY26: ArlicMa | AZ26: BrondiPa | BD26: BrondiPa | BE26: BrondiPa | BF26: FecchioFe | BG26: ArlicMa | BH26: DivisDo | BQ26: FecchioFe | BR26: MarkizetiGr | BY26: GrisentiLu | CA26: CristeliMa
D27: StrimitzerDa | H27: IlmerNo | J27: RinkerDa | P27: MurnikPe | Q27: WendnerMa | T27: MurnikPe | AG27: GrisentiLu | AJ27: CusinFe | AX27: FecchioFe | AY27: FleischmannLu | AZ27: CristeliMa | BD27: MurnikPe | BE27: FecchioFe | BF27: IlmerNo | BG27: MiklicGr | BH27: RinkerDa | BQ27: RivisAn | BR27: MurnikPe | BY27: RivisAn | CA27: RivisAn

Sheet AHL_DAT_STRING
A3: 2025-09-20 | B3: 2025-09-21 | C3: 2025-09-26 | D3: 2025-09-27 | E3: 2025-09-25 | F3: 2025-10-01 | G3: 2025-10-02 | H3: 2025-10-04 | I3: 2025-10-10 | J3: 2025-10-11 | K3: 2025-10-07 | L3: 2025-10-09 | M3: 2025-10-14 | N3: 2025-10-16 | O3: 2025-10-17 | P3: 2025-10-18 | Q3: 2025-10-25 | R3: 2025-10-26 | S3: 2025-10-31 | T3: 2025-11-01 | U3: 2025-10-23 | V3: 2025-10-28 | W3: 2025-10-30 | X3: 2025-10-29 | Y3: 2025-11-05 | Z3: 2025-11-07 | AA3: 2025-11-08 | AB3: 2025-11-09 | AC3: 2025-11-11 | AD3: 2025-11-12 | AE3: 2025-11-13 | AF3: 2025-11-14 | AG3: 2025-11-15 | AH3: 2025-11-18 | AI3: 2025-11-20 | AJ3: 2025-11-22 | AK3: 2025-11-23 | AL3: 2025-11-25 | AM3: 2025-11-26 | AN3: 2025-11-27 | AO3: 2025-11-28 | AP3: 2025-11-29 | AQ3: 2025-11-30 | AR3: 2025-12-03 | AS3: 2025-12-04 | AT3: 2025-12-06 | AU3: 2025-12-07 | AV3: 2025-12-13 | AW3: 2025-12-16 | AX3: 2025-12-18 | AY3: 2025-12-20 | AZ3: 2025-12-22 | BA3: 2025-12-10 | BB3: 2026-01-27 | BC3: 2025-12-26 | BD3: 2025-12-28 | BE3: 2025-12-30 | BF3: 2026-01-02 | BG3: 2026-01-04 | BH3: 2026-01-06 | BI3: 2026-01-08 | BJ3: 2026-01-10 | BK3: 2026-01-14 | BL3: 2026-01-17 | BM3: 2026-01-11 | BN3: 2026-01-20 | BO3: 2026-01-22 | BP3: 2026-01-24 | BQ3: 2026-01-29 | BR3: 2026-01-31 | BS3: 2026-02-01 | BT3: 2026-02-04 | BU3: 2026-02-05 | BV3: 2026-02-07 | BW3: 2026-02-17 | BX3: 2026-02-10 | BY3: 2026-02-21 | BZ3: 2026-02-25 | CA3: 2026-02-19 | CB3: 2026-02-24 | CC3: 2026-02-26 | CD3: 2026-02-28 | CE3: 2026-02-14 | CF3: 2026-03-03 | CG3: 2026-03-05 | CH3: 2026-03-07
A4: Eishalle Ritten;MoschenAn;StefenelliFe;AbeltinoSi;BrondiPa | B4: Eishalle Meran;BenvegnuAn;RivisFe;BrondiMa;RivisAn | C4: Eishalle Jesenice;BulovecMi;UnterwegerDo;MiklicGr;WuchererGe | D4: Eishalle Ritten;MoschenAn;PinieOm;BrondiPa;IlmerNo | E4: Eisarena Salzburg;OrelSt;SpiegelSe;RinkerDa;WuchererGe | F4: Eishalle Dornbirn;HolzerTo;WinklerDa;DivisDo;RinkerDa | G4: Eishalle Sissek Zibel;MetzingerFi;SnojTa;MiklicGr;MurnikPe | H4: Eishalle Sterzing;BulovecMi;LazzeriAl;ArlicMa;BrondiPa | I4: Eishalle Jesenice;BrockAd;SnojTa;JeramFi;VeselkaMa | J4: Eishalle Sissek Zibel;MetzingerFi;UnterwegerDo;LegatKo;WuchererGe | K4: Eishalle Ritten;LazzeriAl;OrelSt;BrondiPa;FleischmannLu | L4: Eisarena Salzburg;HlavatyAl;VoicanCh;LegatKo;WendnerMa | M4: Eisarena Salzburg;Huber rRe;OrelSt;DivisDo;WuchererGe | N4: Sportpark Kitzbühel;BulovecMi;SnojTa;BergeljNi;StrimitzerDa | O4: Eisarena Salzburg;VoicanCh;WinklerDa;PreiserJu;RinkerDa | P4: Eishalle Ritten;PirasAn;SoraperraSi;AbeltinoSi;CusinFe | Q4: Eishalle Gröden;MoschenAn;RivisFe;FecchioFe;IlmerNo | R4: Eishalle Sissek Zibel;BrockAd;SnojTa;PreiserJu;VeselkaMa | S4: Eishalle Cortina;LebenJa;WinklerDa;FleischmannLu;MarkizetiGr | T4: Eisarena Salzburg;RuetzMa;VoicanCh;PreiserJu;RinkerDa | U4: KELIT Arena Zell am See;Huber rRe;WinklerDa;MoidlMa;Steiner fFe | V4: Eisarena Salzburg;Huber rRe;SpiegelSe;Dummermuth-haasEl;StrimitzerDa | W4: Eishalle Sissek Zibel;MetzingerFi;UnterwegerDo;ArlicMa;MiklicGr | X4: Würtharena Neumarkt;MoschenAn;OrelSt;BrondiPa;WuchererGe | Y4: Eishalle Dornbirn;BrockAd;WinklerDa;IlmerNo;VeselkaMa | Z4: Eishalle Meran;BergantAn;BulovecMi;ArlicMa;MarkizetiGr | AA4: Eishalle Gröden;GiacomozziFe;LazzeriAl;BrondiMa;FecchioFe | AB4: Eishalle Sterzing;OrelSt;VirtaTu;LegatKo;WuchererGe | AC4: Eishalle Asiago;BenvegnuAn;MoschenAn;AbeltinoSi;GrisentiLu | AD4: Eishalle Dornbirn;HolzerTo;Huber rRe;StrimitzerDa;VeselkaMa | AE4: Eishalle Sissek Zibel;MetzingerFi;SnojTa;MiklicGr;MurnikPe | AF4: Eishalle Jesenice;BulovecMi;WidmannFl;WendnerMa;WuchererGe | AG4: Eishalle Ritten;GiacomozziFe;MoschenAn;BrondiPa;CusinFe | AH4: Eisarena Salzburg;OrelSt;UnterwegerDo;SeewaldJe;WuchererGe | AI4: Eishalle Jesenice;MetzingerFi;VoicanCh;LegatKo;MarkizetiGr | AJ4: Eishalle Ritten;GiacomozziFe;RuetzMa;Steiner fFe;VeselkaMa | AK4: Eishalle Dornbirn;OrelSt;UnterwegerDo;StrimitzerDa;WuchererGe | AL4: Eisarena Salzburg;BrockAd;VoicanCh;VeselkaMa;WendnerMa | AM4: Eishalle Dornbirn;Huber rRe;WinklerDa;DivisDo;RinkerDa | AN4: Eishalle Sissek Zibel;MetzingerFi;SnojTa;ArlicMa;MiklicGr | AO4: Eishalle Meran;PinieOm;UnterwegerDo;CristeliMa;GrisentiLu | AP4: Eishalle Jesenice;BrockAd;HlavatyAl;LegatKo;PreiserJu | AQ4: Eishalle Sterzing;OrelSt;UnterwegerDo;CristeliMa;WuchererGe | AR4: Eishalle Dornbirn;SpiegelSe;WinklerDa;DivisDo;RinkerDa | AS4: Eishalle Gröden;MoschenAn;PirasAn;CalloviniAn;StrimitzerDa | AT4: Eishalle Sterzing;GiacomozziFe;LazzeriAl;AbeltinoSi;RivisAn | AU4: Eishalle Cortina;PinieOm;StefenelliFe;CusinFe;GrisentiLu | AV4: Eishalle Meran;LazzeriAl;MoschenAn;CusinFe;RivisAn | AW4: Eisarena Salzburg;UnterwegerDo;VoicanCh;LegatKo;WuchererGe | AX4: Eishalle Sissek Zibel;BergantAn;OrelSt;ArlicMa;WendnerMa | AY4: Eishalle Sterzing;LazzeriAl;StefenelliFe;CristeliMa;RivisAn | AZ4: Eishalle Meran;OrelSt;UnterwegerDo;AbeltinoSi;FecchioFe | BA4: Eishalle Dornbirn;Huber rRe;SpiegelSe;DivisDo;RinkerDa | BB4: Eishalle Jesenice;BulovecMi;OrelSt;ArlicMa;LegatKo | BC4: Eishalle Sissek Zibel;LebenJa;MetzingerFi;ArlicMa;PreiserJu | BD4: Eishalle Sterzing;HlavatyAl;HolzerTo;DivisDo;PreiserJu | BE4: Eisarena Salzburg;UnterwegerDo;WinklerDa;StrimitzerDa;ZacherlPa | BF4: Eishalle Jesenice;HlavatyAl;UnterwegerDo;ArlicMa;MarkizetiGr | BG4: Eisarena Salzburg;OrelSt;UnterwegerDo;SeewaldJe;StrimitzerDa | BH4: Eisarena Salzburg;HlavatyAl;PirasAn;PreiserJu;ZacherlPa | BI4: Eishalle Jesenice;MetzingerFi;SnojTa;MurnikPe;WuchererGe | BJ4: Eisarena Salzburg;BrockAd;Huber rRe;Steiner fFe;StrimitzerDa | BK4: Eishalle Gröden;MoschenAn;PirasAn;AbeltinoSi;RivisAn | BL4: Würtharena Neumarkt;LazzeriAl;VirtaTu;BrondiMa;FecchioFe | BM4: Eishalle Dornbirn;MoschenAn;WinklerDa;IlmerNo;RinkerDa | BN4: Eishalle Ritten;BergantAn;Huber rRe;ArlicMa;RinkerDa | BO4: Eishalle Sissek Zibel;BergantAn;MetzingerFi;JeramFi;WendnerMa | BP4: Eishalle Sterzing;SpiegelSe;VirtaTu;BrondiPa;FleischmannLu | BQ4: Eisarena Salzburg;HlavatyAl;OrelSt;WuchererGe;ZacherlPa | BR4: Eishalle Jesenice;BrockAd;LebenJa;BergeljNi;Dummermuth-haasEl | BS4: Eishalle Sissek Zibel;OrelSt;UnterwegerDo;LegatKo;WuchererGe | BT4: Eishalle Dornbirn;Huber rRe;SpiegelSe;IlmerNo;SeewaldJe | BU4: KELIT Arena Zell am See;UnterwegerDo;WinklerDa;Dummermuth-haasEl;StrimitzerDa | BV4: Eishalle Ritten;PirasAn;StefenelliFe;CusinFe;RivisAn | BW4: Eishalle Dornbirn;MoschenAn;SpiegelSe;DivisDo;IlmerNo | BX4: Eishalle Jesenice;BergantAn;OrelSt;VeselkaMa;WendnerMa | BY4: Eishalle Sterzing;BulovecMi;SnojTa;CusinFe;DivisDo | BZ4: Eishalle Dornbirn;HolzerTo;LazzeriAl;AbeltinoSi;BrondiMa | CA4: Eishalle Sissek Zibel;LebenJa;VoicanCh;LegatKo;PreiserJu | CB4: Eishalle Gröden;Huber rRe;StefenelliFe;CalloviniAn;StrimitzerDa | CC4: Würtharena Neumarkt;PinieOm;VirtaTu;CristeliMa;IlmerNo | CD4: KELIT Arena Zell am See;BrockAd;Huber rRe;LegatKo;SeewaldJe | CE4: Sportpark Kitzbühel;Huber rRe;LazzeriAl;GrisentiLu;StrimitzerDa | CF4: Eishalle Sissek Zibel;BergantAn;MetzingerFi;MarkizetiGr;MiklicGr | CG4: Eisarena Salzburg;Huber rRe;WinklerDa;StrimitzerDa;VeselkaMa | CH4: Eisarena Salzburg;HolzerTo;VoicanCh;DivisDo;PreiserJu
A5: Würtharena Neumarkt;PinieOm;VirtaTu;CusinFe;FecchioFe | D5: Eishalle Sissek Zibel;BergantAn;LebenJa;JeramFi;MiklicGr | E5: Sportpark Kitzbühel;HolzerTo;Huber rRe;Steiner fFe;VeselkaMa | G5: Würtharena Neumarkt;Huber rRe;WinklerDa;BrondiPa;BrondiMa | H5: Eishalle Jesenice;HlavatyAl;VoicanCh;MurnikPe;PreiserJu | I5: Eishalle Asiago;MoschenAn;VirtaTu;CristeliMa;FecchioFe | J5: Würtharena Neumarkt;GiacomozziFe;StefenelliFe;BrondiMa;FleischmannLu | K5: Eishalle Asiago;PinieOm;StefenelliFe;GrisentiLu;IlmerNo | L5: Eishalle Ritten;Huber rRe;SpiegelSe;AbeltinoSi;RinkerDa | M5: KELIT Arena Zell am See;BenvegnuAn;PinieOm;GrisentiLu;SeewaldJe | N5: Würtharena Neumarkt;LazzeriAl;RivisFe;BrondiPa;RivisAn | P5: Eishalle Sterzing;BrockAd;UnterwegerDo;VeselkaMa;WuchererGe | Q5: Eishalle Sissek Zibel;BrockAd;SnojTa;PreiserJu;VeselkaMa | T5: Eishalle Ritten;PinieOm;RivisFe;GrisentiLu;RivisAn | U5: Eishalle Jesenice;MetzingerFi;RivisFe;ArlicMa;BrondiPa | W5: KELIT Arena Zell am See;BulovecMi;HlavatyAl;LegatKo;MurnikPe | AA5: Eishalle Cortina;BergantAn;BulovecMi;ArlicMa;MarkizetiGr | AB5: Eishalle Cortina;RivisFe;StefenelliFe;CristeliMa;IlmerNo | AE5: Eishalle Asiago;LazzeriAl;PirasAn;FleischmannLu;IlmerNo | AG5: Eishalle Sterzing;Huber rRe;PinieOm;CristeliMa;RivisAn | AI5: KELIT Arena Zell am See;LazzeriAl;LebenJa;AbeltinoSi;ArlicMa | AJ5: Eishalle Gröden;Huber rRe;SpiegelSe;DivisDo;GrisentiLu | AK5: Eishalle Meran;Huber rRe;SpiegelSe;DivisDo;FleischmannLu | AN5: Sportpark Kitzbühel;BenvegnuAn;WinklerDa;FecchioFe;MoidlMa | AP5: KELIT Arena Zell am See;HolzerTo;Huber rRe;MarkizetiGr;SeewaldJe | AS5: Eishalle Meran;UnterwegerDo;VirtaTu;FleischmannLu;WendnerMa | AT5: Eishalle Ritten;BenvegnuAn;PinieOm;CristeliMa;FecchioFe | AV5: Sportpark Kitzbühel;HolzerTo;UnterwegerDo;DivisDo;PreiserJu | AX5: KELIT Arena Zell am See;BajtMi;SnojTa;MarkizetiGr;VeselkaMa | AY5: Eishalle Jesenice;LebenJa;VoicanCh;JeramFi;MiklicGr | AZ5: Eishalle Sissek Zibel;BulovecMi;SnojTa;LegatKo;WendnerMa | BB5: Eishalle Asiago;PinieOm;StefenelliFe;BrondiPa;FecchioFe | BC5: KELIT Arena Zell am See;OrelSt;UnterwegerDo;StrimitzerDa;WuchererGe | BD5: Eishalle Meran;GiacomozziFe;PinieOm;CristeliMa;FleischmannLu | BE5: KELIT Arena Zell am See;KeldererMo;MoidlDa;MattheyPh;MoidlMa | BF5: Sportpark Kitzbühel;BenvegnuAn;WidmannFl;Dummermuth-haasEl;RivisAn | BG5: Eishalle Ritten;BulovecMi;SnojTa;BrondiPa;FleischmannLu | BH5: Würtharena Neumarkt;BenvegnuAn;RivisFe;FecchioFe;FleischmannLu | BI5: KELIT Arena Zell am See;BulovecMi;VoicanCh;JeramFi;VeselkaMa | BJ5: Eishalle Meran;LazzeriAl;RivisFe;LegatKo;WendnerMa | BL5: Eishalle Dornbirn;HolzerTo;SpiegelSe;DivisDo;StrimitzerDa | BO5: Eishalle Asiago;PinieOm;RivisFe;GrisentiLu;IlmerNo | BP5: Eishalle Jesenice;SnojTa;VoicanCh;MurnikPe;PreiserJu | BQ5: Sportpark Kitzbühel;Huber rRe;UnterwegerDo;RinkerDa;WendnerMa | BR5: Eishalle Ritten;LazzeriAl;RuetzMa;BrondiMa;DivisDo | BU5: Eishalle Sissek Zibel;MetzingerFi;SnojTa;ArlicMa;LegatKo | BV5: Würtharena Neumarkt;MoschenAn;PinieOm;AbeltinoSi;GrisentiLu | BW5: Eishalle Sterzing;LazzeriAl;VirtaTu;BrondiMa;BrondiPa | BY5: Eishalle Jesenice;BergantAn;MetzingerFi;MurnikPe;WendnerMa | BZ5: Eisarena Salzburg;OrelSt;WinklerDa;PreiserJu;RinkerDa | CA5: Eishalle Asiago;RuetzMa;StefenelliFe;FecchioFe;RinkerDa | CC5: Eishalle Sterzing;HlavatyAl;UnterwegerDo;DivisDo;VeselkaMa | CD5: Eishalle Asiago;PirasAn;StefenelliFe;BrondiPa;CusinFe | CF5: KELIT Arena Zell am See;OrelSt;UnterwegerDo;WendnerMa;WuchererGe | CG5: Eishalle Sterzing;BenvegnuAn;LazzeriAl;AbeltinoSi;BrondiMa | CH5: Eishalle Asiago;MoschenAn;VirtaTu;CristeliMa;IlmerNo
A6: Eisarena Salzburg;RuetzMa;WinklerDa;DivisDo;WendnerMa | D6: Eishalle Meran;VirtaTu;WinklerDa;AbeltinoSi;RinkerDa | E6: Eishalle Sterzing;LebenJa;SnojTa;MarkizetiGr;MiklicGr | G6: Eishalle Ritten;BulovecMi;LebenJa;AbeltinoSi;CristeliMa | H6: Eisarena Salzburg;OrelSt;UnterwegerDo;WuchererGe;ZacherlPa | J6: Eishalle Meran;BergantAn;OrelSt;ArlicMa;StrimitzerDa | L6: Eishalle Sterzing;HolzerTo;WinklerDa;DivisDo;StrimitzerDa | M6: Eishalle Jesenice;BrockAd;PirasAn;FecchioFe;Steiner fFe | N6: Eishalle Gröden;GiacomozziFe;SpiegelSe;DivisDo;GrisentiLu | P6: Eishalle Jesenice;HlavatyAl;OrelSt;LegatKo;WendnerMa | Q6: Würtharena Neumarkt;GiacomozziFe;WinklerDa;BrondiPa;RinkerDa | T6: KELIT Arena Zell am See;HlavatyAl;SpiegelSe;AbeltinoSi;DivisDo | U6: Eishalle Sterzing;LazzeriAl;PirasAn;CusinFe;StrimitzerDa | W6: Eishalle Sterzing;GiacomozziFe;VirtaTu;BrondiMa;RivisAn | AE6: Sportpark Kitzbühel;OrelSt;WinklerDa;LegatKo;WuchererGe | AG6: Eishalle Sissek Zibel;SnojTa;UnterwegerDo;StrimitzerDa;VeselkaMa | AI6: Würtharena Neumarkt;BergantAn;PirasAn;BergeljNi;BrondiPa | AJ6: Würtharena Neumarkt;BulovecMi;RivisFe;MiklicGr;RivisAn | AN6: Eishalle Sterzing;MoschenAn;StefenelliFe;BrondiPa;CristeliMa | AP6: Eishalle Sissek Zibel;BergantAn;BulovecMi;JeramFi;WendnerMa | AT6: Würtharena Neumarkt;Huber rRe;RivisFe;RinkerDa;ZacherlPa | AV6: Eishalle Dornbirn;BrockAd;SpiegelSe;Steiner fFe;VeselkaMa | AX6: Sportpark Kitzbühel;BulovecMi;Huber rRe;MurnikPe;StrimitzerDa | AY6: Eisarena Salzburg;BrockAd;HlavatyAl;PreiserJu;VeselkaMa | AZ6: Eishalle Ritten;BergantAn;WinklerDa;MarkizetiGr;StrimitzerDa | BC6: Eishalle Dornbirn;Huber rRe;SpiegelSe;Dummermuth-haasEl;SeewaldJe | BD6: Eishalle Ritten;PirasAn;StefenelliFe;AbeltinoSi;FecchioFe | BE6: Eishalle Sissek Zibel;BergantAn;LebenJa;JeramFi;WendnerMa | BF6: Würtharena Neumarkt;PinieOm;VirtaTu;BrondiPa;BrondiMa | BG6: Eishalle Sterzing;PinieOm;PirasAn;LegatKo;WendnerMa | BH6: Eishalle Jesenice;LebenJa;OrelSt;BergeljNi;MarkizetiGr | BI6: Eishalle Meran;MoschenAn;PinieOm;BrondiPa;CristeliMa | BL6: Eishalle Asiago;SnojTa;StefenelliFe;MiklicGr;RivisAn | BO6: Eishalle Sterzing;OrelSt;UnterwegerDo;AbeltinoSi;WuchererGe | BP6: KELIT Arena Zell am See;BrockAd;WinklerDa;Steiner fFe;VeselkaMa | BQ6: Eishalle Pieve di Cadore;LebenJa;MoschenAn;CristeliMa;CusinFe | BR6: Eishalle Sissek Zibel;BergantAn;SnojTa;MiklicGr;PreiserJu | BU6: Sportpark Kitzbühel;BrockAd;HolzerTo;RinkerDa;WendnerMa | BV6: Eisarena Salzburg;HlavatyAl;OrelSt;LegatKo;WuchererGe | BW6: Eishalle Pieve di Cadore;BenvegnuAn;RivisFe;CristeliMa;RivisAn | BY6: Eishalle Ritten;HlavatyAl;PinieOm;BrondiPa;Steiner fFe | CA6: Eishalle Ritten;LazzeriAl;PinieOm;AbeltinoSi;BrondiMa | CC6: Eishalle Gröden;BenvegnuAn;MoschenAn;FecchioFe;GrisentiLu
A7: Sportpark Kitzbühel;Huber rRe;PirasAn;IlmerNo;StrimitzerDa | D7: KELIT Arena Zell am See;BrockAd;RuetzMa;PreiserJu;VeselkaMa | E7: Würtharena Neumarkt;BergantAn;LazzeriAl;BrondiPa;JeramFi | G7: Eishalle Meran;PinieOm;StefenelliFe;FecchioFe;RivisAn | H7: Sportpark Kitzbühel;MetzingerFi;MoschenAn;GrisentiLu;JeramFi | J7: Eishalle Gröden;Huber rRe;LazzeriAl;AbeltinoSi;DivisDo | L7: Eishalle Cortina;BenvegnuAn;BulovecMi;CusinFe;MarkizetiGr | M7: Eishalle Ritten;BajtMi;MoschenAn;MarkizetiGr;MiklicGr | N7: Eishalle Jesenice;BergantAn;LebenJa;LegatKo;WendnerMa | P7: KELIT Arena Zell am See;BergantAn;GiacomozziFe;ArlicMa;IlmerNo | Q7: Eisarena Salzburg;BenvegnuAn;BergantAn;GrisentiLu;MiklicGr | T7: Sportpark Kitzbühel;BrockAd;UnterwegerDo;Steiner fFe;WuchererGe | U7: Eishalle Asiago;PinieOm;VirtaTu;AbeltinoSi;BrondiMa | W7: Eishalle Ritten;BenvegnuAn;LazzeriAl;FecchioFe;IlmerNo | AG7: Würtharena Neumarkt;BenvegnuAn;VirtaTu;BrondiMa;FecchioFe | AI7: Eishalle Meran;Huber rRe;SoraperraSi;FleischmannLu;RinkerDa | AJ7: Eishalle Dornbirn;OrelSt;UnterwegerDo;StrimitzerDa;WuchererGe | AN7: Eishalle Gröden;LebenJa;VirtaTu;AbeltinoSi;BergeljNi | AP7: Eishalle Asiago;RivisFe;RuetzMa;CusinFe;StrimitzerDa | AT7: Sportpark Kitzbühel;MetzingerFi;VoicanCh;MurnikPe;PreiserJu | AV7: Eishalle Pieve di Cadore;LebenJa;VirtaTu;BrondiMa;MiklicGr | AX7: Würtharena Neumarkt;GiacomozziFe;PirasAn;AbeltinoSi;BrondiPa | AY7: Eishalle Dornbirn;HolzerTo;RuetzMa;DivisDo;SeewaldJe | AZ7: Würtharena Neumarkt;BenvegnuAn;RivisFe;CalloviniAn;GrisentiLu | BC7: Sportpark Kitzbühel;MoschenAn;WinklerDa;FecchioFe;IlmerNo | BD7: Eishalle Jesenice;BulovecMi;SnojTa;Steiner fFe;VeselkaMa | BE7: Sportpark Kitzbühel;Huber rRe;OrelSt;DivisDo;WuchererGe | BF7: Eishalle Sterzing;GiacomozziFe;RivisFe;AbeltinoSi;GrisentiLu | BG7: KELIT Arena Zell am See;HolzerTo;Huber rRe;Steiner fFe;VeselkaMa | BH7: Sportpark Kitzbühel;LazzeriAl;RuetzMa;GrisentiLu;IlmerNo | BL7: Sportpark Kitzbühel;UnterwegerDo;WinklerDa;MarkizetiGr;WuchererGe | BO7: Würtharena Neumarkt;SoraperraSi;StefenelliFe;CalloviniAn;RivisAn | BP7: Eishalle Dornbirn;HolzerTo;Huber rRe;SeewaldJe;ZacherlPa | BQ7: Eishalle Meran;BulovecMi;MetzingerFi;FleischmannLu;MarkizetiGr | BR7: Würtharena Neumarkt;PirasAn;StefenelliFe;Steiner fFe;VeselkaMa | BU7: Eishalle Pieve di Cadore;BenvegnuAn;LazzeriAl;CristeliMa;GrisentiLu | BV7: Eishalle Meran;BulovecMi;LebenJa;FecchioFe;FleischmannLu | BW7: Eishalle Sissek Zibel;OrelSt;UnterwegerDo;MarkizetiGr;MurnikPe | BY7: Eishalle Meran;OrelSt;PirasAn;IlmerNo;WuchererGe | CA7: Eishalle Meran;MoschenAn;VirtaTu;Dummermuth-haasEl;ZacherlPa | CC7: Eishalle Pieve di Cadore;LebenJa;RivisFe;ArlicMa;RivisAn
