Workbook

Sheet AHL
A2: =COUNTIF(A4:A47,"<>") -> 17 | B2: =COUNTIF(B4:B47,"<>") -> 7 | C2: =COUNTIF(C4:C50,"<>") -> 20 | D2: =COUNTIF(D4:D49,"<>") -> 31 | E2: =COUNTIF(E4:E51,"<>") -> 16 | F2: =COUNTIF(F4:F51,"<>") -> 15 | G2: =COUNTIF(G4:G46,"<>") -> 25 | H2: =COUNTIF(H4:H45,"<>") -> 20 | I2: =COUNTIF(I4:I54,"<>") -> 29 | J2: =COUNTIF(J4:J55,"<>") -> 14 | K2: =COUNTIF(K4:K53,"<>") -> 25 | L2: =COUNTIF(L4:L53,"<>") -> 32 | M2: =COUNTIF(M4:M53,"<>") -> 43 | N2: =COUNTIF(N4:N53,"<>") -> 22 | O2: =COUNTIF(O4:O54,"<>") -> 38 | P2: =COUNTIF(P4:P49,"<>") -> 34 | Q2: =COUNTIF(Q4:Q52,"<>") -> 35 | R2: =COUNTIF(R4:R54,"<>") -> 27 | S2: =COUNTIF(S4:S50,"<>") -> 41 | T2: =COUNTIF(T4:T54,"<>") -> 21 | U2: =COUNTIF(U4:U55,"<>") -> 31 | V2: =COUNTIF(V4:V54,"<>") -> 35 | W2: =COUNTIF(W4:W54,"<>") -> 21 | X2: =COUNTIF(X4:X53,"<>") -> 22 | Y2: =COUNTIF(Y4:Y55,"<>") -> 10 | Z2: =COUNTIF(Z4:Z53,"<>") -> 8 | AA2: =COUNTIF(AA4:AA53,"<>") -> 31 | AB2: =COUNTIF(AB4:AB54,"<>") -> 19 | AC2: =COUNTIF(AC4:AC52,"<>") -> 17 | AD2: =COUNTIF(AD4:AD55,"<>") -> 23 | AE2: =COUNTIF(AE4:AE53,"<>") -> 16 | AF2: =COUNTIF(AF4:AF47,"<>") -> 44 | AG2: =COUNTIF(AG4:AG54,"<>") -> 19 | AH2: =COUNTIF(AH4:AH53,"<>") -> 16 | AI2: =COUNTIF(AI4:AI54,"<>") -> 21 | AJ2: =COUNTIF(AJ4:AJ54,"<>") -> 12 | AK2: =COUNTIF(AK4:AK55,"<>") -> 19 | AL2: =COUNTIF(AL4:AL55,"<>") -> 21 | AM2: =COUNTIF(AM4:AM55,"<>") -> 21 | AN2: =COUNTIF(AN4:AN55,"<>") -> 25 | AO2: =COUNTIF(AO4:AO54,"<>") -> 10 | AP2: =COUNTIF(AP4:AP55,"<>") -> 27 | AQ2: =COUNTIF(AQ4:AQ55,"<>") -> 23 | AR2: =COUNTIF(AR4:AR53,"<>") -> 29 | AS2: =COUNTIF(AS4:AS54,"<>") -> 24 | AT2: =COUNTIF(AT4:AT55,"<>") -> 24 | AU2: =COUNTIF(AU4:AU55,"<>") -> 31 | AV2: =COUNTIF(AV4:AV55,"<>") -> 25 | AW2: =COUNTIF(AW4:AW53,"<>") -> 25 | AX2: =COUNTIF(AX4:AX55,"<>") -> 24 | AY2: =COUNTIF(AY4:AY55,"<>") -> 22 | AZ2: =COUNTIF(AZ4:AZ55,"<>") -> 22 | BA2: =COUNTIF(BA4:BA55,"<>") -> 4 | BB2: =COUNTIF(BB4:BB55,"<>") -> 23 | BC2: =COUNTIF(BC4:BC55,"<>") -> 24 | BD2: =COUNTIF(BD4:BD55,"<>") -> 20 | BE2: =COUNTIF(BE4:BE55,"<>") -> 17 | BF2: =COUNTIF(BF4:BF55,"<>") -> 18 | BG2: =COUNTIF(BG4:BG54,"<>") -> 21 | BH2: =COUNTIF(BH4:BH55,"<>") -> 21 | BI2: =COUNTIF(BI4:BI55,"<>") -> 18 | BJ2: =COUNTIF(BJ4:BJ55,"<>") -> 2 | BK2: =COUNTIF(BK4:BK55,"<>") -> 21 | BL2: =COUNTIF(BL4:BL54,"<>") -> 18 | BM2: =COUNTIF(BM4:BM54,"<>") -> 24 | BN2: =COUNTIF(BN4:BN55,"<>") -> 17 | BO2: =COUNTIF(BO4:BO55,"<>") -> 2 | BP2: =COUNTIF(BP4:BP55,"<>") -> 5 | BQ2: =COUNTIF(BQ4:BQ55,"<>") -> 7 | BR2: =COUNTIF(BR4:BR55,"<>") -> 3 | BS2: =COUNTIF(BS4:BS55,"<>") -> 1 | BT2: =COUNTIF(BT4:BT55,"<>") -> 1 | BU2: =COUNTIF(BU4:BU55,"<>") -> 1 | BV2: =COUNTIF(BV4:BV55,"<>") -> 1
A3: FAJDIGA | B3: GROZNIK | C3: REZEK | D3: BAJT | E3: PAHOR | F3: LESNIAK | G3: SNOJ | H3: BERGANT | I3: ARLIC | J3: JAVORNIK | K3: WEISS | L3: LAZZERI | M3: MOSCHEN | N3: HLAVATY | O3: RUETZ | P3: EISL | Q3: DE ZORDO | R3: KAINBERGER | S3: HUBER | T3: MOIDL | U3: PUFF | V3: SCHAUER | W3: WIMMLER | X3: MANTOVANI | Y3: BASSO | Z3: RIGONI | AA3: CRISTELI | AB3: LOICHT | AC3: LEGAT | AD3: OREL | AE3: PODLESNIK | AF3: HOLZER | AG3: SCHWEIGHOFER | AH3: KUMMER | AI3: MATTHEY | AJ3: SCHONAKLENER | AK3: LEGA | AL3: SORAPERRA | AM3: BASSANI | AN3: BRUNNER | AO3: REISINGER | AP3: SPIEGEL | AQ3: WUNTSCHEK | AR3: RINKER | AS3: HEINRICHER | AT3: VOICAN | AU3: BENVEGNU | AV3: PINIE | AW3: FLEISCHMANN | AX3: PIRAS | AY3: GIACOMOZZI | AZ3: DA PIAN | BA3: MARTIN | BB3: BEDANA | BC3: EGGER | BD3: BRONDI | BE3: PÖTSCHER | BF3: DURCHNER | BG3: VIRTA | BH3: STEFENELLI | BI3: PACE | BJ3: RICCO | BK3: WALLNER | BL3: WIDMANN | BM3: TSCHREPITSCH | BN3: LEHNER | BO3: SEEWALD | BP3: TELESKLAV | BQ3: MÜLLER | BR3: WUCHERER | BS3: BEDYNEK | BT3: NOTHEGGER | BU3: KANYO | BV3: Milovanovic
A4: 2021-09-11 | B4: 2021-09-18 | C4: 2021-09-18 | D4: 2021-09-16 | E4: 2021-09-23 | F4: 2021-09-11 | G4: 2021-09-11 | H4: 2021-09-23 | I4: 2021-09-11 | J4: 2021-09-18 | K4: 2021-09-16 | L4: 2021-09-16 | M4: 2021-09-14 | N4: 2021-09-28 | O4: 2021-09-11 | P4: 2021-09-14 | Q4: 2021-09-11 | R4: 2021-09-11 | S4: 2021-09-11 | T4: 2021-09-11 | U4: 2021-09-11 | V4: 2021-09-11 | W4: 2021-09-18 | X4: 2021-09-16 | Y4: 2021-09-18 | Z4: 2021-09-16 | AA4: 2021-09-11 | AB4: 2021-09-23 | AC4: 2021-09-23 | AD4: 2021-09-16 | AE4: 2021-09-24 | AF4: 2021-09-11 | AG4: 2021-09-30 | AH4: 2021-09-23 | AI4: 2021-09-11 | AJ4: 2021-09-23 | AK4: 2021-09-11 | AL4: 2021-10-01 | AM4: 2021-09-25 | AN4: 2021-09-11 | AO4: 2021-09-11 | AP4: 2021-09-11 | AQ4: 2021-09-11 | AR4: 2021-09-11 | AS4: 2021-09-11 | AT4: 2021-09-11 | AU4: 2021-09-11 | AV4: 2021-09-11 | AW4: 2021-09-11 | AX4: 2021-09-11 | AY4: 2021-09-11 | AZ4: 2021-09-11 | BA4: 2021-09-14 | BB4: 2021-09-14 | BC4: 2021-09-18 | BD4: 2021-09-14 | BE4: 2021-09-16 | BF4: 2021-09-18 | BG4: 2021-09-18 | BH4: 2021-09-23 | BI4: 2021-09-23 | BJ4: 2021-09-23 | BK4: 2021-09-23 | BL4: 2021-09-24 | BM4: 2021-09-30 | BN4: 2021-10-07 | BO4: 2021-10-09 | BP4: 2021-10-14 | BQ4: 2021-11-11 | BR4: 2021-12-02 | BS4: 2021-11-11 | BT4: 2021-12-28 | BU4: 2022-01-06 | BV4: 2021-12-30
A5: 2021-09-18 | B5: 2021-09-25 | C5: 2021-09-25 | D5: 2021-09-18 | E5: 2021-09-30 | F5: 2021-09-18 | G5: 2021-09-16 | H5: 2021-10-05 | I5: 2021-09-18 | J5: 2021-09-30 | K5: 2021-09-18 | L5: 2021-09-18 | M5: 2021-09-16 | N5: 2021-10-07 | O5: 2021-09-16 | P5: 2021-09-18 | Q5: 2021-09-16 | R5: 2021-09-18 | S5: 2021-09-18 | T5: 2021-09-18 | U5: 2021-09-16 | V5: 2021-09-18 | W5: 2021-09-23 | X5: 2021-09-18 | Y5: 2021-09-11 | Z5: 2021-09-18 | AA5: 2021-09-16 | AB5: 2021-09-28 | AC5: 2021-09-28 | AD5: 2021-09-30 | AE5: 2021-09-25 | AF5: 2021-09-14 | AG5: 2021-10-02 | AH5: 2021-09-28 | AI5: 2021-10-07 | AJ5: 2021-09-25 | AK5: 2021-10-01 | AL5: 2021-10-02 | AM5: 2021-10-01 | AN5: 2021-09-18 | AO5: 2021-09-18 | AP5: 2021-09-18 | AQ5: 2021-09-11 | AR5: 2021-09-16 | AS5: 2021-09-16 | AT5: 2021-10-07 | AU5: 2021-09-14 | AV5: 2021-09-16 | AW5: 2021-09-23 | AX5: 2021-09-14 | AY5: 2021-09-14 | AZ5: 2021-09-18 | BA5: 2021-10-09 | BB5: 2021-09-16 | BC5: 2021-09-14 | BD5: 2021-09-28 | BE5: 2021-09-24 | BF5: 2021-09-25 | BG5: 2021-09-25 | BH5: 2021-09-28 | BI5: 2021-10-26 | BJ5: 2021-10-02 | BK5: 2021-09-28 | BL5: 2021-09-25 | BM5: 2021-10-28 | BN5: 2021-10-09 | BO5: 2021-10-30 | BP5: 2021-11-18 | BQ5: 2021-11-13 | BR5: 2021-12-30
A6: 2021-09-25 | B6: 2021-10-02 | C6: 2021-10-02 | D6: 2021-09-11 | E6: 2021-10-09 | F6: 2021-09-30 | G6: 2021-09-18 | H6: 2021-10-09 | I6: 2021-09-25 | J6: 2021-10-08 | K6: 2021-09-25 | L6: 2021-09-23 | M6: 2021-09-18 | N6: 2021-10-16 | O6: 2021-09-18 | P6: 2021-09-23 | Q6: 2021-09-25 | R6: 2021-09-11 | S6: 2021-09-23 | T6: 2021-10-02 | U6: 2021-09-24 | V6: 2021-09-23 | W6: 2021-10-29 | X6: 2021-09-25 | Y6: 2021-10-30 | Z6: 2021-10-09 | AA6: 2021-09-18 | AB6: 2021-10-02 | AC6: 2021-10-02 | AD6: 2021-10-02 | AE6: 2021-10-23 | AF6: 2021-09-18 | AG6: 2021-10-09 | AH6: 2021-10-09 | AI6: 2021-10-14 | AJ6: 2021-10-02 | AK6: 2021-10-02 | AL6: 2021-10-14 | AM6: 2021-10-02 | AN6: 2021-09-23 | AO6: 2021-09-23 | AP6: 2021-09-28 | AQ6: 2021-09-23 | AR6: 2021-09-11 | AS6: 2021-09-30 | AT6: 2021-10-16 | AU6: 2021-09-18 | AV6: 2021-09-30 | AW6: 2021-09-30 | AX6: 2021-09-25 | AY6: 2021-09-23 | AZ6: 2021-10-02 | BA6: 2021-09-23 | BB6: 2021-09-18 | BC6: 2021-09-23 | BD6: 2021-10-14 | BE6: 2021-09-25 | BF6: 2021-10-02 | BG6: 2021-10-02 | BH6: 2021-10-07 | BI6: 2021-11-04 | BK6: 2021-10-14 | BL6: 2021-10-07 | BM6: 2021-10-30 | BN6: 2021-10-14 | BP6: 2021-11-27 | BQ6: 2021-12-11 | BR6: 2022-02-05
A7: 2021-10-02 | B7: 2021-10-14 | C7: 2021-09-11 | D7: 2021-10-05 | E7: 2021-10-18 | F7: 2021-10-09 | G7: 2021-09-25 | H7: 2021-10-18 | I7: 2021-09-30 | J7: 2021-10-16 | K7: 2021-09-28 | L7: 2021-10-02 | M7: 2021-09-23 | N7: 2021-10-17 | O7: 2021-09-11 | P7: 2021-09-25 | Q7: 2021-10-02 | R7: 2021-09-23 | S7: 2021-09-30 | T7: 2021-10-03 | U7: 2021-09-25 | V7: 2021-10-02 | W7: 2021-11-06 | X7: 2021-10-02 | Y7: 2021-11-06 | Z7: 2021-10-16 | AA7: 2021-09-23 | AB7: 2021-09-11 | AC7: 2021-10-14 | AD7: 2021-10-07 | AE7: 2021-10-28 | AF7: 2021-09-23 | AG7: 2021-10-21 | AH7: 2021-10-23 | AI7: 2021-10-16 | AJ7: 2021-10-07 | AK7: 2021-10-15 | AL7: 2021-10-21 | AM7: 2021-10-15 | AN7: 2021-09-25 | AO7: 2021-10-02 | AP7: 2021-10-09 | AQ7: 2021-09-16 | AR7: 2021-09-30 | AS7: 2021-10-08 | AT7: 2021-10-17 | AU7: 2021-09-16 | AV7: 2021-10-07 | AW7: 2021-09-22 | AX7: 2021-09-28 | AY7: 2021-09-22 | AZ7: 2021-10-13 | BA7: 2021-10-07 | BB7: 2021-10-02 | BC7: 2021-09-25 | BD7: 2021-10-21 | BE7: 2021-10-09 | BF7: 2021-10-09 | BG7: 2021-09-11 | BH7: 2021-10-14 | BI7: 2021-11-20 | BK7: 2021-10-16 | BL7: 2021-10-16 | BM7: 2021-11-04 | BN7: 2021-10-23 | BP7: 2021-12-17 | BQ7: 2021-12-04
A8: 2021-10-09 | B8: 2021-10-30 | C8: 2021-10-08 | D8: 2021-10-09 | E8: 2021-11-02 | F8: 2021-10-16 | G8: 2021-10-01 | H8: 2021-10-28 | I8: 2021-10-14 | J8: 2021-10-18 | K8: 2021-10-07 | L8: 2021-09-11 | M8: 2021-09-25 | N8: 2021-11-05 | O8: 2021-09-25 | P8: 2021-10-02 | Q8: 2021-09-23 | R8: 2021-09-28 | S8: 2021-09-16 | T8: 2021-10-09 | U8: 2021-10-02 | V8: 2021-09-14 | W8: 2021-11-20 | X8: 2021-10-07 | Y8: 2021-11-20 | Z8: 2021-10-23 | AA8: 2021-09-25 | AB8: 2021-10-14 | AC8: 2021-10-23 | AD8: 2021-10-16 | AE8: 2021-10-30 | AF8: 2021-09-23 | AG8: 2021-10-28 | AH8: 2021-11-04 | AI8: 2021-10-17 | AJ8: 2021-10-22 | AK8: 2021-10-26 | AL8: 2021-10-28 | AM8: 2021-10-26 | AN8: 2021-10-02 | AO8: 2021-10-03 | AP8: 2021-10-13 | AQ8: 2021-09-28 | AR8: 2021-10-02 | AS8: 2021-10-21 | AT8: 2021-10-23 | AU8: 2021-09-25 | AV8: 2021-10-16 | AW8: 2021-10-07 | AX8: 2021-10-07 | AY8: 2021-10-07 | AZ8: 2021-10-15 | BB8: 2021-09-22 | BC8: 2021-09-28 | BD8: 2021-10-28 | BE8: 2021-10-16 | BF8: 2021-10-16 | BG8: 2021-10-09 | BH8: 2021-10-17 | BI8: 2021-11-25 | BK8: 2021-10-30 | BL8: 2021-10-14 | BM8: 2021-11-06 | BN8: 2021-10-29 | BP8: 2021-12-30 | BQ8: 2022-01-16
A9: 2021-10-16 | B9: 2021-11-23 | C9: 2021-10-18 | D9: 2021-10-14 | E9: 2021-11-18 | F9: 2021-10-30 | G9: 2021-10-05 | H9: 2021-10-30 | I9: 2021-10-28 | J9: 2021-11-02 | K9: 2021-10-14 | L9: 2021-10-13 | M9: 2021-10-02 | N9: 2021-11-06 | O9: 2021-10-02 | P9: 2021-10-21 | Q9: 2021-10-07 | R9: 2021-10-07 | S9: 2021-10-21 | T9: 2021-10-21 | U9: 2021-10-08 | V9: 2021-10-07 | W9: 2021-11-27 | X9: 2021-10-09 | Y9: 2022-01-04 | Z9: 2021-11-06 | AA9: 2021-09-14 | AB9: 2021-10-22 | AC9: 2021-11-05 | AD9: 2021-10-23 | AE9: 2021-11-06 | AF9: 2021-09-28 | AG9: 2021-11-04 | AH9: 2021-11-06 | AI9: 2021-10-21 | AJ9: 2021-10-30 | AK9: 2021-11-05 | AL9: 2021-11-20 | AM9: 2021-11-05 | AN9: 2021-10-03 | AO9: 2021-10-23 | AP9: 2021-10-16 | AQ9: 2021-10-05 | AR9: 2021-10-21 | AS9: 2021-10-23 | AT9: 2021-11-05 | AU9: 2021-09-28 | AV9: 2021-11-04 | AW9: 2021-10-14 | AX9: 2021-11-02 | AY9: 2021-10-14 | AZ9: 2021-10-21 | BB9: 2021-10-07 | BC9: 2021-10-07 | BD9: 2021-11-04 | BE9: 2021-10-28 | BF9: 2021-10-21 | BG9: 2021-10-17 | BH9: 2021-10-21 | BI9: 2021-12-02 | BK9: 2021-11-04 | BL9: 2021-10-28 | BM9: 2021-11-16 | BN9: 2021-11-11 | BQ9: 2022-02-26
A10: 2021-10-30 | B10: 2021-12-02 | C10: 2021-11-06 | D10: 2021-10-30 | E10: 2021-12-04 | F10: 2021-11-18 | G10: 2021-10-14 | H10: 2021-11-06 | I10: 2021-11-06 | J10: 2021-11-23 | K10: 2021-10-22 | L10: 2021-10-15 | M10: 2021-09-22 | N10: 2021-11-19 | O10: 2021-10-07 | P10: 2021-10-09 | Q10: 2021-10-14 | R10: 2021-10-09 | S10: 2021-10-02 | T10: 2021-10-23 | U10: 2021-10-14 | V10: 2021-10-21 | W10: 2021-12-10 | X10: 2021-10-16 | Y10: 2022-01-22 | Z10: 2022-02-26 | AA10: 2021-09-28 | AB10: 2021-11-20 | AC10: 2021-11-06 | AD10: 2021-10-28 | AE10: 2021-11-20 | AF10: 2021-10-02 | AG10: 2021-10-16 | AH10: 2021-11-18 | AI10: 2021-11-27 | AJ10: 2021-11-25 | AK10: 2021-11-06 | AL10: 2021-11-25 | AM10: 2021-11-06 | AN10: 2021-10-09 | AO10: 2021-11-20 | AP10: 2021-10-23 | AQ10: 2021-10-16 | AR10: 2021-10-23 | AS10: 2021-10-28 | AT10: 2021-11-06 | AU10: 2021-10-02 | AV10: 2021-11-18 | AW10: 2021-10-17 | AX10: 2021-10-21 | AY10: 2021-10-21 | AZ10: 2021-10-23 | BB10: 2021-10-14 | BC10: 2021-10-09 | BD10: 2021-11-25 | BE10: 2021-10-30 | BF10: 2021-10-28 | BG10: 2021-10-23 | BH10: 2021-11-02 | BI10: 2021-12-09 | BK10: 2021-10-21 | BL10: 2021-10-30 | BM10: 2021-11-25 | BN10: 2021-11-27 | BQ10: 2022-03-03
A11: 2021-11-25 | C11: 2021-11-23 | D11: 2021-11-06 | E11: 2021-12-11 | F11: 2021-12-02 | G11: 2021-10-02 | H11: 2021-11-18 | I11: 2021-11-18 | J11: 2021-12-04 | K11: 2021-10-30 | L11: 2021-10-23 | M11: 2021-09-28 | N11: 2021-11-23 | O11: 2021-10-09 | P11: 2021-10-27 | Q11: 2021-10-17 | R11: 2021-10-16 | S11: 2021-10-28 | T11: 2021-11-02 | U11: 2021-10-16 | V11: 2021-10-23 | W11: 2021-12-28 | X11: 2021-10-21 | Y11: 2022-01-29 | Z11: 2022-03-05 | AA11: 2021-10-07 | AB11: 2021-11-27 | AC11: 2021-11-20 | AD11: 2021-11-04 | AE11: 2021-11-25 | AF11: 2021-10-03 | AG11: 2021-11-19 | AH11: 2021-11-23 | AI11: 2021-11-13 | AJ11: 2022-01-08 | AK11: 2021-11-13 | AL11: 2021-12-02 | AM11: 2021-11-13 | AN11: 2021-10-14 | AO11: 2021-11-27 | AP11: 2021-10-27 | AQ11: 2021-10-22 | AR11: 2021-10-16 | AS11: 2021-10-30 | AT11: 2021-11-19 | AU11: 2021-10-07 | AV11: 2021-11-27 | AW11: 2021-10-21 | AX11: 2021-11-16 | AY11: 2021-11-02 | AZ11: 2021-11-04 | BB11: 2021-10-23 | BC11: 2021-10-21 | BD11: 2021-12-11 | BE11: 2021-11-23 | BF11: 2021-10-30 | BG11: 2021-10-30 | BH11: 2021-11-06 | BI11: 2021-12-11 | BK11: 2021-11-18 | BL11: 2021-11-19 | BM11: 2021-11-27 | BN11: 2021-12-04
A12: 2021-12-04 | C12: 2021-12-05 | D12: 2021-11-20 | E12: 2021-12-16 | F12: 2021-12-11 | G12: 2021-11-23 | H12: 2021-11-27 | I12: 2021-11-25 | J12: 2021-12-11 | K12: 2021-11-06 | L12: 2021-11-04 | M12: 2021-10-07 | N12: 2021-11-27 | O12: 2021-10-16 | P12: 2021-11-06 | Q12: 2021-10-23 | R12: 2021-10-29 | S12: 2021-11-06 | T12: 2021-11-13 | U12: 2021-10-23 | V12: 2021-10-27 | W12: 2021-12-26 | X12: 2021-10-28 | Y12: 2022-02-26 | AA12: 2021-10-14 | AB12: 2021-12-04 | AC12: 2021-11-26 | AD12: 2021-11-06 | AE12: 2021-12-02 | AF12: 2021-09-28 | AG12: 2021-11-23 | AH12: 2021-11-13 | AI12: 2021-12-20 | AJ12: 2021-12-22 | AK12: 2021-11-26 | AL12: 2021-12-07 | AM12: 2021-11-26 | AN12: 2021-10-21 | AO12: 2022-01-07 | AP12: 2021-10-28 | AQ12: 2021-10-28 | AR12: 2021-10-28 | AS12: 2021-11-06 | AT12: 2021-11-27 | AU12: 2021-10-14 | AV12: 2021-12-02 | AW12: 2021-10-30 | AX12: 2021-11-20 | AY12: 2021-11-06 | AZ12: 2021-11-18 | BB12: 2021-09-28 | BC12: 2021-10-26 | BD12: 2021-12-09 | BE12: 2021-11-26 | BF12: 2021-12-02 | BG12: 2021-11-06 | BH12: 2021-11-20 | BI12: 2021-12-28 | BK12: 2021-11-20 | BL12: 2021-11-26 | BM12: 2021-12-08 | BN12: 2021-12-11
A13: 2021-12-11 | C13: 2021-12-11 | D13: 2021-11-27 | E13: 2021-12-30 | F13: 2021-12-30 | G13: 2021-10-30 | H13: 2021-12-04 | I13: 2021-12-02 | J13: 2021-12-16 | K13: 2021-11-20 | L13: 2021-11-23 | M13: 2021-10-14 | N13: 2021-12-28 | O13: 2021-10-27 | P13: 2021-11-26 | Q13: 2021-10-30 | R13: 2021-10-30 | S13: 2021-11-13 | T13: 2021-12-04 | U13: 2021-09-28 | V13: 2021-11-05 | W13: 2022-01-29 | X13: 2021-11-04 | Y13: 2022-03-05 | AA13: 2021-10-21 | AB13: 2021-11-26 | AC13: 2021-11-23 | AD13: 2021-11-18 | AE13: 2021-12-30 | AF13: 2021-10-09 | AG13: 2021-12-02 | AH13: 2021-11-27 | AI13: 2021-12-11 | AJ13: 2022-01-22 | AK13: 2021-12-04 | AL13: 2021-12-09 | AM13: 2021-11-27 | AN13: 2021-10-23 | AO13: 2022-02-17 | AP13: 2021-11-04 | AQ13: 2021-10-30 | AR13: 2021-11-05 | AS13: 2021-11-16 | AT13: 2021-12-04 | AU13: 2021-10-21 | AV13: 2021-12-04 | AW13: 2021-11-06 | AX13: 2021-12-02 | AY13: 2021-11-20 | AZ13: 2021-11-23 | BB13: 2021-11-02 | BC13: 2021-11-04 | BD13: 2021-12-26 | BE13: 2021-12-02 | BF13: 2021-12-20 | BG13: 2021-12-04 | BH13: 2021-11-25 | BI13: 2022-01-20 | BK13: 2021-11-27 | BL13: 2021-12-04 | BM13: 2021-12-11 | BN13: 2021-12-27
A14: 2021-12-30 | C14: 2021-12-23 | D14: 2021-12-05 | E14: 2022-01-20 | F14: 2022-01-22 | G14: 2021-12-05 | H14: 2021-12-11 | I14: 2021-12-04 | J14: 2022-01-29 | K14: 2021-11-27 | L14: 2021-11-27 | M14: 2021-10-16 | N14: 2021-12-22 | O14: 2021-11-06 | P14: 2021-12-02 | Q14: 2021-11-04 | R14: 2021-11-18 | S14: 2021-12-08 | T14: 2021-11-04 | U14: 2021-10-28 | V14: 2021-11-11 | W14: 2022-02-03 | X14: 2021-11-20 | AA14: 2021-10-30 | AB14: 2021-12-11 | AC14: 2021-12-11 | AD14: 2021-11-20 | AE14: 2021-12-17 | AF14: 2021-10-09 | AG14: 2021-11-20 | AH14: 2021-12-21 | AI14: 2021-12-27 | AJ14: 2022-02-25 | AK14: 2021-12-11 | AL14: 2021-12-26 | AM14: 2021-12-04 | AN14: 2021-10-29 | AP14: 2021-11-06 | AQ14: 2021-11-04 | AR14: 2021-11-11 | AS14: 2021-11-20 | AT14: 2021-12-11 | AU14: 2021-10-23 | AV14: 2021-12-09 | AW14: 2021-11-20 | AX14: 2021-12-04 | AY14: 2021-11-23 | AZ14: 2021-12-07 | BB14: 2021-11-18 | BC14: 2021-11-18 | BD14: 2021-12-15 | BE14: 2021-11-27 | BF14: 2022-01-06 | BG14: 2021-12-23 | BH14: 2021-12-02 | BI14: 2022-01-22 | BK14: 2021-11-23 | BL14: 2021-12-28 | BM14: 2021-12-29 | BN14: 2021-12-30
A15: 2022-01-06 | C15: 2022-01-22 | D15: 2021-12-21 | E15: 2022-01-27 | F15: 2022-01-29 | G15: 2021-12-30 | H15: 2022-01-20 | I15: 2021-12-05 | J15: 2022-02-05 | K15: 2021-12-11 | L15: 2021-12-09 | M15: 2021-10-21 | N15: 2022-01-20 | O15: 2021-11-11 | P15: 2021-12-01 | Q15: 2021-11-18 | R15: 2021-11-25 | S15: 2021-12-15 | T15: 2021-12-11 | U15: 2021-11-06 | V15: 2021-11-20 | W15: 2022-02-05 | X15: 2021-11-23 | AA15: 2021-11-06 | AB15: 2021-12-28 | AC15: 2022-01-06 | AD15: 2021-11-27 | AE15: 2022-01-28 | AF15: 2021-10-13 | AG15: 2021-12-10 | AH15: 2022-01-20 | AI15: 2021-12-28 | AJ15: 2022-03-05 | AK15: 2021-12-09 | AL15: 2021-12-15 | AM15: 2021-12-11 | AN15: 2021-11-02 | AP15: 2021-11-11 | AQ15: 2021-11-16 | AR15: 2021-11-18 | AS15: 2021-11-25 | AT15: 2021-12-28 | AU15: 2021-10-30 | AV15: 2021-12-11 | AW15: 2021-11-25 | AX15: 2021-12-09 | AY15: 2021-11-27 | AZ15: 2021-12-11 | BB15: 2021-11-25 | BC15: 2021-11-20 | BD15: 2021-12-28 | BE15: 2021-12-21 | BF15: 2022-01-08 | BG15: 2021-12-17 | BH15: 2021-12-04 | BI15: 2022-01-02 | BK15: 2021-12-10 | BL15: 2022-01-06 | BM15: 2022-01-05 | BN15: 2022-01-08
A16: 2022-01-27 | C16: 2022-02-03 | D16: 2021-12-30 | E16: 2022-02-03 | F16: 2022-02-17 | G16: 2022-01-07 | H16: 2022-01-22 | I16: 2021-12-21 | J16: 2022-02-26 | K16: 2021-12-28 | L16: 2022-01-20 | M16: 2021-10-23 | N16: 2022-01-22 | O16: 2021-11-25 | P16: 2021-12-08 | Q16: 2021-11-20 | R16: 2021-11-27 | S16: 2021-12-28 | T16: 2021-12-20 | U16: 2021-11-25 | V16: 2021-11-26 | W16: 2022-02-25 | X16: 2021-12-28 | AA16: 2021-11-18 | AB16: 2021-12-22 | AC16: 2022-01-20 | AD16: 2021-12-02 | AE16: 2022-02-03 | AF16: 2021-10-16 | AG16: 2021-12-30 | AH16: 2022-01-16 | AI16: 2022-01-22 | AK16: 2022-01-04 | AL16: 2021-12-28 | AM16: 2021-12-26 | AN16: 2021-11-06 | AP16: 2021-11-18 | AQ16: 2021-11-25 | AR16: 2021-11-25 | AS16: 2021-12-02 | AT16: 2022-01-06 | AU16: 2021-11-04 | AV16: 2021-12-18 | AW16: 2021-12-04 | AX16: 2021-12-11 | AY16: 2021-12-04 | AZ16: 2021-12-18 | BB16: 2021-12-02 | BC16: 2021-11-25 | BD16: 2022-01-22 | BE16: 2022-01-02 | BF16: 2022-01-20 | BG16: 2021-12-28 | BH16: 2021-12-09 | BI16: 2022-01-27 | BK16: 2021-12-15 | BL16: 2022-01-08 | BM16: 2022-01-09 | BN16: 2022-01-18
A17: 2022-02-05 | C17: 2022-02-24 | D17: 2022-01-07 | E17: 2022-02-19 | F17: 2022-02-26 | G17: 2022-01-22 | H17: 2022-01-27 | I17: 2022-02-03 | J17: 2022-03-03 | K17: 2022-01-20 | L17: 2022-01-22 | M17: 2021-10-28 | N17: 2022-01-08 | O17: 2021-11-27 | P17: 2021-12-23 | Q17: 2021-11-27 | R17: 2021-12-02 | S17: 2021-12-30 | T17: 2021-12-30 | U17: 2021-11-18 | V17: 2021-12-04 | W17: 2022-03-10 | X17: 2022-01-20 | AA17: 2021-11-27 | AB17: 2022-01-22 | AC17: 2022-01-29 | AD17: 2021-11-23 | AE17: 2022-02-17 | AF17: 2021-10-16 | AG17: 2022-01-08 | AH17: 2022-02-17 | AI17: 2022-01-09 | AK17: 2022-01-27 | AL17: 2022-01-02 | AM17: 2021-12-09 | AN17: 2021-11-13 | AP17: 2021-11-27 | AQ17: 2021-12-02 | AR17: 2021-12-01 | AS17: 2021-12-10 | AT17: 2022-01-08 | AU17: 2021-11-18 | AV17: 2021-12-28 | AW17: 2021-12-09 | AX17: 2021-12-23 | AY17: 2021-12-09 | AZ17: 2021-12-17 | BB17: 2021-12-04 | BC17: 2021-12-09 | BD17: 2022-01-02 | BE17: 2022-01-18 | BF17: 2022-01-29 | BG17: 2022-01-04 | BH17: 2021-12-15 | BI17: 2022-01-29 | BK17: 2021-12-23 | BL17: 2022-01-20 | BM17: 2022-01-16 | BN17: 2022-01-22
A18: 2022-02-19 | C18: 2022-03-08 | D18: 2022-01-22 | E18: 2022-02-24 | F18: 2022-03-05 | G18: 2022-01-29 | H18: 2022-01-29 | I18: 2022-02-17 | K18: 2022-01-28 | L18: 2022-01-15 | M18: 2021-11-04 | N18: 2022-02-26 | O18: 2021-12-01 | P18: 2021-12-26 | Q18: 2021-12-04 | R18: 2021-11-23 | S18: 2021-12-30 | T18: 2022-01-08 | U18: 2021-12-27 | V18: 2021-11-18 | W18: 2022-03-15 | X18: 2022-01-15 | AA18: 2021-12-02 | AB18: 2022-01-29 | AC18: 2022-02-05 | AD18: 2021-12-23 | AE18: 2022-02-05 | AF18: 2021-10-21 | AG18: 2022-01-22 | AH18: 2022-02-24 | AI18: 2022-01-29 | AK18: 2022-02-03 | AL18: 2021-12-11 | AM18: 2021-12-23 | AN18: 2021-11-27 | AP18: 2021-12-04 | AQ18: 2021-11-18 | AR18: 2021-12-02 | AS18: 2021-12-20 | AT18: 2021-12-22 | AU18: 2021-11-25 | AV18: 2021-12-26 | AW18: 2021-12-21 | AX18: 2022-01-02 | AY18: 2021-12-26 | AZ18: 2022-01-11 | BB18: 2021-12-09 | BC18: 2021-12-11 | BD18: 2022-01-20 | BE18: 2022-02-03 | BF18: 2022-02-03 | BG18: 2022-01-02 | BH18: 2021-12-28 | BI18: 2022-02-17 | BK18: 2021-12-28 | BL18: 2022-01-29 | BM18: 2022-01-12 | BN18: 2022-01-09
A19: 2022-02-26 | C19: 2022-03-10 | D19: 2022-01-29 | E19: 2022-03-05 | G19: 2022-02-17 | H19: 2022-02-03 | I19: 2022-02-05 | K19: 2022-02-05 | L19: 2022-01-18 | M19: 2021-11-06 | N19: 2022-03-03 | O19: 2021-12-28 | P19: 2021-12-30 | Q19: 2021-12-09 | R19: 2021-11-04 | S19: 2021-12-11 | T19: 2022-01-18 | U19: 2021-12-30 | V19: 2021-12-10 | W19: 2022-03-17 | X19: 2022-02-03 | AA19: 2021-12-07 | AB19: 2022-01-28 | AC19: 2022-01-28 | AD19: 2022-01-02 | AE19: 2022-03-05 | AF19: 2021-10-23 | AG19: 2022-02-05 | AH19: 2022-03-05 | AI19: 2022-02-05 | AK19: 2022-02-17 | AL19: 2022-01-20 | AM19: 2022-01-29 | AN19: 2022-01-07 | AP19: 2021-12-15 | AQ19: 2021-12-10 | AR19: 2021-12-23 | AS19: 2022-01-06 | AT19: 2022-01-22 | AU19: 2021-11-27 | AV19: 2022-01-20 | AW19: 2021-12-18 | AX19: 2022-01-20 | AY19: 2022-01-11 | AZ19: 2022-01-22 | BB19: 2021-12-28 | BC19: 2022-01-02 | BD19: 2022-01-27 | BE19: 2022-02-26 | BF19: 2022-02-17 | BG19: 2022-01-29 | BH19: 2022-01-20 | BI19: 2022-02-12 | BK19: 2022-01-29 | BL19: 2022-02-17 | BM19: 2022-01-13 | BN19: 2022-01-29
A20: 2022-03-03 | C20: 2022-03-15 | D20: 2022-02-17 | G20: 2022-02-24 | H20: 2022-02-26 | I20: 2022-02-24 | K20: 2022-02-26 | L20: 2022-01-29 | M20: 2021-11-18 | N20: 2022-03-15 | O20: 2022-01-05 | P20: 2022-01-05 | Q20: 2021-12-28 | R20: 2021-12-10 | S20: 2022-01-02 | T20: 2022-01-27 | U20: 2022-01-22 | V20: 2021-12-11 | W20: 2022-03-22 | X20: 2022-02-17 | AA20: 2021-12-09 | AB20: 2022-02-05 | AC20: 2022-02-24 | AD20: 2022-01-22 | AF20: 2021-10-23 | AG20: 2022-02-19 | AI20: 2022-02-09 | AK20: 2022-02-19 | AL20: 2022-01-27 | AM20: 2022-02-03 | AN20: 2022-01-18 | AP20: 2022-01-02 | AQ20: 2021-12-21 | AR20: 2021-12-15 | AS20: 2022-01-20 | AT20: zbrisano | AU20: 2021-12-09 | AV20: 2022-01-22 | AW20: 2021-12-26 | AX20: 2022-01-22 | AY20: 2022-01-02 | AZ20: 2022-01-20 | BB20: 2022-01-18 | BC20: 2021-12-21 | BD20: 2022-02-19 | BE20: 2022-03-05 | BF20: 2022-02-25 | BG20: 2022-02-18 | BH20: 2022-01-22 | BI20: 2022-02-24 | BK20: 2022-02-03 | BL20: 2022-02-24 | BM20: 2022-01-26 | BN20: 2022-02-19
C21: 2022-03-17 | D21: 2022-02-05 | G21: 2022-03-08 | H21: 2022-02-24 | I21: 2022-02-19 | K21: 2022-03-03 | L21: 2022-02-05 | M21: 2021-11-25 | N21: 2022-03-17 | O21: 2022-01-20 | P21: 2022-01-22 | Q21: 2021-12-16 | R21: 2021-12-23 | S21: 2022-01-08 | T21: 2022-01-29 | U21: 2022-01-29 | V21: 2021-12-02 | W21: 2022-03-24 | X21: 2022-02-19 | AA21: 2021-12-15 | AB21: 2022-02-17 | AD21: 2022-01-29 | AF21: 2021-10-28 | AG21: 2022-02-26 | AI21: 2022-02-19 | AK21: 2022-02-26 | AL21: 2022-02-03 | AM21: 2022-02-17 | AN21: 2022-01-27 | AP21: 2021-12-23 | AQ21: 2021-12-27 | AR21: 2021-12-30 | AS21: 2022-01-22 | AT21: 2022-01-29 | AU21: 2021-12-11 | AV21: 2022-01-27 | AW21: zbrisano | AX21: 2022-01-27 | AY21: zbrisano | AZ21: 2022-01-27 | BB21: 2022-01-27 | BC21: 2021-12-30 | BD21: 2022-02-17 | BF21: 2022-03-05 | BG21: 2022-02-12 | BH21: 2022-01-27 | BI21: 2022-03-03 | BK21: 2022-02-05 | BL21: 2022-02-26 | BM21: 2022-01-29
C22: 2022-03-24 | D22: 2022-02-24 | G22: 2022-03-10 | H22: 2022-03-10 | I22: 2022-03-03 | K22: 2022-03-08 | L22: 2022-02-19 | M22: 2021-12-02 | N22: 2022-03-19 | O22: 2022-01-18 | P22: 2022-01-08 | Q22: 2022-01-04 | R22: 2021-12-28 | S22: 2022-01-12 | T22: 2022-02-09 | U22: 2022-01-27 | V22: 2021-12-28 | W22: 2022-03-29 | X22: 2022-02-26 | AA22: 2022-01-11 | AB22: 2022-02-25 | AD22: 2022-02-05 | AF22: 2021-11-04 | AG22: 2022-03-05 | AI22: 2022-02-26 | AK22: 2022-03-05 | AL22: 2022-02-18 | AM22: 2022-02-19 | AN22: 2022-02-03 | AP22: 2022-01-22 | AQ22: 2022-01-16 | AR22: 2022-01-20 | AS22: 2022-01-29 | AT22: 2022-02-03 | AU22: 2021-12-23 | AV22: 2022-01-29 | AW22: 2022-02-19 | AX22: 2022-01-29 | AY22: 2022-01-27 | AZ22: 2022-02-03 | BB22: 2022-02-03 | BC22: 2022-01-22 | BD22: 2022-02-24 | BG22: 2022-02-26 | BH22: 2022-02-03 | BK22: 2022-02-16 | BM22: 2022-02-05
C23: 2022-03-29 | D23: 2022-03-03 | G23: 2022-03-15 | H23: 2022-03-12 | I23: 2022-03-08 | K23: 2022-03-15 | L23: 2022-02-24 | M23: 2021-11-27 | N23: 2022-03-31 | O23: 2022-01-12 | P23: 2022-01-18 | Q23: 2022-01-20 | R23: 2022-01-06 | S23: 2022-01-12 | T23: 2022-03-03 | U23: 2022-02-19 | V23: 2022-01-08 | W23: 2022-04-02 | X23: 2022-03-19 | AA23: 2022-01-02 | AD23: 2022-02-19 | AF23: 2021-11-05 | AI23: 2022-02-17 | AL23: 2022-02-24 | AM23: 2022-02-26 | AN23: 2022-02-05 | AP23: 2022-01-08 | AQ23: 2022-02-03 | AR23: 2022-01-18 | AS23: 2022-02-05 | AT23: 2022-02-17 | AU23: 2021-12-16 | AV23: 2022-02-03 | AW23: 2022-02-05 | AX23: 2022-02-03 | AY23: 2022-02-03 | AZ23: 2022-02-19 | BB23: 2022-02-17 | BC23: 2022-01-27 | BD23: 2022-03-03 | BG23: 2022-03-03 | BH23: 2022-02-19 | BK23: 2022-02-24 | BM23: 2022-02-16
D24: 2022-03-05 | G24: 2022-03-17 | I24: 2022-03-10 | K24: 2022-03-17 | L24: 2022-02-26 | M24: 2021-12-07 | N24: 2022-04-12 | O24: 2022-01-27 | P24: 2022-01-29 | Q24: 2022-01-15 | R24: 2022-01-09 | S24: 2022-01-13 | T24: 2022-03-22 | U24: 2022-02-17 | V24: 2022-01-13 | W24: 2022-04-12 | X24: 2022-03-26 | AA24: 2021-12-29 | AD24: 2022-02-26 | AF24: 2021-11-06 | AI24: 2022-02-24 | AL24: 2022-03-05 | AM24: 2022-03-05 | AN24: 2022-02-09 | AP24: 2022-01-27 | AQ24: 2022-02-19 | AR24: 2022-01-27 | AS24: 2022-02-17 | AT24: 2022-02-24 | AU24: 2021-12-28 | AV24: 2022-02-05 | AW24: 2022-02-24 | AX24: 2022-02-05 | AY24: 2022-02-19 | AZ24: 2022-02-12 | BB24: 2022-02-24 | BC24: 2022-01-29 | BG24: 2022-03-19 | BH24: 2022-03-03 | BK24: 2022-02-26 | BM24: 2022-02-19
D25: 2022-03-08 | G25: 2022-03-19 | I25: 2022-03-15 | K25: 2022-03-19 | L25: 2022-03-03 | M25: 2021-12-11 | N25: 2022-04-19 | O25: 2022-02-03 | P25: 2022-01-27 | Q25: 2022-01-27 | R25: 2022-02-19 | S25: 2022-01-18 | U25: 2022-03-03 | V25: 2022-01-26 | X25: 2022-04-02 | AA25: 2021-12-26 | AD25: 2022-03-05 | AF25: 2021-11-06 | AN25: 2022-02-24 | AP25: 2022-02-03 | AQ25: 2022-02-26 | AR25: 2022-02-03 | AS25: 2022-02-26 | AT25: 2022-03-05 | AU25: 2021-12-26 | AV25: 2022-02-17 | AW25: 2022-03-03 | AX25: 2022-02-26 | AY25: 2022-02-12 | AZ25: 2022-03-03 | BB25: 2022-03-03 | BC25: 2022-02-19 | BM25: 2022-02-26
D26: 2022-03-10 | G26: 2022-03-24 | I26: 2022-03-17 | K26: 2022-03-31 | L26: 2022-03-05 | M26: 2022-01-11 | O26: 2022-02-05 | P26: 2022-02-03 | Q26: 2022-02-03 | R26: 2022-02-24 | S26: 2022-01-22 | U26: 2022-03-05 | V26: 2022-01-29 | AA26: 2022-01-20 | AD26: 2022-03-08 | AF26: 2021-10-17 | AN26: 2022-02-26 | AP26: 2022-02-05 | AQ26: 2022-03-05 | AR26: 2022-02-05 | AS26: 2022-02-19 | AT26: 2022-03-08 | AU26: 2022-01-18 | AV26: 2022-02-26 | AW26: 2022-03-10 | AX26: 2022-02-18 | BB26: 2022-03-05 | BC26: 2022-02-26 | BM26: 2022-03-03
D27: 2022-03-12 | G27: 2022-03-29 | I27: 2022-03-19 | K27: 2022-04-09 | L27: 2022-03-08 | M27: 2021-12-28 | O27: 2022-02-19 | P27: 2022-02-19 | Q27: 2022-02-05 | R27: 2022-03-15 | S27: 2022-01-26 | U27: 2022-03-08 | V27: 2022-02-05 | AA27: 2022-01-29 | AF27: 2021-11-11 | AN27: 2022-03-03 | AP27: 2022-02-19 | AR27: 2022-02-12 | AS27: 2022-03-03 | AT27: 2022-03-22 | AU27: 2022-01-15 | AV27: 2022-03-05 | AW27: 2022-03-17 | AX27: 2022-03-05 | BC27: 2022-03-03 | BM27: 2022-03-05
D28: 2022-03-15 | G28: 2022-03-31 | I28: 2022-03-22 | K28: 2022-04-19 | L28: 2022-03-10 | M28: 2021-12-18 | O28: 2022-02-16 | P28: 2022-02-26 | Q28: 2022-02-18 | R28: 2022-03-17 | S28: 2022-01-26 | U28: 2022-03-17 | V28: 2022-02-12 | AA28: 2022-02-03 | AF28: 2021-11-18 | AN28: 2022-03-08 | AP28: 2022-02-24 | AR28: 2022-02-19 | AU28: 2022-01-20 | AV28: 2022-03-03 | AW28: 2022-03-24
D29: 2022-03-17 | I29: 2022-03-26 | L29: 2022-03-15 | M29: 2021-12-26 | O29: 2022-02-24 | P29: 2022-03-08 | Q29: 2022-02-24 | R29: 2022-03-22 | S29: 2022-02-03 | U29: 2022-03-19 | V29: 2022-02-24 | AA29: 2022-02-26 | AF29: 2021-11-18 | AP29: 2022-02-16 | AR29: 2022-02-26 | AU29: 2022-01-27
D30: 2022-03-19 | I30: 2022-03-31 | L30: 2022-03-17 | M30: 2021-12-29 | O30: 2022-03-03 | P30: 2022-03-10 | Q30: 2022-03-03 | R30: 2022-03-24 | S30: 2022-02-12 | U30: 2022-03-22 | V30: 2022-03-03 | AA30: 2022-03-03 | AF30: 2021-11-20 | AP30: 2022-03-03 | AR30: 2022-03-05 | AU30: 2022-02-03
D31: 2022-03-22 | I31: 2022-04-12 | L31: 2022-03-19 | M31: 2022-01-29 | O31: 2022-03-08 | P31: 2022-03-15 | Q31: 2022-03-08 | S31: 2022-02-12 | U31: 2022-03-29 | V31: 2022-03-10 | AA31: 2022-03-05 | AF31: 2021-11-20 | AR31: 2022-03-08 | AU31: 2022-02-17
D32: 2022-03-26 | I32: 2022-04-16 | L32: 2022-03-22 | M32: 2022-02-03 | O32: 2022-03-10 | P32: 2022-03-17 | Q32: 2022-03-12 | S32: 2022-02-17 | U32: 2022-04-02 | V32: 2022-03-12 | AA32: 2022-03-10 | AF32: 2021-12-01 | AR32: 2022-03-10 | AU32: 2022-02-19
D33: 2022-03-31 | L33: 2022-03-24 | M33: 2022-02-05 | O33: 2022-03-15 | P33: 2022-03-19 | Q33: 2022-03-15 | S33: 2022-02-05 | U33: 2022-04-14 | V33: 2022-03-17 | AA33: 2022-03-15 | AF33: 2021-12-02 | AU33: 2022-02-26
D34: 2022-04-12 | L34: 2022-03-26 | M34: 2022-02-19 | O34: 2022-03-17 | P34: 2022-03-24 | Q34: 2022-03-19 | S34: 2022-02-24 | U34: 2022-04-19 | V34: 2022-03-19 | AA34: 2022-03-19 | AF34: 2021-12-04 | AU34: 2022-03-03
L35: 2022-03-31 | M35: 2022-03-03 | O35: 2022-03-19 | P35: 2022-03-29 | Q35: 2022-03-24 | S35: 2022-02-24 | V35: 2022-03-22 | AF35: 2021-12-08
M36: 2022-02-24 | O36: 2022-03-24 | P36: 2022-04-02 | Q36: 2022-03-31 | S36: 2022-03-03 | V36: 2022-04-02 | AF36: 2021-12-10
M37: 2022-03-08 | O37: 2022-03-22 | P37: 2022-04-09 | Q37: 2022-04-14 | S37: 2022-03-05 | V37: 2022-04-09 | AF37: 2021-12-23
M38: 2022-03-10 | O38: 2022-03-29 | Q38: 2022-04-16 | S38: 2022-03-03 | V38: 2022-04-16 | AF38: 2021-12-26
M39: 2022-03-15 | O39: 2022-04-02 | S39: 2022-03-10 | AF39: 2021-12-30
M40: 2022-03-17 | O40: 2022-04-09 | S40: 2022-03-15 | AF40: 2021-12-30
M41: 2022-03-19 | O41: 2022-04-16 | S41: 2022-03-19 | AF41: 2022-01-05
...

Sheet redn
A1: =COUNTIF(A4:A47,"<>") -> 17 | B1: =COUNTIF(B4:B47,"<>") -> 7 | C1: =COUNTIF(C4:C50,"<>") -> 14 | D1: =COUNTIF(D4:D49,"<>") -> 21 | E1: =COUNTIF(E4:E51,"<>") -> 16 | F1: =COUNTIF(F4:F51,"<>") -> 15 | G1: =COUNTIF(G4:G46,"<>") -> 17 | H1: =COUNTIF(H4:H45,"<>") -> 18 | I1: =COUNTIF(I4:I54,"<>") -> 19 | J1: =COUNTIF(J4:J55,"<>") -> 14 | K1: =COUNTIF(K4:K55,"<>") -> 1 | L1: =COUNTIF(L4:L53,"<>") -> 23 | M1: =COUNTIF(M4:M53,"<>") -> 33 | N1: =COUNTIF(N4:N52,"<>") -> 27 | O1: =COUNTIF(O4:O53,"<>") -> 19 | P1: =COUNTIF(P4:P55,"<>") -> 10 | Q1: =COUNTIF(Q4:Q53,"<>") -> 8 | R1: =COUNTIF(R4:R53,"<>") -> 28 | S1: =COUNTIF(S4:S55,"<>") -> 19 | T1: =COUNTIF(T4:T55,"<>") -> 21 | U1: =COUNTIF(U4:U55,"<>") -> 21 | V1: =COUNTIF(V4:V55,"<>") -> 31 | W1: =COUNTIF(W4:W55,"<>") -> 25 | X1: =COUNTIF(X4:X53,"<>") -> 22 | Y1: =COUNTIF(Y4:Y55,"<>") -> 24 | Z1: =COUNTIF(Z4:Z55,"<>") -> 22 | AA1: =COUNTIF(AA4:AA55,"<>") -> 22 | AB1: =COUNTIF(AB4:AB55,"<>") -> 23 | AC1: =COUNTIF(AC4:AC55,"<>") -> 24 | AD1: =COUNTIF(AD4:AD55,"<>") -> 20 | AE1: =COUNTIF(AE4:AE54,"<>") -> 20 | AF1: =COUNTIF(AF4:AF55,"<>") -> 21 | AG1: =COUNTIF(AG4:AG55,"<>") -> 18 | AH1: =COUNTIF(AH4:AH55,"<>") -> 2 | AI1: =COUNTIF(AI4:AI53,"<>") -> 18 | AJ1: =COUNTIF(AJ4:AJ53,"<>") -> 16 | AK1: =COUNTIF(AK4:AK54,"<>") -> 27 | AL1: =COUNTIF(AL4:AL49,"<>") -> 25 | AM1: =COUNTIF(AM4:AM54,"<>") -> 23 | AN1: =COUNTIF(AN4:AN50,"<>") -> 35 | AO1: =COUNTIF(AO4:AO54,"<>") -> 20 | AP1: =COUNTIF(AP4:AP55,"<>") -> 23 | AQ1: =COUNTIF(AQ4:AQ54,"<>") -> 27 | AR1: =COUNTIF(AR4:AR54,"<>") -> 13 | AS1: =COUNTIF(AS4:AS54,"<>") -> 19 | AT1: =COUNTIF(AT4:AT52,"<>") -> 17 | AU1: =COUNTIF(AU4:AU55,"<>") -> 22 | AV1: =COUNTIF(AV4:AV53,"<>") -> 16 | AW1: =COUNTIF(AW4:AW47,"<>") -> 44 | AX1: =COUNTIF(AX4:AX54,"<>") -> 19 | AY1: =COUNTIF(AY4:AY53,"<>") -> 16 | AZ1: =COUNTIF(AZ4:AZ54,"<>") -> 21 | BA1: =COUNTIF(BA4:BA54,"<>") -> 12 | BB1: =COUNTIF(BB4:BB55,"<>") -> 24 | BC1: =COUNTIF(BC4:BC54,"<>") -> 10 | BD1: =COUNTIF(BD4:BD55,"<>") -> 27 | BE1: =COUNTIF(BE4:BE55,"<>") -> 23 | BF1: =COUNTIF(BF4:BF53,"<>") -> 27 | BG1: =COUNTIF(BG4:BG54,"<>") -> 24 | BH1: =COUNTIF(BH4:BH55,"<>") -> 22 | BI1: =COUNTIF(BI4:BI55,"<>") -> 4 | BJ1: =COUNTIF(BJ4:BJ55,"<>") -> 17 | BK1: =COUNTIF(BK4:BK55,"<>") -> 18 | BL1: =COUNTIF(BL4:BL55,"<>") -> 21 | BM1: =COUNTIF(BM4:BM54,"<>") -> 18 | BN1: =COUNTIF(BN4:BN54,"<>") -> 24 | BO1: =COUNTIF(BO4:BO55,"<>") -> 17 | BP1: =COUNTIF(BP4:BP55,"<>") -> 2 | BQ1: =COUNTIF(BQ4:BQ55,"<>") -> 5 | BR1: =COUNTIF(BR4:BR55,"<>") -> 7 | BS1: =COUNTIF(BS4:BS55,"<>") -> 3 | BT1: =COUNTIF(BT4:BT55,"<>") -> 1 | BU1: =COUNTIF(BU4:BU55,"<>") -> 1 | BV1: =COUNTIF(BV4:BV55,"<>") -> 1
A2: sl | B2: sl | C2: sl | D2: sl | E2: sl | F2: sl | G2: sl | H2: sl | I2: sl | J2: sl | K2: sl | L2: it | M2: it | N2: it | O2: it | P2: it | Q2: it | R2: it | S2: it | T2: it | U2: it | V2: it | W2: it | X2: it | Y2: it | Z2: it | AA2: it | AB2: it | AC2: it | AD2: it | AE2: it | AF2: it | AG2: it | AH2: it | AI2: au | AJ2: au | AK2: au | AL2: au | AM2: au | AN2: au | AO2: au | AP2: au | AQ2: au | AR2: au | AS2: au | AT2: au | AU2: au | AV2: au | AW2: au | AX2: au | AY2: au | AZ2: au | BA2: au | BB2: au | BC2: au | BD2: au | BE2: au | BF2: au | BG2: au | BH2: au | BI2: au | BJ2: au | BK2: au | BL2: au | BM2: au | BN2: au | BO2: au | BP2: au | BQ2: au | BR2: au | BS2: au | BT2: au | BU2: au | BV2: au
A3: FAJDIGA | B3: GROZNIK | C3: REZEK | D3: BAJT | E3: PAHOR | F3: LESNIAK | G3: SNOJ | H3: BERGANT | I3: ARLIC | J3: JAVORNIK | K3: Milovanovic | L3: LAZZERI | M3: MOSCHEN | N3: DE ZORDO | O3: MANTOVANI | P3: BASSO | Q3: RIGONI | R3: CRISTELI | S3: LEGA | T3: SORAPERRA | U3: BASSANI | V3: BENVEGNU | W3: PINIE | X3: FLEISCHMANN | Y3: PIRAS | Z3: GIACOMOZZI | AA3: DA PIAN | AB3: BEDANA | AC3: EGGER | AD3: BRONDI | AE3: VIRTA | AF3: STEFENELLI | AG3: PACE | AH3: RICCO | AI3: WEISS | AJ3: HLAVATY | AK3: RUETZ | AL3: EISL | AM3: KAINBERGER | AN3: HUBER | AO3: MOIDL | AP3: PUFF | AQ3: SCHAUER | AR3: WIMMLER | AS3: LOICHT | AT3: LEGAT | AU3: OREL | AV3: PODLESNIK | AW3: HOLZER | AX3: SCHWEIGHOFER | AY3: KUMMER | AZ3: MATTHEY | BA3: SCHONAKLENER | BB3: BRUNNER | BC3: REISINGER | BD3: SPIEGEL | BE3: WUNTSCHEK | BF3: RINKER | BG3: HEINRICHER | BH3: VOICAN | BI3: MARTIN | BJ3: PÖTSCHER | BK3: DURCHNER | BL3: WALLNER | BM3: WIDMANN | BN3: TSCHREPITSCH | BO3: LEHNER | BP3: SEEWALD | BQ3: TELESKLAV | BR3: MÜLLER | BS3: WUCHERER | BT3: BEDYNEK | BU3: NOTHEGGER | BV3: KANYO
A4: 2021-09-11 | B4: 2021-09-18 | C4: 2021-09-18 | D4: 2021-09-16 | E4: 2021-09-23 | F4: 2021-09-11 | G4: 2021-09-11 | H4: 2021-09-23 | I4: 2021-09-11 | J4: 2021-09-18 | K4: 2021-12-30 | L4: 2021-09-16 | M4: 2021-09-14 | N4: 2021-09-11 | O4: 2021-09-16 | P4: 2021-09-18 | Q4: 2021-09-16 | R4: 2021-09-11 | S4: 2021-09-11 | T4: 2021-10-01 | U4: 2021-09-25 | V4: 2021-09-11 | W4: 2021-09-11 | X4: 2021-09-11 | Y4: 2021-09-11 | Z4: 2021-09-11 | AA4: 2021-09-11 | AB4: 2021-09-14 | AC4: 2021-09-18 | AD4: 2021-09-14 | AE4: 2021-09-18 | AF4: 2021-09-23 | AG4: 2021-09-23 | AH4: 2021-09-23 | AI4: 2021-09-16 | AJ4: 2021-09-28 | AK4: 2021-09-11 | AL4: 2021-09-14 | AM4: 2021-09-11 | AN4: 2021-09-11 | AO4: 2021-09-11 | AP4: 2021-09-11 | AQ4: 2021-09-11 | AR4: 2021-09-18 | AS4: 2021-09-23 | AT4: 2021-09-23 | AU4: 2021-09-16 | AV4: 2021-09-24 | AW4: 2021-09-11 | AX4: 2021-09-30 | AY4: 2021-09-23 | AZ4: 2021-09-11 | BA4: 2021-09-23 | BB4: 2021-09-11 | BC4: 2021-09-11 | BD4: 2021-09-11 | BE4: 2021-09-11 | BF4: 2021-09-11 | BG4: 2021-09-11 | BH4: 2021-09-11 | BI4: 2021-09-14 | BJ4: 2021-09-16 | BK4: 2021-09-18 | BL4: 2021-09-23 | BM4: 2021-09-24 | BN4: 2021-09-30 | BO4: 2021-10-07 | BP4: 2021-10-09 | BQ4: 2021-10-14 | BR4: 2021-11-11 | BS4: 2021-12-02 | BT4: 2021-11-11 | BU4: 2021-12-28 | BV4: 2022-01-06
A5: 2021-09-18 | B5: 2021-09-25 | C5: 2021-09-25 | D5: 2021-09-18 | E5: 2021-09-30 | F5: 2021-09-18 | G5: 2021-09-16 | H5: 2021-10-05 | I5: 2021-09-18 | J5: 2021-09-30 | L5: 2021-09-18 | M5: 2021-09-16 | N5: 2021-09-16 | O5: 2021-09-18 | P5: 2021-09-11 | Q5: 2021-09-18 | R5: 2021-09-16 | S5: 2021-10-01 | T5: 2021-10-02 | U5: 2021-10-01 | V5: 2021-09-14 | W5: 2021-09-16 | X5: 2021-09-23 | Y5: 2021-09-14 | Z5: 2021-09-14 | AA5: 2021-09-18 | AB5: 2021-09-16 | AC5: 2021-09-14 | AD5: 2021-09-28 | AE5: 2021-09-25 | AF5: 2021-09-28 | AG5: 2021-10-26 | AH5: 2021-10-02 | AI5: 2021-09-18 | AJ5: 2021-10-07 | AK5: 2021-09-16 | AL5: 2021-09-18 | AM5: 2021-09-18 | AN5: 2021-09-18 | AO5: 2021-09-18 | AP5: 2021-09-16 | AQ5: 2021-09-18 | AR5: 2021-09-23 | AS5: 2021-09-28 | AT5: 2021-09-28 | AU5: 2021-09-30 | AV5: 2021-09-25 | AW5: 2021-09-14 | AX5: 2021-10-02 | AY5: 2021-09-28 | AZ5: 2021-10-07 | BA5: 2021-09-25 | BB5: 2021-09-18 | BC5: 2021-09-18 | BD5: 2021-09-18 | BE5: 2021-09-11 | BF5: 2021-09-16 | BG5: 2021-09-16 | BH5: 2021-10-07 | BI5: 2021-10-09 | BJ5: 2021-09-24 | BK5: 2021-09-25 | BL5: 2021-09-28 | BM5: 2021-09-25 | BN5: 2021-10-28 | BO5: 2021-10-09 | BP5: 2021-10-30 | BQ5: 2021-11-18 | BR5: 2021-11-13 | BS5: 2021-12-30
A6: 2021-09-25 | B6: 2021-10-02 | C6: 2021-10-02 | D6: 2021-09-11 | E6: 2021-10-09 | F6: 2021-09-30 | G6: 2021-09-18 | H6: 2021-10-09 | I6: 2021-09-25 | J6: 2021-10-08 | L6: 2021-09-23 | M6: 2021-09-18 | N6: 2021-09-25 | O6: 2021-09-25 | P6: 2021-10-30 | Q6: 2021-10-09 | R6: 2021-09-18 | S6: 2021-10-02 | T6: 2021-10-14 | U6: 2021-10-02 | V6: 2021-09-18 | W6: 2021-09-30 | X6: 2021-09-30 | Y6: 2021-09-25 | Z6: 2021-09-23 | AA6: 2021-10-02 | AB6: 2021-09-18 | AC6: 2021-09-23 | AD6: 2021-10-14 | AE6: 2021-10-02 | AF6: 2021-10-07 | AG6: 2021-11-04 | AI6: 2021-09-25 | AJ6: 2021-10-16 | AK6: 2021-09-18 | AL6: 2021-09-23 | AM6: 2021-09-11 | AN6: 2021-09-23 | AO6: 2021-10-02 | AP6: 2021-09-24 | AQ6: 2021-09-23 | AR6: 2021-10-29 | AS6: 2021-10-02 | AT6: 2021-10-02 | AU6: 2021-10-02 | AV6: 2021-10-23 | AW6: 2021-09-18 | AX6: 2021-10-09 | AY6: 2021-10-09 | AZ6: 2021-10-14 | BA6: 2021-10-02 | BB6: 2021-09-23 | BC6: 2021-09-23 | BD6: 2021-09-28 | BE6: 2021-09-23 | BF6: 2021-09-11 | BG6: 2021-09-30 | BH6: 2021-10-16 | BI6: 2021-09-23 | BJ6: 2021-09-25 | BK6: 2021-10-02 | BL6: 2021-10-14 | BM6: 2021-10-07 | BN6: 2021-10-30 | BO6: 2021-10-14 | BQ6: 2021-11-27 | BR6: 2021-12-11 | BS6: 2022-02-05
A7: 2021-10-02 | B7: 2021-10-14 | C7: 2021-09-11 | D7: 2021-10-05 | E7: 2021-10-18 | F7: 2021-10-09 | G7: 2021-09-25 | H7: 2021-10-18 | I7: 2021-09-30 | J7: 2021-10-16 | L7: 2021-10-02 | M7: 2021-09-23 | N7: 2021-10-02 | O7: 2021-10-02 | P7: 2021-11-06 | Q7: 2021-10-16 | R7: 2021-09-23 | S7: 2021-10-15 | T7: 2021-10-21 | U7: 2021-10-15 | V7: 2021-09-16 | W7: 2021-10-07 | X7: 2021-09-22 | Y7: 2021-09-28 | Z7: 2021-09-22 | AA7: 2021-10-13 | AB7: 2021-10-02 | AC7: 2021-09-25 | AD7: 2021-10-21 | AE7: 2021-09-11 | AF7: 2021-10-14 | AG7: 2021-11-20 | AI7: 2021-09-28 | AJ7: 2021-10-17 | AK7: 2021-09-11 | AL7: 2021-09-25 | AM7: 2021-09-23 | AN7: 2021-09-30 | AO7: 2021-10-03 | AP7: 2021-09-25 | AQ7: 2021-10-02 | AR7: 2021-11-06 | AS7: 2021-09-11 | AT7: 2021-10-14 | AU7: 2021-10-07 | AV7: 2021-10-28 | AW7: 2021-09-23 | AX7: 2021-10-21 | AY7: 2021-10-23 | AZ7: 2021-10-16 | BA7: 2021-10-07 | BB7: 2021-09-25 | BC7: 2021-10-02 | BD7: 2021-10-09 | BE7: 2021-09-16 | BF7: 2021-09-30 | BG7: 2021-10-08 | BH7: 2021-10-17 | BI7: 2021-10-07 | BJ7: 2021-10-09 | BK7: 2021-10-09 | BL7: 2021-10-16 | BM7: 2021-10-16 | BN7: 2021-11-04 | BO7: 2021-10-23 | BQ7: 2021-12-17 | BR7: 2021-12-04
A8: 2021-10-09 | B8: 2021-10-30 | C8: 2021-10-08 | D8: 2021-10-09 | E8: 2021-11-02 | F8: 2021-10-16 | G8: 2021-10-01 | H8: 2021-10-28 | I8: 2021-10-14 | J8: 2021-10-18 | L8: 2021-09-11 | M8: 2021-09-25 | N8: 2021-09-23 | O8: 2021-10-07 | P8: 2021-11-20 | Q8: 2021-10-23 | R8: 2021-09-25 | S8: 2021-10-26 | T8: 2021-10-28 | U8: 2021-10-26 | V8: 2021-09-25 | W8: 2021-10-16 | X8: 2021-10-07 | Y8: 2021-10-07 | Z8: 2021-10-07 | AA8: 2021-10-15 | AB8: 2021-09-22 | AC8: 2021-09-28 | AD8: 2021-10-28 | AE8: 2021-10-09 | AF8: 2021-10-17 | AG8: 2021-11-25 | AI8: 2021-10-07 | AJ8: 2021-11-05 | AK8: 2021-09-25 | AL8: 2021-10-02 | AM8: 2021-09-28 | AN8: 2021-09-16 | AO8: 2021-10-09 | AP8: 2021-10-02 | AQ8: 2021-09-14 | AR8: 2021-11-20 | AS8: 2021-10-14 | AT8: 2021-10-23 | AU8: 2021-10-16 | AV8: 2021-10-30 | AW8: 2021-09-23 | AX8: 2021-10-28 | AY8: 2021-11-04 | AZ8: 2021-10-17 | BA8: 2021-10-22 | BB8: 2021-10-02 | BC8: 2021-10-03 | BD8: 2021-10-13 | BE8: 2021-09-28 | BF8: 2021-10-02 | BG8: 2021-10-21 | BH8: 2021-10-23 | BJ8: 2021-10-16 | BK8: 2021-10-16 | BL8: 2021-10-30 | BM8: 2021-10-14 | BN8: 2021-11-06 | BO8: 2021-10-29 | BQ8: 2021-12-30 | BR8: 2022-01-16
A9: 2021-10-16 | B9: 2021-11-23 | C9: 2021-10-18 | D9: 2021-10-14 | E9: 2021-11-18 | F9: 2021-10-30 | G9: 2021-10-05 | H9: 2021-10-30 | I9: 2021-10-28 | J9: 2021-11-02 | L9: 2021-10-13 | M9: 2021-10-02 | N9: 2021-10-07 | O9: 2021-10-09 | P9: 2022-01-04 | Q9: 2021-11-06 | R9: 2021-09-14 | S9: 2021-11-05 | T9: 2021-11-20 | U9: 2021-11-05 | V9: 2021-09-28 | W9: 2021-11-04 | X9: 2021-10-14 | Y9: 2021-11-02 | Z9: 2021-10-14 | AA9: 2021-10-21 | AB9: 2021-10-07 | AC9: 2021-10-07 | AD9: 2021-11-04 | AE9: 2021-10-17 | AF9: 2021-10-21 | AG9: 2021-12-02 | AI9: 2021-10-14 | AJ9: 2021-11-06 | AK9: 2021-10-02 | AL9: 2021-10-21 | AM9: 2021-10-07 | AN9: 2021-10-21 | AO9: 2021-10-21 | AP9: 2021-10-08 | AQ9: 2021-10-07 | AR9: 2021-11-27 | AS9: 2021-10-22 | AT9: 2021-11-05 | AU9: 2021-10-23 | AV9: 2021-11-06 | AW9: 2021-09-28 | AX9: 2021-11-04 | AY9: 2021-11-06 | AZ9: 2021-10-21 | BA9: 2021-10-30 | BB9: 2021-10-03 | BC9: 2021-10-23 | BD9: 2021-10-16 | BE9: 2021-10-05 | BF9: 2021-10-21 | BG9: 2021-10-23 | BH9: 2021-11-05 | BJ9: 2021-10-28 | BK9: 2021-10-21 | BL9: 2021-11-04 | BM9: 2021-10-28 | BN9: 2021-11-16 | BO9: 2021-11-11 | BR9: 2022-02-26
A10: 2021-10-30 | B10: 2021-12-02 | C10: 2021-11-06 | D10: 2021-10-30 | E10: 2021-12-04 | F10: 2021-11-18 | G10: 2021-10-14 | H10: 2021-11-06 | I10: 2021-11-06 | J10: 2021-11-23 | L10: 2021-10-15 | M10: 2021-09-22 | N10: 2021-10-14 | O10: 2021-10-16 | P10: 2022-01-22 | Q10: 2022-02-26 | R10: 2021-09-28 | S10: 2021-11-06 | T10: 2021-11-25 | U10: 2021-11-06 | V10: 2021-10-02 | W10: 2021-11-18 | X10: 2021-10-17 | Y10: 2021-10-21 | Z10: 2021-10-21 | AA10: 2021-10-23 | AB10: 2021-10-14 | AC10: 2021-10-09 | AD10: 2021-11-25 | AE10: 2021-10-23 | AF10: 2021-11-02 | AG10: 2021-12-09 | AI10: 2021-10-22 | AJ10: 2021-11-19 | AK10: 2021-10-07 | AL10: 2021-10-09 | AM10: 2021-10-09 | AN10: 2021-10-02 | AO10: 2021-10-23 | AP10: 2021-10-14 | AQ10: 2021-10-21 | AR10: 2021-12-10 | AS10: 2021-11-20 | AT10: 2021-11-06 | AU10: 2021-10-28 | AV10: 2021-11-20 | AW10: 2021-10-02 | AX10: 2021-10-16 | AY10: 2021-11-18 | AZ10: 2021-11-27 | BA10: 2021-11-25 | BB10: 2021-10-09 | BC10: 2021-11-20 | BD10: 2021-10-23 | BE10: 2021-10-16 | BF10: 2021-10-23 | BG10: 2021-10-28 | BH10: 2021-11-06 | BJ10: 2021-10-30 | BK10: 2021-10-28 | BL10: 2021-10-21 | BM10: 2021-10-30 | BN10: 2021-11-25 | BO10: 2021-11-27 | BR10: 2022-03-03
A11: 2021-11-25 | C11: 2021-11-23 | D11: 2021-11-06 | E11: 2021-12-11 | F11: 2021-12-02 | G11: 2021-10-02 | H11: 2021-11-18 | I11: 2021-11-18 | J11: 2021-12-04 | L11: 2021-10-23 | M11: 2021-09-28 | N11: 2021-10-17 | O11: 2021-10-21 | P11: 2022-01-29 | Q11: 2022-03-05 | R11: 2021-10-07 | S11: 2021-11-13 | T11: 2021-12-02 | U11: 2021-11-13 | V11: 2021-10-07 | W11: 2021-11-27 | X11: 2021-10-21 | Y11: 2021-11-16 | Z11: 2021-11-02 | AA11: 2021-11-04 | AB11: 2021-10-23 | AC11: 2021-10-21 | AD11: 2021-12-11 | AE11: 2021-10-30 | AF11: 2021-11-06 | AG11: 2021-12-11 | AI11: 2021-10-30 | AJ11: 2021-11-23 | AK11: 2021-10-09 | AL11: 2021-10-27 | AM11: 2021-10-16 | AN11: 2021-10-28 | AO11: 2021-11-02 | AP11: 2021-10-16 | AQ11: 2021-10-23 | AR11: 2021-12-28 | AS11: 2021-11-27 | AT11: 2021-11-20 | AU11: 2021-11-04 | AV11: 2021-11-25 | AW11: 2021-10-03 | AX11: 2021-11-19 | AY11: 2021-11-23 | AZ11: 2021-11-13 | BA11: 2022-01-08 | BB11: 2021-10-14 | BC11: 2021-11-27 | BD11: 2021-10-27 | BE11: 2021-10-22 | BF11: 2021-10-16 | BG11: 2021-10-30 | BH11: 2021-11-19 | BJ11: 2021-11-23 | BK11: 2021-10-30 | BL11: 2021-11-18 | BM11: 2021-11-19 | BN11: 2021-11-27 | BO11: 2021-12-04
A12: 2021-12-04 | C12: 2021-12-05 | D12: 2021-11-20 | E12: 2021-12-16 | F12: 2021-12-11 | G12: 2021-11-23 | H12: 2021-11-27 | I12: 2021-11-25 | J12: 2021-12-11 | L12: 2021-11-04 | M12: 2021-10-07 | N12: 2021-10-23 | O12: 2021-10-28 | P12: 2022-02-26 | R12: 2021-10-14 | S12: 2021-11-26 | T12: 2021-12-07 | U12: 2021-11-26 | V12: 2021-10-14 | W12: 2021-12-02 | X12: 2021-10-30 | Y12: 2021-11-20 | Z12: 2021-11-06 | AA12: 2021-11-18 | AB12: 2021-09-28 | AC12: 2021-10-26 | AD12: 2021-12-09 | AE12: 2021-11-06 | AF12: 2021-11-20 | AG12: 2021-12-28 | AI12: 2021-11-06 | AJ12: 2021-11-27 | AK12: 2021-10-16 | AL12: 2021-11-06 | AM12: 2021-10-29 | AN12: 2021-11-06 | AO12: 2021-11-13 | AP12: 2021-10-23 | AQ12: 2021-10-27 | AR12: 2021-12-26 | AS12: 2021-12-04 | AT12: 2021-11-26 | AU12: 2021-11-06 | AV12: 2021-12-02 | AW12: 2021-09-28 | AX12: 2021-11-23 | AY12: 2021-11-13 | AZ12: 2021-12-20 | BA12: 2021-12-22 | BB12: 2021-10-21 | BC12: 2022-01-07 | BD12: 2021-10-28 | BE12: 2021-10-28 | BF12: 2021-10-28 | BG12: 2021-11-06 | BH12: 2021-11-27 | BJ12: 2021-11-26 | BK12: 2021-12-02 | BL12: 2021-11-20 | BM12: 2021-11-26 | BN12: 2021-12-08 | BO12: 2021-12-11
A13: 2021-12-11 | C13: 2021-12-11 | D13: 2021-11-27 | E13: 2021-12-30 | F13: 2021-12-30 | G13: 2021-10-30 | H13: 2021-12-04 | I13: 2021-12-02 | J13: 2021-12-16 | L13: 2021-11-23 | M13: 2021-10-14 | N13: 2021-10-30 | O13: 2021-11-04 | P13: 2022-03-05 | R13: 2021-10-21 | S13: 2021-12-04 | T13: 2021-12-09 | U13: 2021-11-27 | V13: 2021-10-21 | W13: 2021-12-04 | X13: 2021-11-06 | Y13: 2021-12-02 | Z13: 2021-11-20 | AA13: 2021-11-23 | AB13: 2021-11-02 | AC13: 2021-11-04 | AD13: 2021-12-26 | AE13: 2021-12-04 | AF13: 2021-11-25 | AG13: 2022-01-20 | AI13: 2021-11-20 | AJ13: 2021-12-28 | AK13: 2021-10-27 | AL13: 2021-11-26 | AM13: 2021-10-30 | AN13: 2021-11-13 | AO13: 2021-12-04 | AP13: 2021-09-28 | AQ13: 2021-11-05 | AR13: 2022-01-29 | AS13: 2021-11-26 | AT13: 2021-11-23 | AU13: 2021-11-18 | AV13: 2021-12-30 | AW13: 2021-10-09 | AX13: 2021-12-02 | AY13: 2021-11-27 | AZ13: 2021-12-11 | BA13: 2022-01-22 | BB13: 2021-10-23 | BC13: 2022-02-17 | BD13: 2021-11-04 | BE13: 2021-10-30 | BF13: 2021-11-05 | BG13: 2021-11-16 | BH13: 2021-12-04 | BJ13: 2021-12-02 | BK13: 2021-12-20 | BL13: 2021-11-27 | BM13: 2021-12-04 | BN13: 2021-12-11 | BO13: 2021-12-27
A14: 2021-12-30 | C14: 2021-12-23 | D14: 2021-12-05 | E14: 2022-01-20 | F14: 2022-01-22 | G14: 2021-12-05 | H14: 2021-12-11 | I14: 2021-12-04 | J14: 2022-01-29 | L14: 2021-11-27 | M14: 2021-10-16 | N14: 2021-11-04 | O14: 2021-11-20 | R14: 2021-10-30 | S14: 2021-12-11 | T14: 2021-12-26 | U14: 2021-12-04 | V14: 2021-10-23 | W14: 2021-12-09 | X14: 2021-11-20 | Y14: 2021-12-04 | Z14: 2021-11-23 | AA14: 2021-12-07 | AB14: 2021-11-18 | AC14: 2021-11-18 | AD14: 2021-12-15 | AE14: 2021-12-23 | AF14: 2021-12-02 | AG14: 2022-01-22 | AI14: 2021-11-27 | AJ14: 2021-12-22 | AK14: 2021-11-06 | AL14: 2021-12-02 | AM14: 2021-11-18 | AN14: 2021-12-08 | AO14: 2021-11-04 | AP14: 2021-10-28 | AQ14: 2021-11-11 | AR14: 2022-02-03 | AS14: 2021-12-11 | AT14: 2021-12-11 | AU14: 2021-11-20 | AV14: 2021-12-17 | AW14: 2021-10-09 | AX14: 2021-11-20 | AY14: 2021-12-21 | AZ14: 2021-12-27 | BA14: 2022-02-25 | BB14: 2021-10-29 | BD14: 2021-11-06 | BE14: 2021-11-04 | BF14: 2021-11-11 | BG14: 2021-11-20 | BH14: 2021-12-11 | BJ14: 2021-11-27 | BK14: 2022-01-06 | BL14: 2021-11-23 | BM14: 2021-12-28 | BN14: 2021-12-29 | BO14: 2021-12-30
A15: 2022-01-06 | C15: 2022-01-22 | D15: 2021-12-21 | E15: 2022-01-27 | F15: 2022-01-29 | G15: 2021-12-30 | H15: 2022-01-20 | I15: 2021-12-05 | J15: 2022-02-05 | L15: 2021-12-09 | M15: 2021-10-21 | N15: 2021-11-18 | O15: 2021-11-23 | R15: 2021-11-06 | S15: 2021-12-09 | T15: 2021-12-15 | U15: 2021-12-11 | V15: 2021-10-30 | W15: 2021-12-11 | X15: 2021-11-25 | Y15: 2021-12-09 | Z15: 2021-11-27 | AA15: 2021-12-11 | AB15: 2021-11-25 | AC15: 2021-11-20 | AD15: 2021-12-28 | AE15: 2021-12-17 | AF15: 2021-12-04 | AG15: 2022-01-02 | AI15: 2021-12-11 | AJ15: 2022-01-20 | AK15: 2021-11-11 | AL15: 2021-12-01 | AM15: 2021-11-25 | AN15: 2021-12-15 | AO15: 2021-12-11 | AP15: 2021-11-06 | AQ15: 2021-11-20 | AR15: 2022-02-05 | AS15: 2021-12-28 | AT15: 2022-01-06 | AU15: 2021-11-27 | AV15: 2022-01-28 | AW15: 2021-10-13 | AX15: 2021-12-10 | AY15: 2022-01-20 | AZ15: 2021-12-28 | BA15: 2022-03-05 | BB15: 2021-11-02 | BD15: 2021-11-11 | BE15: 2021-11-16 | BF15: 2021-11-18 | BG15: 2021-11-25 | BH15: 2021-12-28 | BJ15: 2021-12-21 | BK15: 2022-01-08 | BL15: 2021-12-10 | BM15: 2022-01-06 | BN15: 2022-01-05 | BO15: 2022-01-08
A16: 2022-01-27 | C16: 2022-02-03 | D16: 2021-12-30 | E16: 2022-02-03 | F16: 2022-02-17 | G16: 2022-01-07 | H16: 2022-01-22 | I16: 2021-12-21 | J16: 2022-02-26 | L16: 2022-01-20 | M16: 2021-10-23 | N16: 2021-11-20 | O16: 2021-12-28 | R16: 2021-11-18 | S16: 2022-01-04 | T16: 2021-12-28 | U16: 2021-12-26 | V16: 2021-11-04 | W16: 2021-12-18 | X16: 2021-12-04 | Y16: 2021-12-11 | Z16: 2021-12-04 | AA16: 2021-12-18 | AB16: 2021-12-02 | AC16: 2021-11-25 | AD16: 2022-01-22 | AE16: 2021-12-28 | AF16: 2021-12-09 | AG16: 2022-01-27 | AI16: 2021-12-28 | AJ16: 2022-01-22 | AK16: 2021-11-25 | AL16: 2021-12-08 | AM16: 2021-11-27 | AN16: 2021-12-28 | AO16: 2021-12-20 | AP16: 2021-11-25 | AQ16: 2021-11-26 | AR16: 2022-02-25 | AS16: 2021-12-22 | AT16: 2022-01-20 | AU16: 2021-12-02 | AV16: 2022-02-03 | AW16: 2021-10-16 | AX16: 2021-12-30 | AY16: 2022-01-16 | AZ16: 2022-01-22 | BB16: 2021-11-06 | BD16: 2021-11-18 | BE16: 2021-11-25 | BF16: 2021-11-25 | BG16: 2021-12-02 | BH16: 2022-01-06 | BJ16: 2022-01-02 | BK16: 2022-01-20 | BL16: 2021-12-15 | BM16: 2022-01-08 | BN16: 2022-01-09 | BO16: 2022-01-18
A17: 2022-02-05 | C17: 2022-02-24 | D17: 2022-01-07 | E17: 2022-02-19 | F17: 2022-02-26 | G17: 2022-01-22 | H17: 2022-01-27 | I17: 2022-02-03 | J17: 2022-03-03 | L17: 2022-01-22 | M17: 2021-10-28 | N17: 2021-11-27 | O17: 2022-01-20 | R17: 2021-11-27 | S17: 2022-01-27 | T17: 2022-01-02 | U17: 2021-12-09 | V17: 2021-11-18 | W17: 2021-12-28 | X17: 2021-12-09 | Y17: 2021-12-23 | Z17: 2021-12-09 | AA17: 2021-12-17 | AB17: 2021-12-04 | AC17: 2021-12-09 | AD17: 2022-01-02 | AE17: 2022-01-04 | AF17: 2021-12-15 | AG17: 2022-01-29 | AI17: 2022-01-20 | AJ17: 2022-01-08 | AK17: 2021-11-27 | AL17: 2021-12-23 | AM17: 2021-12-02 | AN17: 2021-12-30 | AO17: 2021-12-30 | AP17: 2021-11-18 | AQ17: 2021-12-04 | AS17: 2022-01-22 | AT17: 2022-01-29 | AU17: 2021-11-23 | AV17: 2022-02-17 | AW17: 2021-10-16 | AX17: 2022-01-08 | AY17: 2022-02-17 | AZ17: 2022-01-09 | BB17: 2021-11-13 | BD17: 2021-11-27 | BE17: 2021-12-02 | BF17: 2021-12-01 | BG17: 2021-12-10 | BH17: 2022-01-08 | BJ17: 2022-01-18 | BK17: 2022-01-29 | BL17: 2021-12-23 | BM17: 2022-01-20 | BN17: 2022-01-16 | BO17: 2022-01-22
A18: 2022-02-19 | D18: 2022-01-22 | E18: 2022-02-24 | F18: 2022-03-05 | G18: 2022-01-29 | H18: 2022-01-29 | I18: 2022-02-17 | L18: 2022-01-15 | M18: 2021-11-04 | N18: 2021-12-04 | O18: 2022-01-15 | R18: 2021-12-02 | S18: 2022-02-03 | T18: 2021-12-11 | U18: 2021-12-23 | V18: 2021-11-25 | W18: 2021-12-26 | X18: 2021-12-21 | Y18: 2022-01-02 | Z18: 2021-12-26 | AA18: 2022-01-11 | AB18: 2021-12-09 | AC18: 2021-12-11 | AD18: 2022-01-20 | AE18: 2022-01-02 | AF18: 2021-12-28 | AG18: 2022-02-17 | AI18: 2022-01-28 | AJ18: 2022-02-26 | AK18: 2021-12-01 | AL18: 2021-12-26 | AM18: 2021-11-23 | AN18: 2021-12-30 | AO18: 2022-01-08 | AP18: 2021-12-27 | AQ18: 2021-11-18 | AS18: 2022-01-29 | AT18: 2022-02-05 | AU18: 2021-12-23 | AV18: 2022-02-05 | AW18: 2021-10-21 | AX18: 2022-01-22 | AY18: 2022-02-24 | AZ18: 2022-01-29 | BB18: 2021-11-27 | BD18: 2021-12-04 | BE18: 2021-11-18 | BF18: 2021-12-02 | BG18: 2021-12-20 | BH18: 2021-12-22 | BJ18: 2022-02-03 | BK18: 2022-02-03 | BL18: 2021-12-28 | BM18: 2022-01-29 | BN18: 2022-01-12 | BO18: 2022-01-09
A19: 2022-02-26 | D19: 2022-01-29 | E19: 2022-03-05 | G19: 2022-02-17 | H19: 2022-02-03 | I19: 2022-02-05 | L19: 2022-01-18 | M19: 2021-11-06 | N19: 2021-12-09 | O19: 2022-02-03 | R19: 2021-12-07 | S19: 2022-02-17 | T19: 2022-01-20 | U19: 2022-01-29 | V19: 2021-11-27 | W19: 2022-01-20 | X19: 2021-12-18 | Y19: 2022-01-20 | Z19: 2022-01-11 | AA19: 2022-01-22 | AB19: 2021-12-28 | AC19: 2022-01-02 | AD19: 2022-01-27 | AE19: 2022-01-29 | AF19: 2022-01-20 | AG19: 2022-02-12 | AI19: 2022-02-05 | AJ19: 2022-03-03 | AK19: 2021-12-28 | AL19: 2021-12-30 | AM19: 2021-11-04 | AN19: 2021-12-11 | AO19: 2022-01-18 | AP19: 2021-12-30 | AQ19: 2021-12-10 | AS19: 2022-01-28 | AT19: 2022-01-28 | AU19: 2022-01-02 | AV19: 2022-03-05 | AW19: 2021-10-23 | AX19: 2022-02-05 | AY19: 2022-03-05 | AZ19: 2022-02-05 | BB19: 2022-01-07 | BD19: 2021-12-15 | BE19: 2021-12-10 | BF19: 2021-12-23 | BG19: 2022-01-06 | BH19: 2022-01-22 | BJ19: 2022-02-26 | BK19: 2022-02-17 | BL19: 2022-01-29 | BM19: 2022-02-17 | BN19: 2022-01-13 | BO19: 2022-01-29
A20: 2022-03-03 | D20: 2022-02-17 | G20: 2022-02-24 | H20: 2022-02-26 | I20: 2022-02-24 | L20: 2022-01-29 | M20: 2021-11-18 | N20: 2021-12-28 | O20: 2022-02-17 | R20: 2021-12-09 | S20: 2022-02-19 | T20: 2022-01-27 | U20: 2022-02-03 | V20: 2021-12-09 | W20: 2022-01-22 | X20: 2021-12-26 | Y20: 2022-01-22 | Z20: 2022-01-02 | AA20: 2022-01-20 | AB20: 2022-01-18 | AC20: 2021-12-21 | AD20: 2022-02-19 | AE20: 2022-02-18 | AF20: 2022-01-22 | AG20: 2022-02-24 | AI20: 2022-02-26 | AK20: 2022-01-05 | AL20: 2022-01-05 | AM20: 2021-12-10 | AN20: 2022-01-02 | AO20: 2022-01-27 | AP20: 2022-01-22 | AQ20: 2021-12-11 | AS20: 2022-02-05 | AT20: 2022-02-24 | AU20: 2022-01-22 | AW20: 2021-10-23 | AX20: 2022-02-19 | AZ20: 2022-02-09 | BB20: 2022-01-18 | BD20: 2022-01-02 | BE20: 2021-12-21 | BF20: 2021-12-15 | BG20: 2022-01-20 | BH20: zbrisano | BJ20: 2022-03-05 | BK20: 2022-02-25 | BL20: 2022-02-03 | BM20: 2022-02-24 | BN20: 2022-01-26 | BO20: 2022-02-19
D21: 2022-02-05 | H21: 2022-02-24 | I21: 2022-02-19 | L21: 2022-02-05 | M21: 2021-11-25 | N21: 2021-12-16 | O21: 2022-02-19 | R21: 2021-12-15 | S21: 2022-02-26 | T21: 2022-02-03 | U21: 2022-02-17 | V21: 2021-12-11 | W21: 2022-01-27 | X21: zbrisano | Y21: 2022-01-27 | Z21: zbrisano | AA21: 2022-01-27 | AB21: 2022-01-27 | AC21: 2021-12-30 | AD21: 2022-02-17 | AE21: 2022-02-12 | AF21: 2022-01-27 | AG21: 2022-03-03 | AI21: 2022-03-03 | AK21: 2022-01-20 | AL21: 2022-01-22 | AM21: 2021-12-23 | AN21: 2022-01-08 | AO21: 2022-01-29 | AP21: 2022-01-29 | AQ21: 2021-12-02 | AS21: 2022-02-17 | AU21: 2022-01-29 | AW21: 2021-10-28 | AX21: 2022-02-26 | AZ21: 2022-02-19 | BB21: 2022-01-27 | BD21: 2021-12-23 | BE21: 2021-12-27 | BF21: 2021-12-30 | BG21: 2022-01-22 | BH21: 2022-01-29 | BK21: 2022-03-05 | BL21: 2022-02-05 | BM21: 2022-02-26 | BN21: 2022-01-29
D22: 2022-02-24 | I22: 2022-03-03 | L22: 2022-02-19 | M22: 2021-12-02 | N22: 2022-01-04 | O22: 2022-02-26 | R22: 2022-01-11 | S22: 2022-03-05 | T22: 2022-02-18 | U22: 2022-02-19 | V22: 2021-12-23 | W22: 2022-01-29 | X22: 2022-02-19 | Y22: 2022-01-29 | Z22: 2022-01-27 | AA22: 2022-02-03 | AB22: 2022-02-03 | AC22: 2022-01-22 | AD22: 2022-02-24 | AE22: 2022-02-26 | AF22: 2022-02-03 | AK22: 2022-01-18 | AL22: 2022-01-08 | AM22: 2021-12-28 | AN22: 2022-01-12 | AO22: 2022-02-09 | AP22: 2022-01-27 | AQ22: 2021-12-28 | AS22: 2022-02-25 | AU22: 2022-02-05 | AW22: 2021-11-04 | AX22: 2022-03-05 | AZ22: 2022-02-26 | BB22: 2022-02-03 | BD22: 2022-01-22 | BE22: 2022-01-16 | BF22: 2022-01-20 | BG22: 2022-01-29 | BH22: 2022-02-03 | BL22: 2022-02-16 | BN22: 2022-02-05
D23: 2022-03-03 | L23: 2022-02-24 | M23: 2021-11-27 | N23: 2022-01-20 | R23: 2022-01-02 | T23: 2022-02-24 | U23: 2022-02-26 | V23: 2021-12-16 | W23: 2022-02-03 | X23: 2022-02-05 | Y23: 2022-02-03 | Z23: 2022-02-03 | AA23: 2022-02-19 | AB23: 2022-02-17 | AC23: 2022-01-27 | AD23: 2022-03-03 | AE23: 2022-03-03 | AF23: 2022-02-19 | AK23: 2022-01-12 | AL23: 2022-01-18 | AM23: 2022-01-06 | AN23: 2022-01-12 | AO23: 2022-03-03 | AP23: 2022-02-19 | AQ23: 2022-01-08 | AU23: 2022-02-19 | AW23: 2021-11-05 | AZ23: 2022-02-17 | BB23: 2022-02-05 | BD23: 2022-01-08 | BE23: 2022-02-03 | BF23: 2022-01-18 | BG23: 2022-02-05 | BH23: 2022-02-17 | BL23: 2022-02-24 | BN23: 2022-02-16
D24: 2022-03-05 | L24: 2022-02-26 | M24: 2021-12-07 | N24: 2022-01-15 | R24: 2021-12-29 | T24: 2022-03-05 | U24: 2022-03-05 | V24: 2021-12-28 | W24: 2022-02-05 | X24: 2022-02-24 | Y24: 2022-02-05 | Z24: 2022-02-19 | AA24: 2022-02-12 | AB24: 2022-02-24 | AC24: 2022-01-29 | AF24: 2022-03-03 | AK24: 2022-01-27 | AL24: 2022-01-29 | AM24: 2022-01-09 | AN24: 2022-01-13 | AP24: 2022-02-17 | AQ24: 2022-01-13 | AU24: 2022-02-26 | AW24: 2021-11-06 | AZ24: 2022-02-24 | BB24: 2022-02-09 | BD24: 2022-01-27 | BE24: 2022-02-19 | BF24: 2022-01-27 | BG24: 2022-02-17 | BH24: 2022-02-24 | BL24: 2022-02-26 | BN24: 2022-02-19
L25: 2022-03-03 | M25: 2021-12-11 | N25: 2022-01-27 | R25: 2021-12-26 | V25: 2021-12-26 | W25: 2022-02-17 | X25: 2022-03-03 | Y25: 2022-02-26 | Z25: 2022-02-12 | AA25: 2022-03-03 | AB25: 2022-03-03 | AC25: 2022-02-19 | AK25: 2022-02-03 | AL25: 2022-01-27 | AM25: 2022-02-19 | AN25: 2022-01-18 | AP25: 2022-03-03 | AQ25: 2022-01-26 | AU25: 2022-03-05 | AW25: 2021-11-06 | BB25: 2022-02-24 | BD25: 2022-02-03 | BE25: 2022-02-26 | BF25: 2022-02-03 | BG25: 2022-02-26 | BH25: 2022-03-05 | BN25: 2022-02-26
L26: 2022-03-05 | M26: 2022-01-11 | N26: 2022-02-03 | R26: 2022-01-20 | V26: 2022-01-18 | W26: 2022-02-26 | Y26: 2022-02-18 | AB26: 2022-03-05 | AC26: 2022-02-26 | AK26: 2022-02-05 | AL26: 2022-02-03 | AM26: 2022-02-24 | AN26: 2022-01-22 | AP26: 2022-03-05 | AQ26: 2022-01-29 | AW26: 2021-10-17 | BB26: 2022-02-26 | BD26: 2022-02-05 | BE26: 2022-03-05 | BF26: 2022-02-05 | BG26: 2022-02-19 | BN26: 2022-03-03
M27: 2021-12-28 | N27: 2022-02-05 | R27: 2022-01-29 | V27: 2022-01-15 | W27: 2022-03-05 | Y27: 2022-03-05 | AC27: 2022-03-03 | AK27: 2022-02-19 | AL27: 2022-02-19 | AN27: 2022-01-26 | AQ27: 2022-02-05 | AW27: 2021-11-11 | BB27: 2022-03-03 | BD27: 2022-02-19 | BF27: 2022-02-12 | BG27: 2022-03-03 | BN27: 2022-03-05
M28: 2021-12-18 | N28: 2022-02-18 | R28: 2022-02-03 | V28: 2022-01-20 | W28: 2022-03-03 | AK28: 2022-02-16 | AL28: 2022-02-26 | AN28: 2022-01-26 | AQ28: 2022-02-12 | AW28: 2021-11-18 | BD28: 2022-02-24 | BF28: 2022-02-19
M29: 2021-12-26 | N29: 2022-02-24 | R29: 2022-02-26 | V29: 2022-01-27 | AK29: 2022-02-24 | AN29: 2022-02-03 | AQ29: 2022-02-24 | AW29: 2021-11-18 | BD29: 2022-02-16 | BF29: 2022-02-26
M30: 2021-12-29 | N30: 2022-03-03 | R30: 2022-03-03 | V30: 2022-02-03 | AK30: 2022-03-03 | AN30: 2022-02-12 | AQ30: 2022-03-03 | AW30: 2021-11-20 | BD30: 2022-03-03 | BF30: 2022-03-05
M31: 2022-01-29 | R31: 2022-03-05 | V31: 2022-02-17 | AN31: 2022-02-12 | AW31: 2021-11-20
M32: 2022-02-03 | V32: 2022-02-19 | AN32: 2022-02-17 | AW32: 2021-12-01
M33: 2022-02-05 | V33: 2022-02-26 | AN33: 2022-02-05 | AW33: 2021-12-02
M34: 2022-02-19 | V34: 2022-03-03 | AN34: 2022-02-24 | AW34: 2021-12-04
M35: 2022-03-03 | AN35: 2022-02-24 | AW35: 2021-12-08
M36: 2022-02-24 | AN36: 2022-03-03 | AW36: 2021-12-10
AN37: 2022-03-05 | AW37: 2021-12-23
AN38: 2022-03-03 | AW38: 2021-12-26
AW39: 2021-12-30
AW40: 2021-12-30
...

Sheet AHL_DAT
