Workbook

Sheet AHL
A1: =COUNTIF(A4:A69,"<>") -> 28 | B1: =COUNTIF(B4:B64,"<>") -> 17 | C1: =COUNTIF(C4:C67,"<>") -> 27 | D1: =COUNTIF(D4:D67,"<>") -> 20 | E1: =COUNTIF(E4:E66,"<>") -> 24 | F1: =COUNTIF(F4:F67,"<>") -> 16 | G1: =COUNTIF(G4:G68,"<>") -> 4 | H1: =COUNTIF(H4:H68,"<>") -> 17 | I1: =COUNTIF(I4:I68,"<>") -> 29 | J1: =COUNTIF(J4:J64,"<>") -> 12 | K1: =COUNTIF(K4:K70,"<>") -> 15 | L1: =COUNTIF(L4:L69,"<>") -> 17 | M1: =COUNTIF(M4:M70,"<>") -> 1 | N1: =COUNTIF(N4:N65,"<>") -> 19 | O1: =COUNTIF(O4:O66,"<>") -> 19 | P1: =COUNTIF(P4:P70,"<>") -> 23 | Q1: =COUNTIF(Q4:Q66,"<>") -> 21 | R1: =COUNTIF(R4:R63,"<>") -> 33 | S1: =COUNTIF(S4:S69,"<>") -> 32 | T1: =COUNTIF(T4:T68,"<>") -> 20 | U1: =COUNTIF(U4:U69,"<>") -> 24 | V1: =COUNTIF(V4:V66,"<>") -> 21 | W1: =COUNTIF(W4:W68,"<>") -> 25 | X1: =COUNTIF(X4:X68,"<>") -> 17 | Y1: =COUNTIF(Y4:Y68,"<>") -> 12 | Z1: =COUNTIF(Z4:Z70,"<>") -> 21 | AA1: =COUNTIF(AA4:AA65,"<>") -> 19 | AB1: =COUNTIF(AB4:AB65,"<>") -> 22 | AC1: =COUNTIF(AC4:AC68,"<>") -> 20 | AD1: =COUNTIF(AD4:AD66,"<>") -> 17 | AE1: =COUNTIF(AE4:AE67,"<>") -> 17 | AF1: =COUNTIF(AF4:AF63,"<>") -> 17 | AG1: =COUNTIF(AG4:AG65,"<>") -> 22 | AH1: =COUNTIF(AH4:AH65,"<>") -> 21 | AI1: =COUNTIF(AI4:AI66,"<>") -> 13 | AJ1: =COUNTIF(AJ4:AJ61,"<>") -> 14 | AK1: =COUNTIF(AK4:AK63,"<>") -> 25 | AL1: =COUNTIF(AL4:AL65,"<>") -> 24 | AM1: =COUNTIF(AM4:AM64,"<>") -> 21 | AN1: =COUNTIF(AN4:AN63,"<>") -> 29 | AO1: =COUNTIF(AO4:AO64,"<>") -> 24 | AP1: =COUNTIF(AP4:AP66,"<>") -> 18 | AQ1: =COUNTIF(AQ4:AQ67,"<>") -> 17 | AR1: =COUNTIF(AR4:AR60,"<>") -> 27 | AS1: =COUNTIF(AS4:AS68,"<>") -> 18 | AT1: =COUNTIF(AT4:AT67,"<>") -> 24 | AU1: =COUNTIF(AU4:AU67,"<>") -> 23 | AV1: =COUNTIF(AV4:AV64,"<>") -> 16 | AW1: =COUNTIF(AW4:AW64,"<>") -> 19 | AX1: =COUNTIF(AX4:AX65,"<>") -> 30 | AY1: =COUNTIF(AY4:AY60,"<>") -> 17 | AZ1: =COUNTIF(AZ4:AZ63,"<>") -> 28 | BA1: =COUNTIF(BA4:BA68,"<>") -> 31 | BB1: =COUNTIF(BB4:BB68,"<>") -> 23 | BC1: =COUNTIF(BC4:BC67,"<>") -> 19 | BD1: =COUNTIF(BD4:BD67,"<>") -> 21 | BE1: =COUNTIF(BE4:BE67,"<>") -> 18 | BF1: =COUNTIF(BF4:BF66,"<>") -> 14 | BG1: =COUNTIF(BG4:BG68,"<>") -> 14 | BH1: =COUNTIF(BH4:BH61,"<>") -> 18 | BI1: =COUNTIF(BI4:BI68,"<>") -> 8 | BJ1: =COUNTIF(BJ4:BJ70,"<>") -> 1 | BK1: =COUNTIF(BK4:BK67,"<>") -> 9 | BL1: =COUNTIF(BL4:BL65,"<>") -> 17 | BM1: =COUNTIF(BM4:BM70,"<>") -> 1 | BN1: =COUNTIF(BN4:BN68,"<>") -> 13 | BO1: =COUNTIF(BO4:BO69,"<>") -> 8 | BP1: =COUNTIF(BP4:BP68,"<>") -> 10 | BQ1: =COUNTIF(BQ4:BQ70,"<>") -> 3
A2: sl | B2: sl | C2: sl | D2: sl | E2: sl | F2: sl | G2: sl | H2: sl | I2: sl | J2: sl | K2: hr | L2: hr | M2: hr | N2: it | O2: it | P2: it | Q2: it | R2: it | S2: it | T2: it | U2: it | V2: it | W2: it | X2: it | Y2: it | Z2: it | AA2: it | AB2: it | AC2: it | AD2: it | AE2: it | AF2: it | AG2: it | AH2: it | AI2: it | AJ2: it | AK2: it | AL2: au | AM2: au | AN2: au | AO2: au | AP2: au | AQ2: au | AR2: au | AS2: au | AT2: au | AU2: au | AV2: au | AW2: au | AX2: au | AY2: au | AZ2: au | BA2: au | BB2: au | BC2: au | BD2: au | BE2: au | BF2: au | BG2: au | BH2: au | BI2: au | BJ2: au | BK2: au | BL2: au | BM2: au | BN2: au | BO2: au | BP2: au | BQ2: au
A3: SnojTa | B3: BajtMi | C3: BulovecMi | D3: ArlicMa | E3: MarkizetiGr | F3: LebenJa | G3: MiklicGr | H3: LesniakBo | I3: JeramFi | J3: JavornikBl | K3: MetzingerFi | L3: KnezRo | M3: PiragicTr | N3: BenvegnuAn | O3: SoraperraSi | P3: FecchioFe | Q3: GrisentiLu | R3: LazzeriAl | S3: BrondiPa | T3: FormaioniTh | U3: MoschenAn | V3: RivisAn | W3: VirtaTu | X3: FleischmannLu | Y3: IlmerNo | Z3: StefenelliFe | AA3: ScalzeriAl | AB3: GiacomozziFe | AC3: AbeltinoSi | AD3: PirasAn | AE3: RivisFe | AF3: CusinFe | AG3: PinieOm | AH3: PaceJa | AI3: LegaSi | AJ3: EggerTh | AK3: CristeliMa | AL3: KainbergerJu | AM3: TelesklavFa | AN3: WuchererGe | AO3: Huber rRe | AP3: SpiegelSe | AQ3: MeixnerSe | AR3: OrelSt | AS3: WendnerMa | AT3: RuetzMa | AU3: VoicanCh | AV3: LegatKo | AW3: PreiserJu | AX3: RinkerDa | AY3: WidmannFl | AZ3: StrimitzerDa | BA3: HolzerTo | BB3: DivisDo | BC3: BrockAd | BD3: HlavatyAl | BE3: SeewaldJe | BF3: ZacherlPa | BG3: MoidlMa | BH3: WeissAl | BI3: WenuschHe | BJ3: PuffWo | BK3: MattheyPh | BL3: JägerRi | BM3: SternatCh | BN3: EislCh | BO3: MoidlDa | BP3: LehnerMo | BQ3: UnterwegerDo
A4: 2024-09-21 | B4: 2024-09-26 | C4: 2024-09-26 | D4: 2024-09-26 | E4: 2024-09-26 | F4: 2024-10-05 | G4: 2024-10-05 | H4: 2024-09-28 | I4: 2024-09-28 | J4: 2024-11-01 | K4: 2024-09-22 | L4: 2024-09-28 | M4: 2024-10-19 | N4: 2024-09-21 | O4: 2024-09-21 | P4: 2024-09-21 | Q4: 2024-09-21 | R4: 2024-09-21 | S4: 2024-09-21 | T4: 2024-09-21 | U4: 2024-09-21 | V4: 2024-09-21 | W4: 2024-09-21 | X4: 2024-09-21 | Y4: 2024-09-21 | Z4: 2024-09-22 | AA4: 2024-09-22 | AB4: 2024-10-05 | AC4: 2024-10-05 | AD4: 2024-09-26 | AE4: 2024-09-26 | AF4: 2024-09-26 | AG4: 2024-09-26 | AH4: 2024-11-01 | AI4: 2024-10-12 | AJ4: 2024-10-27 | AK4: 2024-10-20 | AL4: 2024-09-24 | AM4: 2024-09-28 | AN4: 2024-10-10 | AO4: 2024-09-26 | AP4: 2024-09-21 | AQ4: 2024-09-29 | AR4: 2024-09-21 | AS4: 2024-09-21 | AT4: 2024-09-21 | AU4: 2024-09-24 | AV4: 2024-09-24 | AW4: 2024-09-24 | AX4: 2024-09-28 | AY4: 2024-10-05 | AZ4: 2024-09-26 | BA4: 2024-09-26 | BB4: 2024-09-26 | BC4: 2024-09-28 | BD4: 2024-10-26 | BE4: 2024-10-03 | BF4: 2024-10-03 | BG4: 2024-10-10 | BH4: 2024-10-05 | BI4: 2024-10-12 | BJ4: 2024-09-28 | BK4: 2024-10-23 | BL4: 2024-11-03 | BM4: 2024-10-26 | BN4: 2024-10-29 | BO4: 2024-11-01 | BP4: 2024-11-23 | BQ4: 2024-12-26
A5: 2024-09-28 | B5: 2024-10-05 | C5: 2024-10-03 | D5: 2024-10-03 | E5: 2024-09-21 | F5: 2024-10-12 | G5: 2024-10-10 | H5: 2024-10-05 | I5: 2024-10-10 | J5: 2024-10-24 | K5: 2024-09-28 | L5: 2024-10-12 | N5: 2024-10-05 | O5: 2024-09-28 | P5: 2024-09-26 | Q5: 2024-10-05 | R5: 2024-10-05 | S5: 2024-09-26 | T5: 2024-09-26 | U5: 2024-10-05 | V5: 2024-10-05 | W5: 2024-09-28 | X5: 2024-12-07 | Y5: 2024-09-28 | Z5: 2024-09-28 | AA5: 2024-10-03 | AB5: 2024-10-12 | AC5: 2024-09-22 | AD5: 2024-10-03 | AE5: 2024-10-03 | AF5: 2024-10-03 | AG5: 2024-10-03 | AH5: 2024-10-24 | AI5: 2024-11-14 | AJ5: 2024-11-23 | AK5: 2024-10-29 | AL5: 2024-10-10 | AM5: 2024-10-10 | AN5: 2024-09-21 | AO5: 2024-10-03 | AP5: 2024-10-03 | AQ5: 2024-10-10 | AR5: 2024-10-16 | AS5: 2024-10-05 | AT5: 2024-10-03 | AU5: 2024-09-29 | AV5: 2024-09-29 | AW5: 2024-09-29 | AX5: 2024-10-08 | AY5: 2024-09-28 | AZ5: 2024-09-28 | BA5: 2024-09-28 | BB5: 2024-10-03 | BC5: 2024-10-17 | BD5: 2024-10-29 | BE5: 2024-10-09 | BF5: 2024-11-03 | BG5: 2024-11-01 | BH5: 2024-11-16 | BI5: 2024-10-25 | BK5: 2024-11-03 | BL5: 2024-10-09 | BN5: 2024-11-23 | BO5: 2024-10-24 | BP5: 2024-11-30 | BQ5: 2024-12-17
A6: 2024-10-10 | B6: 2024-10-12 | C6: 2024-10-10 | D6: 2024-10-05 | E6: 2024-10-05 | F6: 2024-09-28 | G6: 2024-11-01 | H6: 2024-10-12 | I6: 2024-10-17 | J6: 2024-11-23 | K6: 2024-10-12 | L6: 2024-10-26 | N6: 2024-09-26 | O6: 2024-10-03 | P6: 2024-10-10 | Q6: 2024-09-26 | R6: 2024-09-26 | S6: 2024-10-03 | T6: 2024-10-03 | U6: 2024-09-28 | V6: 2024-09-28 | W6: 2024-10-03 | X6: 2024-12-28 | Y6: 2024-10-03 | Z6: 2024-10-08 | AA6: 2024-10-16 | AB6: 2024-10-31 | AC6: 2024-10-12 | AD6: 2024-10-10 | AE6: 2024-10-12 | AF6: 2024-10-10 | AG6: 2024-10-10 | AH6: 2024-10-31 | AI6: 2024-11-28 | AJ6: 2024-12-03 | AK6: 2024-10-19 | AL6: 2024-10-17 | AM6: 2024-09-26 | AN6: 2024-10-06 | AO6: 2024-10-19 | AP6: 2024-10-09 | AQ6: 2024-09-26 | AR6: 2024-10-06 | AS6: 2024-09-28 | AT6: 2024-10-08 | AU6: 2024-10-10 | AV6: 2024-10-10 | AW6: 2024-10-12 | AX6: 2024-10-17 | AY6: 2024-09-21 | AZ6: 2024-10-03 | BA6: 2024-10-03 | BB6: 2024-10-12 | BC6: 2024-10-05 | BD6: 2024-11-30 | BE6: 2024-10-17 | BF6: 2024-11-14 | BG6: 2024-11-23 | BH6: 2024-12-30 | BI6: 2024-11-02 | BK6: 2024-11-23 | BL6: 2024-10-27 | BN6: 2024-12-07 | BO6: 2024-11-30 | BP6: 2024-12-07 | BQ6: 2024-12-19
A7: 2024-10-17 | B7: 2024-10-20 | C7: 2024-10-17 | D7: 2024-10-12 | E7: 2024-10-12 | F7: 2024-10-27 | G7: 2024-10-24 | H7: 2024-11-01 | I7: 2024-10-27 | J7: 2024-12-07 | K7: 2024-10-26 | L7: 2024-11-01 | N7: 2024-10-12 | O7: 2024-10-10 | P7: 2024-10-17 | Q7: 2024-09-28 | R7: 2024-10-10 | S7: 2024-10-10 | T7: 2024-10-10 | U7: 2024-10-12 | V7: 2024-10-12 | W7: 2024-10-10 | X7: 2024-12-21 | Y7: 2024-10-12 | Z7: 2024-10-16 | AA7: 2024-10-31 | AB7: 2024-11-30 | AC7: 2024-10-08 | AD7: 2024-10-19 | AE7: 2024-10-17 | AF7: 2024-10-27 | AG7: 2024-10-19 | AH7: 2024-11-23 | AI7: 2024-12-28 | AJ7: 2024-11-28 | AK7: 2024-11-17 | AL7: 2024-10-29 | AM7: 2024-10-19 | AN7: 2024-10-16 | AO7: 2024-10-29 | AP7: 2024-10-29 | AQ7: 2024-10-17 | AR7: 2024-09-28 | AS7: 2024-10-12 | AT7: 2024-10-12 | AU7: 2024-10-12 | AV7: 2024-10-05 | AW7: 2024-10-29 | AX7: 2024-10-12 | AY7: 2024-10-19 | AZ7: 2024-10-06 | BA7: 2024-10-09 | BB7: 2024-10-17 | BC7: 2024-10-26 | BD7: 2024-11-21 | BE7: 2024-09-28 | BF7: 2024-11-28 | BG7: 2024-11-30 | BH7: 2024-12-05 | BI7: 2024-11-21 | BK7: 2024-11-30 | BL7: 2024-11-12 | BN7: 2024-12-03 | BO7: 2024-12-07 | BP7: 2024-12-22
A8: 2024-10-26 | B8: 2024-11-01 | C8: 2024-10-26 | D8: 2024-10-26 | E8: 2024-09-28 | F8: 2024-11-03 | H8: 2024-10-24 | I8: 2024-11-03 | J8: 2024-11-26 | K8: 2024-11-01 | L8: 2024-11-17 | N8: 2024-10-20 | O8: 2024-10-17 | P8: 2024-10-05 | Q8: 2024-10-12 | R8: 2024-10-19 | S8: 2024-10-12 | T8: 2024-10-17 | U8: 2024-10-19 | V8: 2024-10-26 | W8: 2024-10-06 | X8: 2025-01-30 | Y8: 2024-10-19 | Z8: 2024-11-01 | AA8: 2024-10-19 | AB8: 2024-11-14 | AC8: 2024-10-19 | AD8: 2024-10-31 | AE8: 2024-10-29 | AF8: 2024-11-01 | AG8: 2024-10-26 | AH8: 2024-12-05 | AI8: 2025-01-06 | AJ8: 2024-11-01 | AK8: 2024-11-21 | AL8: 2024-11-03 | AM8: 2024-11-01 | AN8: 2024-11-01 | AO8: 2024-11-03 | AP8: 2024-10-24 | AQ8: 2024-10-23 | AR8: 2024-10-29 | AS8: 2024-10-26 | AT8: 2024-10-05 | AU8: 2024-10-29 | AV8: 2024-10-29 | AW8: 2024-11-02 | AX8: 2024-10-19 | AY8: 2024-10-26 | AZ8: 2024-10-19 | BA8: 2024-10-17 | BB8: 2024-10-29 | BC8: 2024-11-02 | BD8: 2024-12-05 | BE8: 2024-11-03 | BF8: 2025-01-02 | BG8: 2024-11-14 | BH8: 2025-02-04 | BI8: 2024-12-26 | BK8: 2024-12-22 | BL8: 2024-11-19 | BN8: 2024-11-21 | BO8: 2024-12-28 | BP8: 2024-12-26
A9: 2024-10-24 | B9: 2024-11-23 | C9: 2024-11-03 | D9: 2024-10-17 | E9: 2024-10-20 | F9: 2024-11-21 | H9: 2024-11-16 | I9: 2024-11-21 | J9: 2024-12-28 | K9: 2024-11-17 | L9: 2024-11-28 | N9: 2024-10-25 | O9: 2024-10-24 | P9: 2024-10-19 | Q9: 2024-10-17 | R9: 2024-10-27 | S9: 2024-10-25 | T9: 2024-11-01 | U9: 2024-10-29 | V9: 2024-11-23 | W9: 2024-11-01 | X9: 2025-02-15 | Y9: 2024-10-29 | Z9: 2024-10-24 | AA9: 2024-11-21 | AB9: 2024-11-21 | AC9: 2024-10-29 | AD9: 2024-11-21 | AE9: 2024-11-23 | AF9: 2024-10-24 | AG9: 2024-11-03 | AH9: 2024-11-26 | AI9: 2024-12-30 | AJ9: 2024-12-05 | AK9: 2024-11-28 | AL9: 2024-11-30 | AM9: 2024-10-26 | AN9: 2024-10-29 | AO9: 2024-10-23 | AP9: 2024-11-16 | AQ9: 2024-11-03 | AR9: 2024-11-03 | AS9: 2024-11-03 | AT9: 2024-10-19 | AU9: 2024-11-16 | AV9: 2024-11-02 | AW9: 2024-10-26 | AX9: 2024-10-29 | AY9: 2024-11-01 | AZ9: 2024-10-23 | BA9: 2024-10-27 | BB9: 2024-11-03 | BC9: 2024-11-16 | BD9: 2024-12-30 | BE9: 2024-11-30 | BF9: 2025-01-21 | BG9: 2024-12-07 | BH9: 2025-02-01 | BI9: 2024-12-21 | BK9: 2024-12-26 | BL9: 2024-11-21 | BN9: 2024-12-28 | BO9: 2025-01-02 | BP9: 2025-01-02
A10: 2024-11-16 | B10: 2024-12-05 | C10: 2024-11-14 | D10: 2024-11-23 | E10: 2024-10-26 | F10: 2024-11-28 | H10: 2024-11-30 | I10: 2024-11-14 | J10: 2024-12-19 | K10: 2024-11-28 | L10: 2024-12-05 | N10: 2024-11-19 | O10: 2024-11-30 | P10: 2024-11-14 | Q10: 2024-10-26 | R10: 2024-11-01 | S10: 2024-11-01 | T10: 2024-10-27 | U10: 2024-11-30 | V10: 2024-11-14 | W10: 2024-11-03 | X10: 2025-03-01 | Y10: 2024-10-23 | Z10: 2024-11-17 | AA10: 2024-11-28 | AB10: 2024-12-07 | AC10: 2024-11-03 | AD10: 2024-11-28 | AE10: 2024-11-14 | AF10: 2024-11-30 | AG10: 2024-11-23 | AH10: 2024-11-21 | AI10: 2025-01-16 | AJ10: 2024-12-19 | AK10: 2024-12-01 | AL10: 2024-11-14 | AM10: 2024-11-16 | AN10: 2024-11-16 | AO10: 2024-11-14 | AP10: 2024-11-23 | AQ10: 2024-11-14 | AR10: 2024-11-01 | AS10: 2024-11-16 | AT10: 2024-10-23 | AU10: 2024-11-23 | AV10: 2024-10-25 | AW10: 2024-11-30 | AX10: 2024-11-03 | AY10: 2024-11-16 | AZ10: 2024-10-29 | BA10: 2024-11-03 | BB10: 2024-10-24 | BC10: 2024-11-28 | BD10: 2024-12-17 | BE10: 2024-11-12 | BF10: 2025-01-14 | BG10: 2025-01-09 | BH10: 2025-02-15 | BI10: 2025-02-02 | BK10: 2024-12-28 | BL10: 2024-12-03 | BN10: 2024-12-21 | BO10: 2025-01-09 | BP10: 2025-01-21
A11: 2024-11-23 | B11: 2024-11-26 | C11: 2024-11-21 | D11: 2024-11-16 | E11: 2024-11-30 | F11: 2024-12-07 | H11: 2024-11-24 | I11: 2024-12-26 | J11: 2025-01-05 | K11: 2024-12-05 | L11: 2024-12-01 | N11: 2024-11-26 | O11: 2024-11-14 | P11: 2024-11-21 | Q11: 2024-10-24 | R11: 2024-10-23 | S11: 2024-10-24 | T11: 2024-11-14 | U11: 2024-11-14 | V11: 2024-11-24 | W11: 2024-10-24 | X11: 2025-03-04 | Y11: 2024-11-16 | Z11: 2024-12-03 | AA11: 2024-12-05 | AB11: 2024-12-28 | AC11: 2024-11-30 | AD11: 2024-12-07 | AE11: 2024-11-24 | AF11: 2024-12-07 | AG11: 2024-11-30 | AH11: 2024-11-16 | AI11: 2025-01-23 | AJ11: 2025-01-04 | AK11: 2024-11-03 | AL11: 2024-12-07 | AM11: 2024-11-23 | AN11: 2024-11-23 | AO11: 2025-01-06 | AP11: 2024-11-21 | AQ11: 2024-11-28 | AR11: 2024-11-16 | AS11: 2024-11-30 | AT11: 2024-10-29 | AU11: 2024-12-07 | AV11: 2024-12-07 | AW11: 2024-11-16 | AX11: 2024-10-24 | AY11: 2024-11-23 | AZ11: 2024-11-16 | BA11: 2024-11-23 | BB11: 2024-10-23 | BC11: 2024-11-23 | BD11: 2025-01-02 | BE11: 2024-11-26 | BF11: 2025-01-30 | BG11: 2025-02-01 | BH11: 2025-02-20 | BI11: 2025-02-20 | BK11: 2025-01-09 | BL11: 2024-12-28 | BN11: 2025-01-02 | BO11: 2025-02-20 | BP11: 2025-01-09
A12: 2024-11-14 | B12: 2024-12-28 | C12: 2024-12-22 | D12: 2024-11-24 | E12: 2024-11-14 | F12: 2025-01-02 | H12: 2024-12-26 | I12: 2024-12-21 | J12: 2025-01-16 | K12: 2024-12-01 | L12: 2024-12-21 | N12: 2024-12-05 | O12: 2024-11-21 | P12: 2024-11-28 | Q12: 2024-12-03 | R12: 2024-11-19 | S12: 2024-12-03 | T12: 2024-11-21 | U12: 2024-11-21 | V12: 2024-11-28 | W12: 2024-11-16 | X12: 2025-03-11 | Y12: 2024-11-14 | Z12: 2024-11-21 | AA12: 2024-11-23 | AB12: 2024-12-21 | AC12: 2024-12-22 | AD12: 2024-11-03 | AE12: 2024-12-19 | AF12: 2024-12-30 | AG12: 2024-12-30 | AH12: 2024-12-28 | AI12: 2025-01-11 | AJ12: 2024-12-26 | AK12: 2024-11-14 | AL12: 2025-01-11 | AM12: 2024-11-30 | AN12: 2024-11-30 | AO12: 2024-12-04 | AP12: 2024-12-03 | AQ12: 2024-12-05 | AR12: 2024-11-30 | AS12: 2024-12-22 | AT12: 2024-11-16 | AU12: 2025-01-03 | AV12: 2024-12-30 | AW12: 2024-12-26 | AX12: 2024-12-04 | AY12: 2024-11-30 | AZ12: 2024-11-23 | BA12: 2024-11-30 | BB12: 2024-11-16 | BC12: 2024-12-28 | BD12: 2025-01-06 | BE12: 2024-12-17 | BF12: 2025-02-18 | BG12: 2025-02-13 | BH12: 2025-02-27 | BK12: 2025-01-28 | BL12: 2025-01-06 | BN12: 2024-12-05 | BP12: 2025-01-28
A13: 2024-12-26 | B13: 2024-12-17 | C13: 2024-12-30 | D13: 2024-11-30 | E13: 2024-11-28 | F13: 2025-01-06 | H13: 2024-12-19 | I13: 2025-01-02 | J13: 2025-01-23 | K13: 2024-12-21 | L13: 2025-01-02 | N13: 2024-12-30 | O13: 2024-12-07 | P13: 2024-12-05 | Q13: 2024-11-21 | R13: 2024-11-26 | S13: 2024-11-14 | T13: 2024-12-07 | U13: 2024-12-07 | V13: 2024-12-30 | W13: 2024-11-21 | X13: 2025-03-13 | Y13: 2025-02-02 | Z13: 2024-11-28 | AA13: 2024-12-28 | AB13: 2024-11-26 | AC13: 2024-12-30 | AD13: 2024-12-30 | AE13: 2025-01-02 | AF13: 2025-01-06 | AG13: 2024-12-17 | AH13: 2024-12-19 | AI13: 2025-02-01 | AJ13: 2025-01-09 | AK13: 2024-12-30 | AL13: 2025-01-23 | AM13: 2024-11-28 | AN13: 2024-11-21 | AO13: 2024-12-17 | AP13: 2025-01-02 | AQ13: 2024-12-22 | AR13: 2024-11-28 | AS13: 2025-01-04 | AT13: 2024-11-12 | AU13: 2025-01-02 | AV13: 2024-12-21 | AW13: 2025-01-06 | AX13: 2024-11-26 | AY13: 2025-01-21 | AZ13: 2024-11-21 | BA13: 2024-11-12 | BB13: 2024-11-30 | BC13: 2025-01-02 | BD13: 2025-01-18 | BE13: 2025-01-02 | BF13: 2025-02-27 | BG13: 2025-03-01 | BH13: 2025-03-01 | BL13: 2024-12-17 | BN13: 2025-01-09 | BP13: 2025-02-01
A14: 2024-12-21 | B14: 2024-12-21 | C14: 2025-01-05 | D14: 2024-12-22 | E14: 2024-12-05 | F14: 2025-01-18 | H14: 2025-01-06 | I14: 2025-01-06 | J14: 2025-02-15 | K14: 2025-01-05 | L14: 2025-01-05 | N14: 2024-12-19 | O14: 2024-10-29 | P14: 2024-12-28 | Q14: 2024-12-07 | R14: 2024-12-05 | S14: 2024-11-21 | T14: 2024-12-28 | U14: 2024-10-24 | V14: 2024-12-19 | W14: 2024-11-28 | X14: 2025-03-15 | Y14: 2025-02-11 | Z14: 2024-12-01 | AA14: 2024-12-19 | AB14: 2024-12-26 | AC14: 2024-12-17 | AD14: 2024-12-21 | AE14: 2025-01-09 | AF14: 2024-12-19 | AG14: 2024-12-22 | AH14: 2025-01-09 | AI14: 2025-02-11 | AJ14: 2025-01-02 | AK14: 2024-12-17 | AL14: 2025-01-06 | AM14: 2024-12-26 | AN14: 2024-12-28 | AO14: 2025-01-22 | AP14: 2025-01-06 | AQ14: 2025-01-05 | AR14: 2024-12-07 | AS14: 2025-01-12 | AT14: 2024-11-21 | AU14: 2025-01-21 | AV14: 2025-01-05 | AW14: 2024-11-23 | AX14: 2024-12-26 | AY14: 2025-01-16 | AZ14: 2024-12-28 | BA14: 2024-12-28 | BB14: 2024-11-19 | BC14: 2025-01-09 | BD14: 2025-01-11 | BE14: 2025-01-21 | BF14: 2025-03-04 | BG14: 2025-03-04 | BH14: 2025-03-04 | BL14: 2025-01-22 | BN14: 2025-01-30
A15: 2025-01-05 | B15: 2024-12-26 | C15: 2025-01-18 | D15: 2024-12-19 | E15: 2024-12-26 | F15: 2025-01-11 | H15: 2025-01-11 | I15: 2025-01-21 | J15: 2025-02-22 | K15: 2025-01-11 | L15: 2025-01-11 | N15: 2025-01-04 | O15: 2024-12-19 | P15: 2024-12-30 | Q15: 2024-12-05 | R15: 2024-12-30 | S15: 2024-11-28 | T15: 2024-12-19 | U15: 2024-11-16 | V15: 2025-01-05 | W15: 2024-12-05 | X15: 2025-03-18 | Y15: 2025-02-15 | Z15: 2024-12-30 | AA15: 2025-01-02 | AB15: 2025-01-08 | AC15: 2025-01-04 | AD15: 2025-01-30 | AE15: 2025-01-16 | AF15: 2025-01-16 | AG15: 2025-01-16 | AH15: 2024-12-26 | AI15: 2025-02-15 | AJ15: 2025-01-25 | AK15: 2024-12-21 | AL15: 2025-01-25 | AM15: 2024-12-30 | AN15: 2024-12-27 | AO15: 2025-01-14 | AP15: 2024-12-28 | AQ15: 2025-01-12 | AR15: 2024-12-28 | AS15: 2025-01-30 | AT15: 2024-12-03 | AU15: 2025-01-11 | AV15: 2024-12-17 | AW15: 2024-11-28 | AX15: 2024-12-19 | AY15: 2025-01-18 | AZ15: 2024-12-21 | BA15: 2024-12-17 | BB15: 2024-12-28 | BC15: 2025-01-30 | BD15: 2025-02-04 | BE15: 2025-01-18 | BF15: 2025-03-11 | BG15: 2025-03-08 | BH15: 2025-03-08 | BL15: 2025-01-11 | BN15: 2025-01-18
A16: 2025-01-16 | B16: 2025-01-05 | C16: 2025-01-09 | D16: 2025-01-06 | E16: 2024-12-17 | F16: 2025-01-26 | H16: 2025-01-23 | I16: 2025-01-11 | K16: 2025-01-23 | L16: 2025-01-23 | N16: 2025-01-05 | O16: 2025-01-06 | P16: 2024-12-19 | Q16: 2024-12-30 | R16: 2024-12-17 | S16: 2024-12-30 | T16: 2025-01-04 | U16: 2024-12-28 | V16: 2025-01-11 | W16: 2024-12-28 | X16: 2025-03-22 | Z16: 2024-12-19 | AA16: 2025-01-06 | AB16: 2025-01-04 | AC16: 2024-12-26 | AD16: 2025-01-16 | AE16: 2025-01-30 | AF16: 2025-01-23 | AG16: 2025-01-26 | AH16: 2025-01-28 | AI16: 2025-02-23 | AJ16: 2025-02-02 | AK16: 2025-01-06 | AL16: 2025-02-13 | AM16: 2025-01-04 | AN16: 2025-01-03 | AO16: 2025-01-16 | AP16: 2025-01-11 | AQ16: 2025-01-21 | AR16: 2024-12-21 | AS16: 2025-02-02 | AT16: 2024-12-28 | AU16: 2025-01-04 | AV16: 2025-01-21 | AW16: 2025-01-03 | AX16: 2025-01-02 | AY16: 2025-01-23 | AZ16: 2024-12-27 | BA16: 2025-01-04 | BB16: 2024-12-17 | BC16: 2025-02-02 | BD16: 2025-02-15 | BE16: 2025-01-11 | BF16: 2025-03-13 | BG16: 2025-03-13 | BH16: 2025-03-13 | BL16: 2025-01-29 | BN16: 2025-02-13
A17: 2025-01-23 | B17: 2025-02-01 | C17: 2025-01-26 | D17: 2025-01-05 | E17: 2025-01-05 | F17: 2025-02-15 | H17: 2025-02-01 | I17: 2025-01-12 | K17: 2025-02-01 | L17: 2025-01-06 | N17: 2025-01-28 | O17: 2025-01-09 | P17: 2025-01-06 | Q17: 2024-12-19 | R17: 2025-01-04 | S17: 2024-12-17 | T17: 2025-01-09 | U17: 2024-12-17 | V17: 2025-01-16 | W17: 2024-12-30 | X17: 2025-03-29 | Z17: 2025-01-06 | AA17: 2025-01-16 | AB17: 2025-01-28 | AC17: 2025-01-09 | AD17: 2025-02-04 | AE17: 2025-02-22 | AF17: 2025-01-11 | AG17: 2025-02-04 | AH17: 2025-01-11 | AJ17: 2025-02-13 | AK17: 2025-01-04 | AL17: 2025-02-20 | AM17: 2025-01-18 | AN17: 2025-01-09 | AO17: 2025-01-08 | AP17: 2025-01-30 | AQ17: 2025-01-28 | AR17: 2024-12-27 | AS17: 2025-02-11 | AT17: 2024-12-19 | AU17: 2025-02-04 | AV17: 2025-01-11 | AW17: 2024-12-07 | AX17: 2025-01-06 | AY17: 2025-01-26 | AZ17: 2025-01-06 | BA17: 2024-12-04 | BB17: 2025-01-02 | BC17: 2025-02-13 | BD17: 2025-02-20 | BE17: 2025-01-30 | BF17: 2025-03-16 | BG17: 2025-03-15 | BH17: 2025-03-18 | BL17: 2025-02-05
A18: 2025-01-30 | B18: 2025-02-11 | C18: 2025-02-01 | D18: 2025-01-18 | E18: 2025-01-23 | F18: 2025-02-22 | H18: 2025-02-15 | I18: 2025-01-26 | K18: 2025-02-11 | L18: 2025-02-11 | N18: 2025-01-26 | O18: 2025-01-29 | P18: 2025-01-02 | Q18: 2025-01-06 | R18: 2024-12-19 | S18: 2024-12-21 | T18: 2025-01-16 | U18: 2024-12-21 | V18: 2025-01-23 | W18: 2024-12-19 | X18: 2025-04-01 | Z18: 2025-01-16 | AA18: 2025-01-09 | AB18: 2025-01-18 | AC18: 2025-01-23 | AD18: 2025-02-13 | AE18: 2025-03-04 | AF18: 2025-02-01 | AG18: 2025-02-13 | AH18: 2025-01-26 | AK18: 2025-01-18 | AL18: 2025-02-22 | AM18: 2025-01-11 | AN18: 2025-01-16 | AO18: 2025-01-30 | AP18: 2025-01-16 | AQ18: 2025-02-11 | AR18: 2024-11-23 | AS18: 2025-02-18 | AT18: 2025-01-02 | AU18: 2025-03-01 | AV18: 2025-02-02 | AW18: 2025-01-18 | AX18: 2025-01-14 | AY18: 2025-02-11 | AZ18: 2025-01-22 | BA18: 2025-01-22 | BB18: 2024-12-04 | BC18: 2025-02-18 | BD18: 2025-02-25 | BE18: 2025-02-18 | BH18: 2025-03-25 | BL18: 2025-02-11
A19: 2025-01-12 | B19: 2025-02-20 | C19: 2025-02-15 | D19: 2025-01-25 | E19: 2025-01-30 | F19: 2025-03-01 | H19: 2025-02-22 | I19: 2025-02-01 | L19: 2025-02-18 | N19: 2025-02-11 | O19: 2025-02-11 | P19: 2025-01-11 | Q19: 2025-01-16 | R19: 2025-01-11 | S19: 2025-01-02 | T19: 2025-01-30 | U19: 2025-01-06 | V19: 2025-01-04 | W19: 2025-01-09 | X19: 2025-04-13 | Z19: 2025-01-29 | AA19: 2025-02-04 | AB19: 2025-02-04 | AC19: 2025-01-30 | AD19: 2025-02-18 | AE19: 2025-03-11 | AF19: 2025-02-11 | AG19: 2025-02-15 | AH19: 2025-02-01 | AK19: 2025-01-26 | AL19: 2025-02-18 | AM19: 2025-01-26 | AN19: 2025-01-23 | AO19: 2025-01-18 | AP19: 2025-02-11 | AQ19: 2025-02-18 | AR19: 2025-01-03 | AS19: 2025-02-13 | AT19: 2025-01-06 | AU19: 2025-03-04 | AV19: 2025-02-25 | AW19: 2025-01-11 | AX19: 2025-01-23 | AY19: 2025-02-20 | AZ19: 2025-01-11 | BA19: 2025-01-11 | BB19: 2025-01-08 | BC19: 2025-02-22 | BD19: 2025-02-27 | BE19: 2025-02-22 | BH19: 2025-04-01 | BL19: 2025-02-20
A20: 2025-01-25 | B20: 2025-03-01 | C20: 2025-02-20 | D20: 2025-02-01 | E20: 2025-02-11 | H20: 2025-02-27 | I20: 2025-02-15 | L20: 2025-02-22 | N20: 2025-02-15 | O20: 2025-02-15 | P20: 2025-01-16 | Q20: 2025-02-04 | R20: 2025-01-18 | S20: 2024-12-07 | T20: 2025-02-11 | U20: 2024-12-30 | V20: 2025-01-30 | W20: 2025-01-16 | X20: 2025-04-05 | Z20: 2025-01-30 | AA20: 2025-02-13 | AB20: 2025-02-13 | AC20: 2025-01-28 | AD20: 2025-03-01 | AE20: 2025-03-15 | AF20: 2025-02-23 | AG20: 2025-02-20 | AH20: 2025-02-13 | AK20: 2025-02-04 | AL20: 2025-02-27 | AM20: 2025-02-01 | AN20: 2025-01-18 | AO20: 2025-02-01 | AP20: 2025-02-20 | AQ20: 2025-02-13 | AR20: 2025-01-11 | AS20: 2025-02-22 | AT20: 2025-01-14 | AU20: 2025-03-08 | AW20: 2025-02-04 | AX20: 2025-01-30 | AY20: 2025-02-27 | AZ20: 2025-01-18 | BA20: 2024-12-27 | BB20: 2025-01-16 | BC20: 2025-03-04 | BD20: 2025-03-04 | BE20: 2025-02-27 | BH20: 2025-04-08 | BL20: 2025-02-22
A21: 2025-02-15 | C21: 2025-02-22 | D21: 2025-02-15 | E21: 2025-03-04 | I21: 2025-02-20 | N21: 2025-02-20 | O21: 2025-02-18 | P21: 2025-01-29 | Q21: 2025-02-02 | R21: 2024-12-28 | S21: 2025-01-08 | T21: 2025-02-15 | U21: 2025-01-11 | V21: 2025-01-26 | W21: 2025-01-26 | Z21: 2025-02-11 | AA21: 2025-02-20 | AB21: 2025-02-18 | AC21: 2025-02-15 | AG21: 2025-02-18 | AH21: 2025-02-15 | AK21: 2025-02-13 | AL21: 2025-03-01 | AM21: 2025-02-11 | AN21: 2025-01-25 | AO21: 2025-02-05 | AP21: 2025-02-22 | AR21: 2025-01-06 | AS21: 2025-03-08 | AT21: 2025-01-23 | AU21: 2025-03-13 | AW21: 2025-02-15 | AX21: 2025-02-11 | AZ21: 2025-02-01 | BA21: 2025-01-30 | BB21: 2025-01-25 | BC21: 2025-03-08 | BD21: 2025-03-08 | BE21: 2025-03-01 | BH21: 2025-04-10
A22: 2025-02-18 | C22: 2025-02-27 | D22: 2025-02-20 | E22: 2025-03-01 | I22: 2025-02-22 | N22: 2025-02-25 | O22: 2025-02-27 | P22: 2025-01-26 | Q22: 2025-02-13 | R22: 2025-02-04 | S22: 2025-01-16 | T22: 2025-02-22 | U22: 2025-01-23 | V22: 2025-02-13 | W22: 2025-02-13 | Z22: 2025-02-15 | AA22: 2025-03-01 | AB22: 2025-02-25 | AC22: 2025-02-18 | AG22: 2025-03-01 | AH22: 2025-02-20 | AK22: 2025-02-18 | AL22: 2025-03-08 | AM22: 2025-02-15 | AN22: 2025-01-28 | AO22: 2025-02-11 | AR22: 2025-01-25 | AT22: 2025-01-30 | AU22: 2025-03-18 | AW22: 2025-02-20 | AX22: 2025-02-20 | AZ22: 2025-02-11 | BA22: 2025-01-18 | BB22: 2025-02-05 | BC22: 2025-03-11 | BD22: 2025-03-13
A23: 2025-03-04 | C23: 2025-03-01 | D23: 2025-02-27 | E23: 2025-03-11 | I23: 2025-02-18 | P23: 2025-02-11 | Q23: 2025-02-23 | R23: 2025-02-02 | S23: 2025-01-25 | T23: 2025-03-04 | U23: 2025-01-30 | V23: 2025-02-18 | W23: 2025-02-20 | Z23: 2025-02-20 | AB23: 2025-03-08 | AC23: 2025-02-25 | AG23: 2025-03-11 | AH23: 2025-03-04 | AK23: 2025-02-20 | AL23: 2025-03-11 | AM23: 2025-02-27 | AN23: 2025-02-22 | AO23: 2025-02-18 | AR23: 2025-02-01 | AT23: 2025-02-05 | AU23: 2025-03-25 | AX23: 2025-02-22 | AZ23: 2025-02-22 | BA23: 2025-02-11 | BB23: 2025-02-11 | BD23: 2025-03-18
A24: 2025-03-11 | C24: 2025-03-08 | E24: 2025-03-15 | I24: 2025-02-27 | P24: 2025-02-15 | Q24: 2025-02-18 | R24: 2025-02-13 | S24: 2025-02-04 | U24: 2025-02-11 | V24: 2025-03-01 | W24: 2025-02-27 | Z24: 2025-03-04 | AB24: 2025-03-13 | AG24: 2025-03-13 | AH24: 2025-03-08 | AK24: 2025-02-25 | AL24: 2025-03-16 | AM24: 2025-03-08 | AN24: 2025-02-20 | AO24: 2025-02-22 | AR24: 2025-02-15 | AT24: 2025-02-13 | AU24: 2025-04-01 | AX24: 2025-02-18 | AZ24: 2025-02-20 | BA24: 2025-02-18 | BB24: 2025-02-18 | BD24: 2025-03-29
A25: 2025-03-15 | C25: 2025-03-13 | E25: 2025-03-18 | I25: 2025-03-01 | P25: 2025-02-22 | R25: 2025-02-18 | S25: 2025-02-13 | U25: 2025-02-15 | W25: 2025-03-01 | AB25: 2025-03-18 | AG25: 2025-03-15 | AK25: 2025-02-27 | AL25: 2025-03-22 | AN25: 2025-03-04 | AO25: 2025-03-08 | AR25: 2025-02-22 | AT25: 2025-02-18 | AU25: 2025-04-08 | AX25: 2025-02-27 | AZ25: 2025-02-13 | BA25: 2025-02-22 | BB25: 2025-02-22
A26: 2025-03-20 | C26: 2025-03-20 | E26: 2025-03-25 | I26: 2025-03-08 | P26: 2025-02-27 | R26: 2025-02-23 | S26: 2025-02-18 | U26: 2025-02-22 | W26: 2025-03-13 | AK26: 2025-03-11 | AL26: 2025-03-27 | AN26: 2025-03-11 | AO26: 2025-03-11 | AR26: 2025-03-04 | AT26: 2025-02-22 | AU26: 2025-04-15 | AX26: 2025-03-11 | AZ26: 2025-02-25 | BA26: 2025-02-27 | BB26: 2025-03-01
A27: 2025-03-27 | C27: 2025-03-25 | E27: 2025-03-29 | I27: 2025-03-13 | R27: 2025-02-27 | S27: 2025-02-20 | U27: 2025-02-27 | W27: 2025-03-15 | AK27: 2025-03-13 | AL27: 2025-04-01 | AN27: 2025-03-16 | AO27: 2025-03-18 | AR27: 2025-03-11 | AT27: 2025-02-25 | AX27: 2025-03-13 | AZ27: 2025-03-01 | BA27: 2025-03-01
A28: 2025-03-29 | C28: 2025-03-29 | I28: 2025-03-20 | R28: 2025-03-01 | S28: 2025-02-27 | W28: 2025-03-08 | AK28: 2025-03-15 | AN28: 2025-03-25 | AR28: 2025-03-16 | AX28: 2025-03-15 | AZ28: 2025-03-08 | BA28: 2025-03-13
A29: 2025-04-01 | C29: 2025-04-08 | I29: 2025-03-27 | R29: 2025-03-04 | S29: 2025-03-08 | AN29: 2025-03-27 | AR29: 2025-03-25 | AX29: 2025-03-22 | AZ29: 2025-03-11 | BA29: 2025-03-15
A30: 2025-04-10 | C30: 2025-04-10 | I30: 2025-04-01 | R30: 2025-03-11 | S30: 2025-03-11 | AN30: 2025-03-29 | AR30: 2025-03-29 | AX30: 2025-03-29 | AZ30: 2025-03-18 | BA30: 2025-03-22
A31: 2025-04-15 | I31: 2025-04-08 | R31: 2025-03-13 | S31: 2025-03-13 | AN31: 2025-04-10 | AX31: 2025-04-01 | AZ31: 2025-03-27 | BA31: 2025-03-27
I32: 2025-04-15 | R32: 2025-03-15 | S32: 2025-03-15 | AN32: 2025-04-15 | AX32: 2025-04-13 | BA32: 2025-04-01
R33: 2025-03-25 | S33: 2025-03-20 | AX33: 2025-04-05 | BA33: 2025-04-13
R34: 2025-03-27 | S34: 2025-03-25 | BA34: 2025-04-05
R35: 2025-04-13 | S35: 2025-03-27
R36: 2025-04-05

Sheet AHL_DAT
A3: 2024-09-21 | B3: 2024-09-22 | C3: 2024-09-24 | D3: 2024-09-26 | E3: 2024-09-29 | F3: 2024-10-05 | G3: 2024-09-28 | H3: 2024-10-03 | I3: 2024-10-08 | J3: 2024-10-09 | K3: 2024-10-10 | L3: 2024-10-12 | M3: 2024-10-16 | N3: 2024-10-17 | O3: 2024-10-06 | P3: 2024-10-19 | Q3: 2024-10-20 | R3: 2024-10-23 | S3: 2024-10-25 | T3: 2024-10-26 | U3: 2024-10-27 | V3: 2024-10-29 | W3: 2024-11-01 | X3: 2024-11-02 | Y3: 2024-11-03 | Z3: 2024-10-24 | AA3: 2024-10-31 | AB3: 2024-11-16 | AC3: 2024-11-17 | AD3: 2024-11-23 | AE3: 2024-11-30 | AF3: 2024-12-03 | AG3: 2024-12-04 | AH3: 2024-11-12 | AI3: 2024-11-14 | AJ3: 2024-11-19 | AK3: 2024-11-21 | AL3: 2024-11-26 | AM3: 2024-11-28 | AN3: 2024-12-05 | AO3: 2024-12-07 | AP3: 2024-12-01 | AQ3: 2024-11-24 | AR3: 2024-12-22 | AS3: 2024-12-26 | AT3: 2024-12-28 | AU3: 2024-12-30 | AV3: 2024-12-17 | AW3: 2024-12-19 | AX3: 2024-12-21 | AY3: 2024-12-27 | AZ3: 2025-01-02 | BA3: 2025-01-04 | BB3: 2025-01-05 | BC3: 2025-01-06 | BD3: 2025-01-03 | BE3: 2025-01-08 | BF3: 2025-01-12 | BG3: 2025-01-18 | BH3: 2025-01-21 | BI3: 2025-01-22 | BJ3: 2025-01-09 | BK3: 2025-01-11 | BL3: 2025-01-14 | BM3: 2025-01-16 | BN3: 2025-01-23 | BO3: 2025-01-25 | BP3: 2025-01-26 | BQ3: 2025-01-28 | BR3: 2025-01-29 | BS3: 2025-01-30 | BT3: 2025-02-02 | BU3: 2025-02-04 | BV3: 2025-02-01 | BW3: 2025-02-05 | BX3: 2025-02-11 | BY3: 2025-02-13 | BZ3: 2025-02-15 | CA3: 2025-02-18 | CB3: 2025-02-20 | CC3: 2025-02-22 | CD3: 2025-02-23 | CE3: 2025-02-25 | CF3: 2025-02-27 | CG3: 2025-03-01 | CH3: 2025-03-04 | CI3: 2025-03-08 | CJ3: 2025-03-11 | CK3: 2025-03-13 | CL3: 2025-03-15 | CM3: 2025-03-16 | CN3: 2025-03-18 | CO3: 2025-03-20 | CP3: 2025-03-22 | CQ3: 2025-03-25 | CR3: 2025-03-27 | CS3: 2025-03-29 | CT3: 2025-04-01 | CU3: 2025-04-08 | CV3: 2025-04-13 | CW3: 2025-04-05 | CX3: 2025-04-10 | CY3: 2025-04-15
A4: BenvegnuAn | B4: MetzingerFi | C4: KainbergerJu | D4: BajtMi | E4: MeixnerSe | F4: LazzeriAl | G4: MoschenAn | H4: RuetzMa | I4: RuetzMa | J4: HolzerTo | K4: BulovecMi | L4: BajtMi | M4: OrelSt | N4: HolzerTo | O4: OrelSt | P4: RuetzMa | Q4: BajtMi | R4: MeixnerSe | S4: BenvegnuAn | T4: BrockAd | U4: LazzeriAl | V4: HlavatyAl | W4: OrelSt | X4: BrockAd | Y4: PinieOm | Z4: LesniakBo | AA4: GiacomozziFe | AB4: SpiegelSe | AC4: MetzingerFi | AD4: BrockAd | AE4: GiacomozziFe | AF4: EggerTh | AG4: HolzerTo | AH4: HolzerTo | AI4: KainbergerJu | AJ4: BenvegnuAn | AK4: HlavatyAl | AL4: BenvegnuAn | AM4: BrockAd | AN4: HlavatyAl | AO4: MoschenAn | AP4: MetzingerFi | AQ4: LesniakBo | AR4: LehnerMo | AS4: BajtMi | AT4: BrockAd | AU4: BenvegnuAn | AV4: LazzeriAl | AW4: LesniakBo | AX4: BajtMi | AY4: HolzerTo | AZ4: HlavatyAl | BA4: HolzerTo | BB4: BenvegnuAn | BC4: LesniakBo | BD4: OrelSt | BE4: GiacomozziFe | BF4: MeixnerSe | BG4: BulovecMi | BH4: LehnerMo | BI4: HolzerTo | BJ4: LehnerMo | BK4: LegaSi | BL4: Huber rRe | BM4: SnojTa | BN4: MetzingerFi | BO4: EggerTh | BP4: LebenJa | BQ4: LehnerMo | BR4: SoraperraSi | BS4: BrockAd | BT4: EggerTh | BU4: HlavatyAl | BV4: BajtMi | BW4: Huber rRe | BX4: BajtMi | BY4: BrockAd | BZ4: MoschenAn | CA4: BrockAd | CB4: BajtMi | CC4: BrockAd | CD4: LazzeriAl | CE4: BenvegnuAn | CF4: LesniakBo | CG4: KainbergerJu | CH4: OrelSt | CI4: BulovecMi | CJ4: BrockAd | CK4: LazzeriAl | CL4: HolzerTo | CM4: KainbergerJu | CN4: GiacomozziFe | CO4: BulovecMi | CP4: HolzerTo | CQ4: OrelSt | CR4: KainbergerJu | CS4: OrelSt | CT4: KainbergerJu | CU4: BulovecMi | CV4: HolzerTo | CW4: HolzerTo | CX4: BulovecMi | CY4: SnojTa
A5: SoraperraSi | B5: StefenelliFe | C5: VoicanCh | D5: BulovecMi | E5: VoicanCh | F5: MoschenAn | G5: SoraperraSi | H5: SpiegelSe | I5: StefenelliFe | J5: SpiegelSe | K5: MeixnerSe | L5: WenuschHe | M5: StefenelliFe | N5: KainbergerJu | O5: VirtaTu | P5: WidmannFl | Q5: BenvegnuAn | R5: RuetzMa | S5: WenuschHe | T5: SternatCh | U5: LebenJa | V5: KainbergerJu | W5: WidmannFl | X5: WenuschHe | Y5: VirtaTu | Z5: SnojTa | AA5: PirasAn | AB5: VoicanCh | AC5: StefenelliFe | AD5: SnojTa | AE5: SoraperraSi | AF5: StefenelliFe | AG5: Huber rRe | AH5: RuetzMa | AI5: LegaSi | AJ5: LazzeriAl | AK5: WenuschHe | AL5: LazzeriAl | AM5: MeixnerSe | AN5: MeixnerSe | AO5: SoraperraSi | AP5: StefenelliFe | AQ5: RivisFe | AR5: MeixnerSe | AS5: LehnerMo | AT5: MoidlDa | AU5: MoschenAn | AV5: PinieOm | AW5: UnterwegerDo | AX5: OrelSt | AY5: OrelSt | AZ5: VoicanCh | BA5: VoicanCh | BB5: SnojTa | BC5: OrelSt | BD5: VoicanCh | BE5: Huber rRe | BF5: SnojTa | BG5: GiacomozziFe | BH5: WidmannFl | BI5: Huber rRe | BJ5: MoidlDa | BK5: MoschenAn | BL5: RuetzMa | BM5: WidmannFl | BN5: SnojTa | BO5: SnojTa | BP5: WidmannFl | BQ5: MeixnerSe | BR5: StefenelliFe | BS5: SnojTa | BT5: LazzeriAl | BU5: VoicanCh | BV5: LegaSi | BW5: RuetzMa | BX5: MetzingerFi | BY5: KainbergerJu | BZ5: PinieOm | CA5: MeixnerSe | CB5: BulovecMi | CC5: RuetzMa | CD5: LegaSi | CE5: HlavatyAl | CF5: SoraperraSi | CG5: VoicanCh | CH5: SnojTa | CI5: KainbergerJu | CJ5: Huber rRe | CK5: VoicanCh | CL5: VirtaTu | CM5: OrelSt | CN5: Huber rRe | CO5: SnojTa | CP5: KainbergerJu | CQ5: VoicanCh | CR5: SnojTa | CS5: SnojTa | CT5: VoicanCh | CU5: VoicanCh | CV5: LazzeriAl | CW5: LazzeriAl | CX5: SnojTa | CY5: VoicanCh
A6: FecchioFe | B6: AbeltinoSi | C6: LegatKo | D6: ArlicMa | E6: LegatKo | F6: GrisentiLu | G6: IlmerNo | H6: SeewaldJe | I6: AbeltinoSi | J6: JägerRi | K6: MiklicGr | L6: PreiserJu | M6: ScalzeriAl | N6: DivisDo | O6: StrimitzerDa | P6: RinkerDa | Q6: CristeliMa | R6: MattheyPh | S6: BrondiPa | T6: RivisAn | U6: FormaioniTh | V6: EislCh | W6: TelesklavFa | X6: LegatKo | Y6: DivisDo | Z6: JavornikBl | AA6: PaceJa | AB6: PreiserJu | AC6: CristeliMa | AD6: ArlicMa | AE6: AbeltinoSi | AF6: BrondiPa | AG6: DivisDo | AH6: JägerRi | AI6: CristeliMa | AJ6: DivisDo | AK6: EislCh | AL6: RinkerDa | AM6: PreiserJu | AN6: EislCh | AO6: CusinFe | AP6: CristeliMa | AQ6: ArlicMa | AR6: MattheyPh | AS6: MarkizetiGr | AT6: FecchioFe | AU6: BrondiPa | AV6: AbeltinoSi | AW6: ArlicMa | AX6: EislCh | AY6: StrimitzerDa | AZ6: EislCh | BA6: TelesklavFa | BB6: ArlicMa | BC6: ArlicMa | BD6: PreiserJu | BE6: BrondiPa | BF6: JeramFi | BG6: ArlicMa | BH6: SeewaldJe | BI6: JägerRi | BJ6: MattheyPh | BK6: CusinFe | BL6: RinkerDa | BM6: JavornikBl | BN6: KnezRo | BO6: ArlicMa | BP6: FecchioFe | BQ6: MattheyPh | BR6: FecchioFe | BS6: MarkizetiGr | BT6: GrisentiLu | BU6: PreiserJu | BV6: CusinFe | BW6: DivisDo | BX6: KnezRo | BY6: EislCh | BZ6: AbeltinoSi | CA6: KnezRo | CB6: ArlicMa | CC6: RinkerDa | CD6: CusinFe | CE6: AbeltinoSi | CF6: ArlicMa | CG6: MoidlMa | CH6: MarkizetiGr | CI6: JeramFi | CJ6: RinkerDa | CK6: FleischmannLu | CL6: BrondiPa | CM6: WuchererGe | CN6: FleischmannLu | CO6: BrondiPa | CP6: FleischmannLu | CQ6: WeissAl | CR6: JeramFi | CS6: FleischmannLu | CT6: RinkerDa | CU6: JeramFi | CV6: FleischmannLu | CW6: FleischmannLu | CX6: WeissAl | CY6: JeramFi
A7: GrisentiLu | B7: ScalzeriAl | C7: PreiserJu | D7: MarkizetiGr | E7: PreiserJu | F7: RivisAn | G7: RivisAn | H7: ZacherlPa | I7: RinkerDa | J7: SeewaldJe | K7: TelesklavFa | L7: RinkerDa | M7: WuchererGe | N7: FecchioFe | O7: WuchererGe | P7: TelesklavFa | Q7: MarkizetiGr | R7: StrimitzerDa | S7: LegatKo | T7: WendnerMa | U7: JeramFi | V7: PreiserJu | W7: WuchererGe | X7: PreiserJu | Y7: JägerRi | Z7: MiklicGr | AA7: ScalzeriAl | AB7: WeissAl | AC7: KnezRo | AD7: TelesklavFa | AE7: CusinFe | AF7: GrisentiLu | AG7: RinkerDa | AH7: SeewaldJe | AI7: ZacherlPa | AJ7: JägerRi | AK7: WuchererGe | AL7: SeewaldJe | AM7: ZacherlPa | AN7: WeissAl | AO7: FormaioniTh | AP7: KnezRo | AQ7: RivisAn | AR7: WendnerMa | AS7: MattheyPh | AT7: MattheyPh | AU7: WeissAl | AV7: BrondiPa | AW7: JavornikBl | AX7: StrimitzerDa | AY7: WuchererGe | AZ7: RinkerDa | BA7: WendnerMa | BB7: RivisAn | BC7: KnezRo | BD7: WuchererGe | BE7: DivisDo | BF7: WendnerMa | BG7: CristeliMa | BH7: ZacherlPa | BI7: StrimitzerDa | BJ7: MoidlMa | BK7: StrimitzerDa | BL7: ZacherlPa | BM7: WuchererGe | BN7: MarkizetiGr | BO7: BrondiPa | BP7: TelesklavFa | BQ7: WuchererGe | BR7: JägerRi | BS7: WendnerMa | BT7: IlmerNo | BU7: WeissAl | BV7: PaceJa | BW7: JägerRi | BX7: MarkizetiGr | BY7: WendnerMa | BZ7: FecchioFe | CA7: WendnerMa | CB7: JeramFi | CC7: WendnerMa | CD7: GrisentiLu | CE7: LegatKo | CF7: BrondiPa | CG7: WeissAl | CH7: WuchererGe | CI7: TelesklavFa | CJ7: StrimitzerDa | CK7: WeissAl | CL7: FleischmannLu | CM7: ZacherlPa | CN7: StrimitzerDa | CO7: JeramFi | CP7: RinkerDa | CQ7: WuchererGe | CR7: WuchererGe | CS7: WuchererGe | CT7: WeissAl | CU7: WeissAl | CV7: RinkerDa | CW7: RinkerDa | CX7: WuchererGe | CY7: WuchererGe
A8: LazzeriAl | D8: HuberRe | F8: LebenJa | G8: LesniakBo | H8: HolzerTo | K8: KainbergerJu | L8: MetzingerFi | N8: BrockAd | P8: PiragicTr | R8: HuberRe | T8: SnojTa | U8: EggerTh | V8: Huber rRe | W8: StefenelliFe | Y8: MeixnerSe | Z8: SoraperraSi | AB8: BrockAd | AD8: EggerTh | AE8: MoschenAn | AF8: RuetzMa | AI8: MeixnerSe | AK8: GiacomozziFe | AL8: BajtMi | AM8: LebenJa | AN8: BenvegnuAn | AO8: OrelSt | AR8: BulovecMi | AS8: LesniakBo | AT8: LazzeriAl | AU8: BulovecMi | AV8: HolzerTo | AW8: EggerTh | AX8: MoschenAn | AZ8: LehnerMo | BA8: BenvegnuAn | BB8: BajtMi | BC8: Huber rRe | BG8: HolzerTo | BH8: MeixnerSe | BJ8: BrockAd | BK8: HolzerTo | BM8: PinieOm | BN8: KainbergerJu | BO8: KainbergerJu | BP8: BulovecMi | BQ8: BenvegnuAn | BS8: HolzerTo | BT8: BrockAd | BU8: GiacomozziFe | BV8: Huber rRe | BX8: MeixnerSe | BY8: EggerTh | BZ8: HlavatyAl | CA8: HolzerTo | CB8: HlavatyAl | CC8: LebenJa | CE8: GiacomozziFe | CF8: MoschenAn | CG8: BulovecMi | CH8: RivisFe | CI8: GiacomozziFe | CJ8: KainbergerJu | CK8: BulovecMi | CL8: PinieOm | CN8: HlavatyAl | CQ8: BulovecMi | CR8: HolzerTo | CS8: BulovecMi | CT8: HolzerTo
A9: SpiegelSe | D9: MeixnerSe | F9: WidmannFl | G9: SnojTa | H9: HuberRe | K9: VoicanCh | L9: VoicanCh | N9: MeixnerSe | P9: PirasAn | R9: LazzeriAl | T9: WidmannFl | U9: HolzerTo | V9: MoschenAn | W9: VirtaTu | Y9: OrelSt | Z9: VirtaTu | AB9: OrelSt | AD9: PinieOm | AE9: PinieOm | AF9: SpiegelSe | AI9: MoschenAn | AK9: RuetzMa | AL9: GiacomozziFe | AM9: OrelSt | AN9: VirtaTu | AO9: VoicanCh | AR9: PinieOm | AS9: UnterwegerDo | AT9: OrelSt | AU9: HlavatyAl | AV9: Huber rRe | AW9: StefenelliFe | AX9: SnojTa | AZ9: MoidlDa | BA9: LazzeriAl | BB9: BulovecMi | BC9: LegaSi | BG9: Huber rRe | BH9: VoicanCh | BJ9: BulovecMi | BK9: SpiegelSe | BM9: StefenelliFe | BN9: RuetzMa | BO9: OrelSt | BP9: VirtaTu | BQ9: GiacomozziFe | BS9: SpiegelSe | BT9: WenuschHe | BU9: PinieOm | BV9: LesniakBo | BX9: WidmannFl | BY9: LazzeriAl | BZ9: LebenJa | CA9: KainbergerJu | CB9: WenuschHe | CC9: LesniakBo | CE9: RuetzMa | CF9: WidmannFl | CG9: LazzeriAl | CH9: StefenelliFe | CI9: VirtaTu | CJ9: PinieOm | CK9: GiacomozziFe | CL9: SnojTa | CN9: VoicanCh | CQ9: LazzeriAl | CR9: LazzeriAl | CS9: HlavatyAl | CT9: SnojTa
A10: BrondiPa | D10: StrimitzerDa | F10: LegatKo | G10: JeramFi | H10: DivisDo | K10: LegatKo | L10: KnezRo | N10: RinkerDa | P10: CristeliMa | R10: DivisDo | T10: ArlicMa | U10: CusinFe | V10: IlmerNo | W10: BrondiPa | Y10: JeramFi | Z10: CusinFe | AB10: WendnerMa | AD10: PaceJa | AE10: PreiserJu | AF10: EislCh | AI10: IlmerNo | AK10: BrondiPa | AL10: JavornikBl | AM10: MarkizetiGr | AN10: FecchioFe | AO10: LegatKo | AR10: AbeltinoSi | AS10: JeramFi | AT10: EislCh | AU10: LegatKo | AV10: DivisDo | AW10: FecchioFe | AX10: BrondiPa | AZ10: SeewaldJe | BA10: FormaioniTh | BB10: JavornikBl | BC10: CusinFe | BG10: EislCh | BH10: JeramFi | BJ10: EislCh | BK10: JägerRi | BM10: BrondiPa | BN10: AbeltinoSi | BO10: DivisDo | BP10: JeramFi | BQ10: AbeltinoSi | BS10: RinkerDa | BT10: LegatKo | BU10: GrisentiLu | BV10: ArlicMa | BX10: TelesklavFa | BY10: CristeliMa | BZ10: PreiserJu | CA10: DivisDo | CB10: PreiserJu | CC10: JavornikBl | CE10: CristeliMa | CF10: FecchioFe | CG10: JeramFi | CH10: FormaioniTh | CI10: BrondiPa | CJ10: BrondiPa | CK10: CristeliMa | CL10: CristeliMa | CN10: MarkizetiGr | CQ10: BrondiPa | CR10: BrondiPa | CS10: MarkizetiGr | CT10: FleischmannLu
A11: FormaioniTh | D11: TelesklavFa | F11: MiklicGr | G11: RinkerDa | H11: StrimitzerDa | K11: MoidlMa | L11: WendnerMa | N11: SeewaldJe | P11: FecchioFe | R11: IlmerNo | T11: TelesklavFa | U11: JägerRi | V11: StrimitzerDa | W11: PaceJa | Y11: WendnerMa | Z11: PaceJa | AB11: WuchererGe | AD11: ScalzeriAl | AE11: WendnerMa | AF11: JägerRi | AI11: MoidlMa | AK11: StrimitzerDa | AL11: PaceJa | AM11: TelesklavFa | AN11: PaceJa | AO11: PreiserJu | AR11: ArlicMa | AS11: TelesklavFa | AT11: WuchererGe | AU11: TelesklavFa | AV11: JägerRi | AW11: PaceJa | AX11: JeramFi | AZ11: ZacherlPa | BA11: RivisAn | BB11: MarkizetiGr | BC11: RinkerDa | BG11: StrimitzerDa | BH11: LegatKo | BJ11: WuchererGe | BK11: RivisAn | BM11: GrisentiLu | BN11: RinkerDa | BO11: WuchererGe | BP11: PaceJa | BQ11: PaceJa | BS11: SeewaldJe | BT11: WendnerMa | BU11: ScalzeriAl | BV11: StrimitzerDa | BX11: WendnerMa | BY11: GrisentiLu | BZ11: WeissAl | CA11: RinkerDa | CB11: WeissAl | CC11: KnezRo | CE11: StrimitzerDa | CF11: TelesklavFa | CG11: MarkizetiGr | CH11: PaceJa | CI11: StrimitzerDa | CJ11: ZacherlPa | CK11: JeramFi | CL11: MarkizetiGr | CN11: WeissAl | CQ11: MarkizetiGr | CR11: StrimitzerDa | CS11: RinkerDa | CT11: JeramFi
A12: OrelSt | D12: PirasAn | F12: BajtMi | G12: MetzingerFi | H12: PinieOm | K12: PirasAn | L12: BenvegnuAn | N12: RivisFe | P12: HuberRe | T12: MetzingerFi | V12: OrelSt | W12: BajtMi | Y12: BulovecMi | Z12: MoidlDa | AB12: MoschenAn | AD12: VoicanCh | AE12: LesniakBo | AI12: BulovecMi | AK12: BulovecMi | AM12: EggerTh | AN12: BajtMi | AO12: GiacomozziFe | AS12: SnojTa | AT12: GiacomozziFe | AU12: LazzeriAl | AV12: BajtMi | AW12: LazzeriAl | AX12: MetzingerFi | AZ12: EggerTh | BA12: EggerTh | BB12: MeixnerSe | BC12: SoraperraSi | BG12: HlavatyAl | BJ12: EggerTh | BK12: HlavatyAl | BM12: PirasAn | BN12: LesniakBo | BP12: BenvegnuAn | BS12: Huber rRe | BU12: LazzeriAl | BV12: BulovecMi | BX12: HolzerTo | BY12: PirasAn | BZ12: BulovecMi | CA12: Huber rRe | CB12: MoidlDa | CC12: HolzerTo | CF12: HolzerTo | CG12: PinieOm | CH12: BrockAd | CI12: BrockAd | CJ12: OrelSt | CK12: HlavatyAl | CL12: LazzeriAl
A13: WidmannFl | D13: RivisFe | F13: LesniakBo | G13: WidmannFl | H13: PirasAn | K13: SoraperraSi | L13: MoschenAn | N13: SoraperraSi | P13: MoschenAn | T13: PinieOm | V13: VoicanCh | W13: MoidlDa | Y13: KainbergerJu | Z13: SpiegelSe | AB13: RuetzMa | AD13: WidmannFl | AE13: OrelSt | AI13: SnojTa | AK13: LebenJa | AM13: StefenelliFe | AN13: MetzingerFi | AO13: KainbergerJu | AS13: WenuschHe | AT13: LegaSi | AU13: StefenelliFe | AV13: MoschenAn | AW13: VirtaTu | AX13: WenuschHe | AZ13: RuetzMa | BA13: GiacomozziFe | BB13: MetzingerFi | BC13: StefenelliFe | BG13: LebenJa | BJ13: VirtaTu | BK13: MetzingerFi | BM13: RivisFe | BN13: WidmannFl | BP13: PinieOm | BS13: RuetzMa | BU13: PirasAn | BV13: OrelSt | BX13: SpiegelSe | BY13: VirtaTu | BZ13: SnojTa | CA13: RuetzMa | CB13: SpiegelSe | CC13: SpiegelSe | CF13: KainbergerJu | CG13: PirasAn | CH13: LazzeriAl | CI13: Huber rRe | CJ13: SnojTa | CK13: HolzerTo | CL13: RivisFe
A14: WendnerMa | D14: BrondiPa | F14: ArlicMa | G14: KnezRo | H14: CusinFe | K14: BrondiPa | L14: IlmerNo | N14: FormaioniTh | P14: AbeltinoSi | T14: GrisentiLu | V14: LegatKo | W14: MiklicGr | Y14: SeewaldJe | Z14: DivisDo | AB14: DivisDo | AD14: PreiserJu | AE14: MarkizetiGr | AI14: JeramFi | AK14: GrisentiLu | AM14: BrondiPa | AN14: KnezRo | AO14: EislCh | AS14: PreiserJu | AT14: PaceJa | AU14: AbeltinoSi | AV14: CristeliMa | AW14: FormaioniTh | AX14: KnezRo | AZ14: FecchioFe | BA14: AbeltinoSi | BB14: KnezRo | BC14: FecchioFe | BG14: PreiserJu | BJ14: FormaioniTh | BK14: KnezRo | BM14: FecchioFe | BN14: JavornikBl | BP14: CristeliMa | BS14: EislCh | BU14: BrondiPa | BV14: JeramFi | BX14: DivisDo | BY14: PaceJa | BZ14: ArlicMa | CA14: SeewaldJe | CB14: JägerRi | CC14: DivisDo | CF14: SeewaldJe | CG14: RivisAn | CH14: FleischmannLu | CI14: MoidlMa | CJ14: MarkizetiGr | CK14: MoidlMa | CL14: MoidlMa
A15: WuchererGe | D15: GrisentiLu | F15: MarkizetiGr | G15: TelesklavFa | H15: FormaioniTh | K15: CusinFe | L15: RivisAn | N15: GrisentiLu | P15: StrimitzerDa | T15: KnezRo | V15: WuchererGe | W15: MoidlMa | Y15: ZacherlPa | Z15: RinkerDa | AB15: IlmerNo | AD15: WuchererGe | AE15: TelesklavFa | AI15: MarkizetiGr | AK15: JeramFi | AM15: ScalzeriAl | AN15: MarkizetiGr | AO15: FleischmannLu | AS15: RinkerDa | AT15: ScalzeriAl | AU15: RivisAn | AV15: MarkizetiGr | AW15: RinkerDa | AX15: LegatKo | AZ15: ScalzeriAl | BA15: CristeliMa | BB15: LegatKo | BC15: GrisentiLu | BG15: TelesklavFa | BJ15: ScalzeriAl | BK15: LegatKo | BM15: RivisAn | BN15: WuchererGe | BP15: RivisAn | BS15: ZacherlPa | BU15: CristeliMa | BV15: TelesklavFa | BX15: JägerRi | BY15: ScalzeriAl | BZ15: JeramFi | CA15: ZacherlPa | CB15: RinkerDa | CC15: JägerRi | CF15: ZacherlPa | CG15: ScalzeriAl | CH15: ZacherlPa | CI15: WendnerMa | CJ15: WuchererGe | CK15: ZacherlPa | CL15: RinkerDa
A16: RuetzMa | D16: BenvegnuAn | F16: BrockAd | G16: BrockAd | H16: SoraperraSi | K16: PinieOm | L16: LebenJa | N16: BulovecMi | P16: LazzeriAl | T16: BulovecMi | V16: RuetzMa | W16: LesniakBo | Y16: HolzerTo | Z16: MoschenAn | AB16: LesniakBo | AD16: BajtMi | AE16: HolzerTo | AI16: Huber rRe | AK16: MoschenAn | AM16: MetzingerFi | AN16: EggerTh | AO16: LehnerMo | AS16: EggerTh | AT16: RuetzMa | AU16: LegaSi | AV16: HlavatyAl | AW16: RivisFe | AX16: GiacomozziFe | AZ16: BrockAd | BC16: RuetzMa | BG16: LazzeriAl | BJ16: RivisFe | BK16: LebenJa | BM16: LegaSi | BN16: LegaSi | BS16: MoschenAn | BV16: LehnerMo | BX16: BenvegnuAn | BY16: GiacomozziFe | BZ16: BenvegnuAn | CA16: LazzeriAl | CB16: KainbergerJu | CC16: Huber rRe | CF16: HlavatyAl | CG16: BajtMi | CH16: HlavatyAl | CI16: HlavatyAl | CJ16: LazzeriAl | CK16: PinieOm
A17: VirtaTu | D17: LazzeriAl | F17: RuetzMa | G17: HolzerTo | H17: VirtaTu | K17: VirtaTu | L17: LesniakBo | N17: SnojTa | P17: PinieOm | T17: HlavatyAl | V17: SpiegelSe | W17: MetzingerFi | Y17: Huber rRe | Z17: StefenelliFe | AB17: SnojTa | AD17: RivisFe | AE17: KainbergerJu | AI17: RivisFe | AK17: SpiegelSe | AM17: PirasAn | AN17: LazzeriAl | AO17: MoidlDa | AS17: GiacomozziFe | AT17: SpiegelSe | AU17: PinieOm | AV17: UnterwegerDo | AW17: SoraperraSi | AX17: PirasAn | AZ17: LebenJa | BC17: SpiegelSe | BG17: WidmannFl | BJ17: SoraperraSi | BK17: LesniakBo | BM17: SpiegelSe | BN17: MoschenAn | BS17: PirasAn | BV17: MetzingerFi | BX17: SoraperraSi | BY17: PinieOm | BZ17: StefenelliFe | CA17: PinieOm | CB17: PinieOm | CC17: OrelSt | CF17: VirtaTu | CG17: LebenJa | CH17: VoicanCh | CI17: VoicanCh | CJ17: RivisFe | CK17: VirtaTu
A18: FleischmannLu | D18: CusinFe | F18: WeissAl | G18: SeewaldJe | H18: BrondiPa | K18: FecchioFe | L18: ArlicMa | N18: ArlicMa | P18: IlmerNo | T18: MarkizetiGr | V18: DivisDo | W18: JavornikBl | Y18: MattheyPh | Z18: BrondiPa | AB18: ArlicMa | AD18: JavornikBl | AE18: DivisDo | AI18: FecchioFe | AK18: FecchioFe | AM18: FecchioFe | AN18: GrisentiLu | AO18: BrondiPa | AS18: AbeltinoSi | AT18: DivisDo | AU18: CristeliMa | AV18: LegatKo | AW18: GrisentiLu | AX18: CristeliMa | AZ18: JeramFi | BC18: JägerRi | BG18: SeewaldJe | BJ18: AbeltinoSi | BK18: FecchioFe | BM18: CusinFe | BN18: CusinFe | BS18: AbeltinoSi | BV18: MoidlMa | BX18: FecchioFe | BY18: BrondiPa | BZ18: FleischmannLu | CA18: AbeltinoSi | CB18: CristeliMa | CC18: StrimitzerDa | CF18: RinkerDa | CG18: SeewaldJe | CH18: MoidlMa | CI18: PaceJa | CJ18: CristeliMa | CK18: BrondiPa
A19: IlmerNo | D19: FormaioniTh | F19: WendnerMa | G19: WendnerMa | H19: ScalzeriAl | K19: FormaioniTh | L19: MarkizetiGr | N19: JeramFi | P19: ScalzeriAl | T19: PreiserJu | V19: RinkerDa | W19: KnezRo | Y19: RinkerDa | Z19: GrisentiLu | AB19: StrimitzerDa | AD19: RivisAn | AE19: SeewaldJe | AI19: RivisAn | AK19: JägerRi | AM19: KnezRo | AN19: ScalzeriAl | AO19: MoidlMa | AS19: PaceJa | AT19: JägerRi | AU19: CusinFe | AV19: SeewaldJe | AW19: ScalzeriAl | AX19: FleischmannLu | AZ19: KnezRo | BC19: StrimitzerDa | BG19: WuchererGe | BJ19: PaceJa | BK19: JeramFi | BM19: DivisDo | BN19: RivisAn | BS19: FormaioniTh | BV19: WeissAl | BX19: IlmerNo | BY19: RivisAn | BZ19: IlmerNo | CA19: CristeliMa | CB19: StrimitzerDa | CC19: WuchererGe | CF19: WeissAl | CG19: StrimitzerDa | CH19: WeissAl | CI19: WeissAl | CJ19: FleischmannLu | CK19: RinkerDa
A20: MoschenAn | D20: HolzerTo | F20: BenvegnuAn | G20: StefenelliFe | H20: BulovecMi | K20: LazzeriAl | L20: GiacomozziFe | V20: RivisFe | W20: EggerTh | Y20: LebenJa | AB20: VirtaTu | AD20: LehnerMo | AE20: LehnerMo | AI20: GiacomozziFe | AK20: StefenelliFe | AM20: LegaSi | AO20: LebenJa | AT20: BajtMi | AU20: PirasAn | AW20: BenvegnuAn | AZ20: RivisFe | BC20: HlavatyAl | BK20: LazzeriAl | BM20: Huber rRe | BS20: RivisFe | BX20: LegaSi | BY20: MeixnerSe | BZ20: LegaSi | CA20: PirasAn | CB20: VirtaTu | CC20: BulovecMi | CF20: BulovecMi | CG20: HolzerTo
A21: SnojTa | D21: PinieOm | F21: GiacomozziFe | G21: VirtaTu | H21: RivisFe | K21: SnojTa | L21: RivisFe | V21: SoraperraSi | W21: LazzeriAl | Y21: PirasAn | AB21: WidmannFl | AD21: OrelSt | AE21: MoidlDa | AI21: SoraperraSi | AK21: VirtaTu | AM21: VirtaTu | AO21: PirasAn | AT21: HolzerTo | AU21: VirtaTu | AW21: RuetzMa | AZ21: SpiegelSe | BC21: KainbergerJu | BK21: OrelSt | BM21: VirtaTu | BS21: StefenelliFe | BX21: StefenelliFe | BY21: RuetzMa | BZ21: SoraperraSi | CA21: SnojTa | CB21: WidmannFl | CC21: KainbergerJu | CF21: LazzeriAl | CG21: VirtaTu
A22: MarkizetiGr | D22: DivisDo | F22: AbeltinoSi | G22: GrisentiLu | H22: ArlicMa | K22: JeramFi | L22: AbeltinoSi | V22: AbeltinoSi | W22: CusinFe | Y22: AbeltinoSi | AB22: PaceJa | AD22: EislCh | AE22: MattheyPh | AI22: BrondiPa | AK22: CristeliMa | AM22: CristeliMa | AO22: GrisentiLu | AT22: JavornikBl | AU22: FecchioFe | AW22: CusinFe | AZ22: BrondiPa | BC22: PreiserJu | BK22: PaceJa | BM22: FormaioniTh | BS22: FleischmannLu | BX22: CusinFe | BY22: MoidlMa | BZ22: FormaioniTh | CA22: BrondiPa | CB22: BrondiPa | CC22: JeramFi | CF22: CristeliMa | CG22: DivisDo
A23: RivisAn | D23: FecchioFe | F23: FecchioFe | G23: StrimitzerDa | H23: IlmerNo | K23: WuchererGe | L23: DivisDo | V23: CristeliMa | W23: FormaioniTh | Y23: CristeliMa | AB23: TelesklavFa | AD23: StrimitzerDa | AE23: MoidlMa | AI23: FormaioniTh | AK23: PaceJa | AM23: RivisAn | AO23: JavornikBl | AT23: StrimitzerDa | AU23: GrisentiLu | AW23: RivisAn | AZ23: DivisDo | BC23: ScalzeriAl | BK23: TelesklavFa | BM23: ScalzeriAl | BS23: RivisAn | BX23: FormaioniTh | BY23: StrimitzerDa | BZ23: PaceJa | CA23: JeramFi | CB23: WuchererGe | CC23: SeewaldJe | CF23: JeramFi | CG23: FleischmannLu
G24: LebenJa | L24: LegaSi | AD24: HolzerTo | AE24: HlavatyAl | AK24: PirasAn | AT24: MoschenAn | BC24: LebenJa | BK24: KainbergerJu | BX24: Huber rRe | BZ24: LesniakBo | CA24: GiacomozziFe | CB24: BenvegnuAn | CC24: MoschenAn
G25: OrelSt | L25: RuetzMa | AD25: SpiegelSe | AE25: WidmannFl | AK25: SoraperraSi | AT25: VirtaTu | BC25: MoschenAn | BK25: VoicanCh | BX25: MoschenAn | BZ25: OrelSt | CA25: SoraperraSi | CB25: StefenelliFe | CC25: RivisFe
G26: MarkizetiGr | L26: BrondiPa | AD26: MattheyPh | AE26: ArlicMa | AK26: FormaioniTh | AT26: FleischmannLu | BC26: CristeliMa | BK26: PreiserJu | BX26: RinkerDa | BZ26: JavornikBl | CA26: GrisentiLu | CB26: PaceJa | CC26: FecchioFe
G27: PuffWo | L27: GrisentiLu | AD27: MoidlMa | AE27: WuchererGe | AK27: ScalzeriAl | AT27: FormaioniTh | BC27: JeramFi | BK27: SeewaldJe | BX27: StrimitzerDa | BZ27: TelesklavFa | CA27: RivisAn | CB27: ScalzeriAl | CC27: FormaioniTh

Sheet AHL_DAT_STRING
A3: 2024-09-21 | B3: 2024-09-22 | C3: 2024-09-24 | D3: 2024-09-26 | E3: 2024-09-29 | F3: 2024-10-05 | G3: 2024-09-28 | H3: 2024-10-03 | I3: 2024-10-08 | J3: 2024-10-09 | K3: 2024-10-10 | L3: 2024-10-12 | M3: 2024-10-16 | N3: 2024-10-17 | O3: 2024-10-06 | P3: 2024-10-19 | Q3: 2024-10-20 | R3: 2024-10-23 | S3: 2024-10-25 | T3: 2024-10-26 | U3: 2024-10-27 | V3: 2024-10-29 | W3: 2024-11-01 | X3: 2024-11-02 | Y3: 2024-11-03 | Z3: 2024-10-24 | AA3: 2024-10-31 | AB3: 2024-11-16 | AC3: 2024-11-17 | AD3: 2024-11-23 | AE3: 2024-11-30 | AF3: 2024-12-03 | AG3: 2024-12-04 | AH3: 2024-11-12 | AI3: 2024-11-14 | AJ3: 2024-11-19 | AK3: 2024-11-21 | AL3: 2024-11-26 | AM3: 2024-11-28 | AN3: 2024-12-05 | AO3: 2024-12-07 | AP3: 2024-12-01 | AQ3: 2024-11-24 | AR3: 2024-12-22 | AS3: 2024-12-26 | AT3: 2024-12-28 | AU3: 2024-12-30 | AV3: 2024-12-17 | AW3: 2024-12-19 | AX3: 2024-12-21 | AY3: 2024-12-27 | AZ3: 2025-01-02 | BA3: 2025-01-04 | BB3: 2025-01-05 | BC3: 2025-01-06 | BD3: 2025-01-03 | BE3: 2025-01-08 | BF3: 2025-01-12 | BG3: 2025-01-18 | BH3: 2025-01-21 | BI3: 2025-01-22 | BJ3: 2025-01-09 | BK3: 2025-01-11 | BL3: 2025-01-14 | BM3: 2025-01-16 | BN3: 2025-01-23 | BO3: 2025-01-25 | BP3: 2025-01-26 | BQ3: 2025-01-28 | BR3: 2025-01-29 | BS3: 2025-01-30 | BT3: 2025-02-02 | BU3: 2025-02-04 | BV3: 2025-02-01 | BW3: 2025-02-05 | BX3: 2025-02-11 | BY3: 2025-02-13 | BZ3: 2025-02-15 | CA3: 2025-02-18 | CB3: 2025-02-20 | CC3: 2025-02-22 | CD3: 2025-02-23 | CE3: 2025-02-25 | CF3: 2025-02-27 | CG3: 2025-03-01 | CH3: 2025-03-04 | CI3: 2025-03-08 | CJ3: 2025-03-11 | CK3: 2025-03-13 | CL3: 2025-03-15 | CM3: 2025-03-16 | CN3: 2025-03-18 | CO3: 2025-03-20 | CP3: 2025-03-22 | CQ3: 2025-03-25 | CR3: 2025-03-27 | CS3: 2025-03-29 | CT3: 2025-04-01 | CU3: 2025-04-08 | CV3: 2025-04-13 | CW3: 2025-04-05 | CX3: 2025-04-10 | CY3: 2025-04-15
A4: Eishalle Sterzing;BenvegnuAn;SoraperraSi;FecchioFe;GrisentiLu | B4: Eishalle Cortina;MetzingerFi;StefenelliFe;AbeltinoSi;ScalzeriAl | C4: Eisarena Salzburg;KainbergerJu;VoicanCh;LegatKo;PreiserJu | D4: Eishalle Jesenice;BajtMi;BulovecMi;ArlicMa;MarkizetiGr | E4: Eishalle Celje;MeixnerSe;VoicanCh;LegatKo;PreiserJu | F4: Eishalle Sterzing;LazzeriAl;MoschenAn;GrisentiLu;RivisAn | G4: Eishalle Ritten;MoschenAn;SoraperraSi;IlmerNo;RivisAn | H4: Sportpark Kitzbühel;RuetzMa;SpiegelSe;SeewaldJe;ZacherlPa | I4: Eishalle Gröden;RuetzMa;StefenelliFe;AbeltinoSi;RinkerDa | J4: Eishalle Dornbirn;HolzerTo;SpiegelSe;JägerRi;SeewaldJe | K4: Eishalle Celje;BulovecMi;MeixnerSe;MiklicGr;TelesklavFa | L4: KELIT Arena Zell am See;BajtMi;WenuschHe;PreiserJu;RinkerDa | M4: Eishalle Gröden;OrelSt;StefenelliFe;ScalzeriAl;WuchererGe | N4: Sportpark Kitzbühel;HolzerTo;KainbergerJu;DivisDo;FecchioFe | O4: Würtharena Neumarkt;OrelSt;VirtaTu;StrimitzerDa;WuchererGe | P4: Eisarena Salzburg;RuetzMa;WidmannFl;RinkerDa;TelesklavFa | Q4: Eishalle Cortina;BajtMi;BenvegnuAn;CristeliMa;MarkizetiGr | R4: Eisarena Salzburg;MeixnerSe;RuetzMa;MattheyPh;StrimitzerDa | S4: Eisarena Salzburg;BenvegnuAn;WenuschHe;BrondiPa;LegatKo | T4: Eishalle Sterzing;BrockAd;SternatCh;RivisAn;WendnerMa | U4: Eishalle Celje;LazzeriAl;LebenJa;FormaioniTh;JeramFi | V4: Eishalle Jesenice;HlavatyAl;KainbergerJu;EislCh;PreiserJu | W4: Eishalle Ritten;OrelSt;WidmannFl;TelesklavFa;WuchererGe | X4: Eishalle Sissek Zibel;BrockAd;WenuschHe;LegatKo;PreiserJu | Y4: Eishalle Dornbirn;PinieOm;VirtaTu;DivisDo;JägerRi | Z4: Eishalle Jesenice;LesniakBo;SnojTa;JavornikBl;MiklicGr | AA4: Eishalle Sterzing;GiacomozziFe;PirasAn;PaceJa;ScalzeriAl | AB4: Sportpark Kitzbühel;SpiegelSe;VoicanCh;PreiserJu;WeissAl | AC4: Eishalle Ritten;MetzingerFi;StefenelliFe;CristeliMa;KnezRo | AD4: Eishalle Jesenice;BrockAd;SnojTa;ArlicMa;TelesklavFa | AE4: Würtharena Neumarkt;GiacomozziFe;SoraperraSi;AbeltinoSi;CusinFe | AF4: Eishalle Gröden;EggerTh;StefenelliFe;BrondiPa;GrisentiLu | AG4: Eishalle Dornbirn;HolzerTo;Huber rRe;DivisDo;RinkerDa | AH4: Eisarena Salzburg;HolzerTo;RuetzMa;JägerRi;SeewaldJe | AI4: Sportpark Kitzbühel;KainbergerJu;LegaSi;CristeliMa;ZacherlPa | AJ4: Eishalle Dornbirn;BenvegnuAn;LazzeriAl;DivisDo;JägerRi | AK4: KELIT Arena Zell am See;HlavatyAl;WenuschHe;EislCh;WuchererGe | AL4: Kitzbühel Sportpark;BenvegnuAn;LazzeriAl;RinkerDa;SeewaldJe | AM4: Eishalle Jesenice;BrockAd;MeixnerSe;PreiserJu;ZacherlPa | AN4: Sportpark Kitzbühel;HlavatyAl;MeixnerSe;EislCh;WeissAl | AO4: Eishalle Sterzing;MoschenAn;SoraperraSi;CusinFe;FormaioniTh | AP4: Eishalle Ritten;MetzingerFi;StefenelliFe;CristeliMa;KnezRo | AQ4: Eishalle Celje;LesniakBo;RivisFe;ArlicMa;RivisAn | AR4: Eishalle Celje;LehnerMo;MeixnerSe;MattheyPh;WendnerMa | AS4: Eishalle Jesenice;BajtMi;LehnerMo;MarkizetiGr;MattheyPh | AT4: Eishalle Sterzing;BrockAd;MoidlDa;FecchioFe;MattheyPh | AU4: Eishalle Ritten;BenvegnuAn;MoschenAn;BrondiPa;WeissAl | AV4: Würtharena Neumarkt;LazzeriAl;PinieOm;AbeltinoSi;BrondiPa | AW4: Eishalle Jesenice;LesniakBo;UnterwegerDo;ArlicMa;JavornikBl | AX4: Eishalle Celje;BajtMi;OrelSt;EislCh;StrimitzerDa | AY4: Eishalle Dornbirn;HolzerTo;OrelSt;StrimitzerDa;WuchererGe | AZ4: Sportpark Kitzbühel;HlavatyAl;VoicanCh;EislCh;RinkerDa | BA4: KELIT Arena Zell am See;HolzerTo;VoicanCh;TelesklavFa;WendnerMa | BB4: Eishalle Sterzing;BenvegnuAn;SnojTa;ArlicMa;RivisAn | BC4: Eishalle Sissek Zibel;LesniakBo;OrelSt;ArlicMa;KnezRo | BD4: Eishalle Jesenice;OrelSt;VoicanCh;PreiserJu;WuchererGe | BE4: Eishalle Dornbirn;GiacomozziFe;Huber rRe;BrondiPa;DivisDo | BF4: Eishalle Ritten;MeixnerSe;SnojTa;JeramFi;WendnerMa | BG4: Eishalle Meran;BulovecMi;GiacomozziFe;ArlicMa;CristeliMa | BH4: Eisarena Salzburg;LehnerMo;WidmannFl;SeewaldJe;ZacherlPa | BI4: Eishalle Dornbirn;HolzerTo;Huber rRe;JägerRi;StrimitzerDa | BJ4: Eisarena Salzburg;LehnerMo;MoidlDa;MattheyPh;MoidlMa | BK4: Eishalle Sterzing;LegaSi;MoschenAn;CusinFe;StrimitzerDa | BL4: Eisarena Salzburg;Huber rRe;RuetzMa;RinkerDa;ZacherlPa | BM4: Eishalle Sissek Zibel;SnojTa;WidmannFl;JavornikBl;WuchererGe | BN4: Eishalle Jesenice;MetzingerFi;SnojTa;KnezRo;MarkizetiGr | BO4: Würtharena Neumarkt;EggerTh;SnojTa;ArlicMa;BrondiPa | BP4: Würtharena Neumarkt;LebenJa;WidmannFl;FecchioFe;TelesklavFa | BQ4: Eishalle Jesenice;LehnerMo;MeixnerSe;MattheyPh;WuchererGe | BR4: Eishalle Dornbirn;SoraperraSi;StefenelliFe;FecchioFe;JägerRi | BS4: Eishalle Celje;BrockAd;SnojTa;MarkizetiGr;WendnerMa | BT4: Eishalle Gröden;EggerTh;LazzeriAl;GrisentiLu;IlmerNo | BU4: Eisarena Salzburg;HlavatyAl;VoicanCh;PreiserJu;WeissAl | BV4: Würtharena Neumarkt;BajtMi;LegaSi;CusinFe;PaceJa | BW4: Eishalle Dornbirn;Huber rRe;RuetzMa;DivisDo;JägerRi | BX4: Eishalle Sissek Zibel;BajtMi;MetzingerFi;KnezRo;MarkizetiGr | BY4: Eisarena Salzburg;BrockAd;KainbergerJu;EislCh;WendnerMa | BZ4: Würtharena Neumarkt;MoschenAn;PinieOm;AbeltinoSi;FecchioFe | CA4: Eishalle Sissek Zibel;BrockAd;MeixnerSe;KnezRo;WendnerMa | CB4: Eishalle Celje;BajtMi;BulovecMi;ArlicMa;JeramFi | CC4: Eishalle Jesenice;BrockAd;RuetzMa;RinkerDa;WendnerMa | CD4: Eishalle Dornbirn;LazzeriAl;LegaSi;CusinFe;GrisentiLu | CE4: Eishalle Zell am See;BenvegnuAn;HlavatyAl;AbeltinoSi;LegatKo | CF4: Eishalle Jesenice;LesniakBo;SoraperraSi;ArlicMa;BrondiPa | CG4: Eishalle Sissek Zibel;KainbergerJu;VoicanCh;MoidlMa;WeissAl | CH4: Eishalle Jesenice;OrelSt;SnojTa;MarkizetiGr;WuchererGe | CI4: Eishalle Jesenice;BulovecMi;KainbergerJu;JeramFi;TelesklavFa | CJ4: Eishalle Dornbirn;BrockAd;Huber rRe;RinkerDa;StrimitzerDa | CK4: Eishalle Jesenice;LazzeriAl;VoicanCh;FleischmannLu;WeissAl | CL4: Eishalle Sterzing;HolzerTo;VirtaTu;BrondiPa;FleischmannLu | CM4: Eishalle Dornbirn;KainbergerJu;OrelSt;WuchererGe;ZacherlPa | CN4: Eishalle Ritten;GiacomozziFe;Huber rRe;FleischmannLu;StrimitzerDa | CO4: Eishalle Meran;BulovecMi;SnojTa;BrondiPa;JeramFi | CP4: Eishalle Ritten;HolzerTo;KainbergerJu;FleischmannLu;RinkerDa | CQ4: KELIT Arena Zell am See;OrelSt;VoicanCh;WeissAl;WuchererGe | CR4: Eishalle Jesenice;KainbergerJu;SnojTa;JeramFi;WuchererGe | CS4: Eishalle Ritten;OrelSt;SnojTa;FleischmannLu;WuchererGe | CT4: Eishalle Jesenice;KainbergerJu;VoicanCh;RinkerDa;WeissAl | CU4: Eishalle Jesenice;BulovecMi;VoicanCh;JeramFi;WeissAl | CV4: Eishalle Jesenice;HolzerTo;LazzeriAl;FleischmannLu;RinkerDa | CW4: KELIT Arena Zell am See;HolzerTo;LazzeriAl;FleischmannLu;RinkerDa | CX4: KELIT Arena Zell am See;BulovecMi;SnojTa;WeissAl;WuchererGe | CY4: KELIT Arena Zell am See;SnojTa;VoicanCh;JeramFi;WuchererGe
